Workbook

Sheet Инструкция
A1: Excel-шаблон к методике формулирования бизнес-логики и пользовательских сценариев
A3: Назначение файла
A4: Этот файл предназначен для последовательной сборки бизнес-логики цифрового товара и пользовательских сценариев на основе всех ранее выполненных видов анализа: проблем, отзывов, конкурентов, рыночного стандарта, ценностного предложения, цифрового товара и Канвас.
A5: Ключевой принцип: каждый элемент бизнес-логики и каждый пользовательский сценарий должен иметь источник, доказательство, связь с ценностным предложением, цифровым товаром, монетизацией и блоком бизнес-модели.
A6: Сначала заполняется «Банк анализа», затем «Бизнес-логика», «Роли и сегменты», «Пользовательские сценарии», «Функциональные требования», «Приоритизация» и «Связность». Лист «Дашборд» рассчитывается автоматически.
A7: Желтые ячейки — зоны ручного ввода. Зеленые ячейки — расчетные поля. Выпадающие списки берутся из листа «Справочники».
A9: Этап | B9: Что сделать | C9: Основной лист | D9: Результат | E9: Проверка качества | F9: Связь с методикой | G9: Ответственный | H9: Статус
A10: 1 | B10: Перенести ключевые выводы из всех видов анализа | C10: Банк анализа | D10: Единая доказательная база | E10: Есть ссылка/факт/уровень доказательности | F10: Анализ проблем, отзывов, конкурентов, Канвас
A11: 2 | B11: Сформулировать элементы бизнес-логики | C11: Бизнес-логика | D11: Понятно, за счет чего создается, доставляется и монетизируется ценность | E11: Для элемента указаны ценность, товар, процесс и выручка | F11: Сборка бизнес-модели
A12: 3 | B12: Описать роли и сегменты пользователей | C12: Роли и сегменты | D12: Понятно, кто участвует в сценариях | E12: У каждой роли есть задача, проблема и основание | F12: Потребительские сегменты Канвас
A13: 4 | B13: Собрать пользовательские сценарии | C13: Пользовательские сценарии | D13: Описаны основные, монетизационные, сервисные и удерживающие сценарии | E13: У сценария есть проблема, цель, результат и монетизация | F13: Переход от ценности к поведению пользователя
A14: 5 | B14: Разложить сценарии по этапам взаимодействия | C14: Карта сценариев | D14: Видны точки входа, оплаты, поддержки и удержания | E14: Нет разрывов между этапами | F14: Клиентский путь
A15: 6 | B15: Перевести сценарии в требования | C15: Функциональные требования | D15: Получен перечень функций и требований | E15: Требование связано со сценарием и бизнес-целью | F15: Товар как носитель ценности
A16: 7 | B16: Приоритизировать инициативы | C16: Приоритизация | D16: Определена очередность разработки | E16: Приоритет зависит от ценности, эффекта, доказательности и сложности | F16: MVP и развитие продукта
A17: 8 | B17: Проверить связность всей конструкции | C17: Связность | D17: Выявлены слабые места модели | E17: Контрольные точки пройдены | F17: Цепочка «анализ → логика → сценарий → товар → монетизация»

Sheet Банк анализа
A1: Банк выводов из всех видов анализа
A3: ID вывода | B3: Направление анализа | C3: Объект анализа | D3: Краткий вывод | E3: Подтверждающий факт | F3: Источник / ссылка | G3: Сила доказательства (1-4) | H3: Значимость для модели (1-5) | I3: Риск ошибочной интерпретации (1-5) | J3: Индекс опоры | K3: Связанный блок Канвас | L3: Связанная проблема / роль / сценарий | M3: Решение использовать | N3: Комментарий
A4: A-001 | B4: Анализ конкурентов по сайтам | C4: Сайты PlantUML, Mermaid, D2, Eraser.io | D4: IDEF0/IDEF3/DFD не поддерживает ни один прямой конкурент | E4: Списки типов диаграмм на сайтах | F4: plantuml.com; mermaid.js.org; d2lang.com; eraser.io (2026-09-17/23) | G4: 4 | H4: 5 | I4: 1 | J4: =IFERROR((G4*H4)*(6-I4)/20,"") -> 5 | K4: Ценностные предложения | L4: P-001 | M4: =IF(J4="","",IF(J4>=3,"Использовать",IF(J4>=1.8,"Проверить дополнительно","Не использовать как основание"))) -> Использовать
A5: A-002 | B5: Анализ цифрового товара и рыночного стандарта | C5: draw.io | D5: Графический редактор не проверяет правила нотаций | E5: Описание функций drawio.com | F5: drawio.com (2026-09-23) | G5: 3 | H5: 5 | I5: 2 | J5: =IFERROR((G5*H5)*(6-I5)/20,"") -> 3 | K5: Ценностные предложения | L5: P-001 | M5: =IF(J5="","",IF(J5>=3,"Использовать",IF(J5>=1.8,"Проверить дополнительно","Не использовать как основание"))) -> Использовать | N5: Косвенный вывод
A6: A-003 | B6: Анализ бизнес-моделей конкурентов | C6: Тарифы Eraser.io | D6: Freemium с подпиской за место и лимитом AI — стандарт монетизации | E6: Free → $15–20 → $45–60 | F6: eraser.io/pricing | G6: 4 | H6: 5 | I6: 1 | J6: =IFERROR((G6*H6)*(6-I6)/20,"") -> 5 | K6: Потоки доходов | L6: M-001 | M6: =IF(J6="","",IF(J6>=3,"Использовать",IF(J6>=1.8,"Проверить дополнительно","Не использовать как основание"))) -> Использовать
A7: A-004 | B7: Анализ бизнес-моделей конкурентов | C7: PlantUML, Mermaid, D2, draw.io | D7: Сильный бесплатный стандарт — Free обязателен | E7: Open-source, донаты | F7: ЛР5, разд. 2 | G7: 4 | H7: 4 | I7: 1 | J7: =IFERROR((G7*H7)*(6-I7)/20,"") -> 4 | K7: Потоки доходов | L7: M-001 | M7: =IF(J7="","",IF(J7>=3,"Использовать",IF(J7>=1.8,"Проверить дополнительно","Не использовать как основание"))) -> Использовать
A8: A-005 | B8: Классификация компаний по уровням конкуренции | C8: 9 конкурентов | D8: Прямые: PlantUML, Mermaid, MermaidChart, Eraser.io | E8: Индексы 83,5–93,0 | F8: ЛР5, разд. 1 | G8: 4 | H8: 4 | I8: 2 | J8: =IFERROR((G8*H8)*(6-I8)/20,"") -> 3.2 | K8: Потребительские сегменты | L8: Выбор эталонов | M8: =IF(J8="","",IF(J8>=3,"Использовать",IF(J8>=1.8,"Проверить дополнительно","Не использовать как основание"))) -> Использовать
A9: A-006 | B9: Анализ цифрового товара и рыночного стандарта | C9: Кано/Левитт | D9: Стандарт: DSL, браузерный рендер, GitHub; отличие: полный охват нотаций | E9: ЛР5, разд. 3–5 | F9: ЛР5 | G9: 3 | H9: 5 | I9: 2 | J9: =IFERROR((G9*H9)*(6-I9)/20,"") -> 3 | K9: Ценностные предложения | L9: F-001…F-012 | M9: =IF(J9="","",IF(J9>=3,"Использовать",IF(J9>=1.8,"Проверить дополнительно","Не использовать как основание"))) -> Использовать
A10: A-007 | B10: Анализ проблем клиентов | C10: Карта проблем 6.1 | D10: Опорная P-001, ИПП 4,35 | E10: 8 проблем, индексы шаблона 57–90 | F10: ЛР6 п. 6.1 | G10: 3 | H10: 5 | I10: 2 | J10: =IFERROR((G10*H10)*(6-I10)/20,"") -> 3 | K10: Потребительские сегменты | L10: R-002, R-003 | M10: =IF(J10="","",IF(J10>=3,"Использовать",IF(J10>=1.8,"Проверить дополнительно","Не использовать как основание"))) -> Использовать
A11: A-008 | B11: Анализ отзывов | C11: G2/Capterra/Reddit/Habr | D11: 🔲 ДОСНЯТЬ: подтверждение боли ручной раскладки | E11: — | F11: 🔲 | G11: 1 | H11: 5 | I11: 3 | J11: =IFERROR((G11*H11)*(6-I11)/20,"") -> 0.75 | K11: Потребительские сегменты | L11: P-001 | M11: =IF(J11="","",IF(J11>=3,"Использовать",IF(J11>=1.8,"Проверить дополнительно","Не использовать как основание"))) -> Не использовать как основание | N11: Нет данных
A12: A-009 | B12: Канвас бизнес-модели | C12: Канвас 6.2 | D12: Самый слабый блок — «Потоки доходов» (42 %) | E12: Индекс доказательности | F12: ЛР6 п. 6.2 | G12: 3 | H12: 5 | I12: 2 | J12: =IFERROR((G12*H12)*(6-I12)/20,"") -> 3 | K12: Потоки доходов | L12: S-007 | M12: =IF(J12="","",IF(J12>=3,"Использовать",IF(J12>=1.8,"Проверить дополнительно","Не использовать как основание"))) -> Использовать
A13: A-010 | B13: Экономика монетизации | C13: Концепция §6 | D13: Pro 4 USD/мес; конверсия 3–5 % — допущения | E13: Концепция NotaCode | F13: 01-project-concept.md | G13: 2 | H13: 4 | I13: 3 | J13: =IFERROR((G13*H13)*(6-I13)/20,"") -> 1.2 | K13: Потоки доходов | L13: S-007 | M13: =IF(J13="","",IF(J13>=3,"Использовать",IF(J13>=1.8,"Проверить дополнительно","Не использовать как основание"))) -> Не использовать как основание
J14: =IFERROR((G14*H14)*(6-I14)/20,"") -> 0 | M14: =IF(J14="","",IF(J14>=3,"Использовать",IF(J14>=1.8,"Проверить дополнительно","Не использовать как основание"))) -> Не использовать как основание
J15: =IFERROR((G15*H15)*(6-I15)/20,"") -> 0 | M15: =IF(J15="","",IF(J15>=3,"Использовать",IF(J15>=1.8,"Проверить дополнительно","Не использовать как основание"))) -> Не использовать как основание
J16: =IFERROR((G16*H16)*(6-I16)/20,"") -> 0 | M16: =IF(J16="","",IF(J16>=3,"Использовать",IF(J16>=1.8,"Проверить дополнительно","Не использовать как основание"))) -> Не использовать как основание
J17: =IFERROR((G17*H17)*(6-I17)/20,"") -> 0 | M17: =IF(J17="","",IF(J17>=3,"Использовать",IF(J17>=1.8,"Проверить дополнительно","Не использовать как основание"))) -> Не использовать как основание
J18: =IFERROR((G18*H18)*(6-I18)/20,"") -> 0 | M18: =IF(J18="","",IF(J18>=3,"Использовать",IF(J18>=1.8,"Проверить дополнительно","Не использовать как основание"))) -> Не использовать как основание
J19: =IFERROR((G19*H19)*(6-I19)/20,"") -> 0 | M19: =IF(J19="","",IF(J19>=3,"Использовать",IF(J19>=1.8,"Проверить дополнительно","Не использовать как основание"))) -> Не использовать как основание
J20: =IFERROR((G20*H20)*(6-I20)/20,"") -> 0 | M20: =IF(J20="","",IF(J20>=3,"Использовать",IF(J20>=1.8,"Проверить дополнительно","Не использовать как основание"))) -> Не использовать как основание
J21: =IFERROR((G21*H21)*(6-I21)/20,"") -> 0 | M21: =IF(J21="","",IF(J21>=3,"Использовать",IF(J21>=1.8,"Проверить дополнительно","Не использовать как основание"))) -> Не использовать как основание
J22: =IFERROR((G22*H22)*(6-I22)/20,"") -> 0 | M22: =IF(J22="","",IF(J22>=3,"Использовать",IF(J22>=1.8,"Проверить дополнительно","Не использовать как основание"))) -> Не использовать как основание
J23: =IFERROR((G23*H23)*(6-I23)/20,"") -> 0 | M23: =IF(J23="","",IF(J23>=3,"Использовать",IF(J23>=1.8,"Проверить дополнительно","Не использовать как основание"))) -> Не использовать как основание
J24: =IFERROR((G24*H24)*(6-I24)/20,"") -> 0 | M24: =IF(J24="","",IF(J24>=3,"Использовать",IF(J24>=1.8,"Проверить дополнительно","Не использовать как основание"))) -> Не использовать как основание
J25: =IFERROR((G25*H25)*(6-I25)/20,"") -> 0 | M25: =IF(J25="","",IF(J25>=3,"Использовать",IF(J25>=1.8,"Проверить дополнительно","Не использовать как основание"))) -> Не использовать как основание
... J203: =IFERROR((G203*H203)*(6-I203)/20,"") -> 0 | M203: =IF(J203="","",IF(J203>=3,"Использовать",IF(J203>=1.8,"Проверить дополнительно","Не использовать как основание"))) -> Не использовать как основание

Sheet Бизнес-логика
A1: Формулирование бизнес-логики цифрового товара
A3: ID элемента | B3: Элемент бизнес-логики | C3: Тип бизнес-логики | D3: Какая ценность создается | E3: Для кого | F3: Цифровой товар / функция | G3: Процесс или механизм | H3: Источник выручки / единица монетизации | I3: Связанный вывод анализа | J3: Доказательность (1-4) | K3: Влияние на модель (1-5) | L3: Проверка связности | M3: Индекс надежности | N3: Статус | O3: Нужное уточнение
A4: BL-001 | B4: Корректная диаграмма из текста с проверкой правил | C4: Продуктовая | D4: Экономия времени и отсутствие замечаний по нотации | E4: Активный пользователь (S-01) | F4: DSL-редактор + валидация профилей нотаций | G4: Код → Run → диагностика с номером строки → исправление | H4: Free (вход в воронку) | I4: A-001, A-002 | J4: 3 | K4: 5 | L4: =IF(A4="","",IF(COUNTA(D4:I4)>=5,1,0)) -> 1 | M4: =IF(A4="","",IFERROR(J4*K4*L4/20,0)) -> 0.75 | N4: Требует проверки | O4: Подтвердить опросом H-01
A5: BL-002 | B5: Первая ценность без регистрации | C5: Клиентская | D5: Снижение риска выбора | E5: Посетитель | F5: Гостевой режим + шаблоны | G5: Открыть шаблон → Run → увидеть диаграмму | H5: Free | I5: A-004 | J5: 3 | K5: 4 | L5: =IF(A5="","",IF(COUNTA(D5:I5)>=5,1,0)) -> 1 | M5: =IF(A5="","",IFERROR(J5*K5*L5/20,0)) -> 0.6 | N5: Требует проверки | O5: Метрика активации
A6: BL-003 | B6: Упор в лимит Free → Pro | C6: Монетизационная | D6: Работа без ограничений объёма и форматов | E6: Потенциальный клиент (S-02/S-03) | F6: Лимиты 5 проектов/20 версий/форматы | G6: Лимит → тарифы → заявка/оплата | H6: Подписка Pro 4 USD/мес | I6: A-003, A-010 | J6: 2 | K6: 5 | L6: =IF(A6="","",IF(COUNTA(D6:I6)>=5,1,0)) -> 1 | M6: =IF(A6="","",IFERROR(J6*K6*L6/20,0)) -> 0.5 | N6: Требует проверки | O6: Тест заявок H-02
A7: BL-004 | B7: Возврат к проекту через историю | C7: Сервисная | D7: Накопленная ценность (версии, откат) | E7: Активный пользователь | F7: История версий, diff, откат | G7: Открыть проект → версии → diff → откат | H7: Удержание | I7: A-006 | J7: 3 | K7: 4 | L7: =IF(A7="","",IF(COUNTA(D7:I7)>=5,1,0)) -> 1 | M7: =IF(A7="","",IFERROR(J7*K7*L7/20,0)) -> 0.6 | N7: Подтверждено
A8: BL-005 | B8: Привлечение через поиск и преподавателей | C8: Канальная | D8: Узнать об инструменте в момент задачи | E8: Посетитель | F8: Лендинг, галерея примеров | G8: Поиск IDEF0/DFD → лендинг → редактор | H8: — | I8: A-005, A-007 | J8: 2 | K8: 4 | L8: =IF(A8="","",IF(COUNTA(D8:I8)>=5,1,0)) -> 1 | M8: =IF(A8="","",IFERROR(J8*K8*L8/20,0)) -> 0.4 | N8: Требует проверки | O8: UTM H-04
A9: BL-006 | B9: Нулевые затраты инфраструктуры в MVP | C9: Инфраструктурная | D9: Возможность запуска без бюджета | E9: Внутренний администратор | F9: Free tiers хостинга, AI-заглушка/BYOK | G9: Сервисы на бесплатных тарифах | H9: — | I9: A-009 | J9: 3 | K9: 3 | L9: =IF(A9="","",IF(COUNTA(D9:I9)>=5,1,0)) -> 1 | M9: =IF(A9="","",IFERROR(J9*K9*L9/20,0)) -> 0.45 | N9: Подтверждено
A10: BL-007 | B10: Измерение поведения с первого дня | C10: Аналитическая | D10: Решение о следующем релизе по данным | E10: Внутренний администратор | F10: События аналитики + форма обратной связи | G10: Run, экспорт, лимит, заявка → события | H10: — | I10: A-009 | J10: 3 | K10: 4 | L10: =IF(A10="","",IF(COUNTA(D10:I10)>=5,1,0)) -> 1 | M10: =IF(A10="","",IFERROR(J10*K10*L10/20,0)) -> 0.6 | N10: В разработку
L11: =IF(A11="","",IF(COUNTA(D11:I11)>=5,1,0)) | M11: =IF(A11="","",IFERROR(J11*K11*L11/20,0))
L12: =IF(A12="","",IF(COUNTA(D12:I12)>=5,1,0)) | M12: =IF(A12="","",IFERROR(J12*K12*L12/20,0))
L13: =IF(A13="","",IF(COUNTA(D13:I13)>=5,1,0)) | M13: =IF(A13="","",IFERROR(J13*K13*L13/20,0))
L14: =IF(A14="","",IF(COUNTA(D14:I14)>=5,1,0)) | M14: =IF(A14="","",IFERROR(J14*K14*L14/20,0))
L15: =IF(A15="","",IF(COUNTA(D15:I15)>=5,1,0)) | M15: =IF(A15="","",IFERROR(J15*K15*L15/20,0))
L16: =IF(A16="","",IF(COUNTA(D16:I16)>=5,1,0)) | M16: =IF(A16="","",IFERROR(J16*K16*L16/20,0))
L17: =IF(A17="","",IF(COUNTA(D17:I17)>=5,1,0)) | M17: =IF(A17="","",IFERROR(J17*K17*L17/20,0))
L18: =IF(A18="","",IF(COUNTA(D18:I18)>=5,1,0)) | M18: =IF(A18="","",IFERROR(J18*K18*L18/20,0))
L19: =IF(A19="","",IF(COUNTA(D19:I19)>=5,1,0)) | M19: =IF(A19="","",IFERROR(J19*K19*L19/20,0))
L20: =IF(A20="","",IF(COUNTA(D20:I20)>=5,1,0)) | M20: =IF(A20="","",IFERROR(J20*K20*L20/20,0))
L21: =IF(A21="","",IF(COUNTA(D21:I21)>=5,1,0)) | M21: =IF(A21="","",IFERROR(J21*K21*L21/20,0))
L22: =IF(A22="","",IF(COUNTA(D22:I22)>=5,1,0)) | M22: =IF(A22="","",IFERROR(J22*K22*L22/20,0))
... L203: =IF(A203="","",IF(COUNTA(D203:I203)>=5,1,0)) | M203: =IF(A203="","",IFERROR(J203*K203*L203/20,0))

Sheet Роли и сегменты
A1: Роли пользователей и потребительские сегменты
A3: ID роли | B3: Роль / сегмент | C3: Потребительская задача | D3: Проблема | E3: Мотивация | F3: Ограничения | G3: Готовность платить (1-5) | H3: Частота потребности (1-5) | I3: Ценность сегмента | J3: Канал входа | K3: Связанный блок Канвас | L3: Основание из анализа | M3: Доказательность (1-4) | N3: Статус
A4: R-001 | B4: Посетитель | C4: Понять, подойдёт ли инструмент для IDEF0/DFD/UML задания | D4: Неясно, чем лучше draw.io и PlantUML | E4: Сэкономить время на лабораторной | F4: Недоверие к новому продукту | G4: 1 | H4: 3 | I4: =IF(A4="","",IFERROR(G4*H4,"")) -> 3 | J4: Органический поиск | K4: Потребительские сегменты | L4: A-005 | M4: 3 | N4: Требует проверки
A5: R-002 | B5: Новый пользователь | C5: Получить первую корректную диаграмму | D5: Незнаком синтаксис DSL | E5: Быстрый результат без обучения | F5: Время, порог входа (P-005) | G5: 2 | H5: 4 | I5: =IF(A5="","",IFERROR(G5*H5,"")) -> 8 | J5: Лендинг / гостевой режим | K5: Потребительские сегменты | L5: A-007 | M5: 3 | N5: Требует проверки
A6: R-003 | B6: Активный пользователь | C6: Регулярно строить и сдавать диаграммы (S-01) | D6: Ручная раскладка, замечания по нотации (P-001) | E6: Сдать работу без возврата | F6: Бюджет 0, срок сдачи | G6: 2 | H6: 5 | I6: =IF(A6="","",IFERROR(G6*H6,"")) -> 10 | J6: Прямой вход / аккаунт | K6: Ценностные предложения | L6: A-001 | M6: 3 | N6: Требует проверки
A7: R-004 | B7: Потенциальный клиент | C7: Работать без лимитов Free (S-02/S-03, дипломники) | D7: Упор в 5 проектов / 20 версий / форматы | E7: Непрерывность работы | F7: Цена, способ оплаты в РБ | G7: 4 | H7: 4 | I7: =IF(A7="","",IFERROR(G7*H7,"")) -> 16 | J7: Уведомление о лимите | K7: Потоки доходов | L7: A-003 | M7: 2 | N7: Требует проверки
A8: R-005 | B8: Платящий клиент | C8: Вести модели как код с полной историей и экспортом | D8: Рассинхронизация модели и требований (P-002) | E8: Контроль и прозрачность | F8: Интеграции, формат экспорта | G8: 5 | H8: 4 | I8: =IF(A8="","",IFERROR(G8*H8,"")) -> 20 | J8: Прямой вход | K8: Потоки доходов | L8: A-003 | M8: 2 | N8: Требует проверки
A9: R-006 | B9: Партнер | C9: Преподаватель: готовить примеры и задания (S-04), влияет на выбор студентов | D9: Ручная проверка правил (P-008) | E9: Воспроизводимые примеры | F9: Нет времени на новый инструмент | G9: 2 | H9: 3 | I9: =IF(A9="","",IFERROR(G9*H9,"")) -> 6 | J9: Рекомендация | K9: Каналы | L9: A-007 | M9: 1 | N9: Черновик
A10: R-007 | B10: Внутренний администратор | C10: PO: вести каталог шаблонов, следить за метриками | D10: Нужны данные для решений | E10: Решение о следующем релизе | F10: Один человек в команде | G10: 1 | H10: 5 | I10: =IF(A10="","",IFERROR(G10*H10,"")) -> 5 | J10: Внутренний переход | K10: Ключевые виды деятельности | L10: A-009 | M10: 3 | N10: Подтверждено
I11: =IF(A11="","",IFERROR(G11*H11,""))
I12: =IF(A12="","",IFERROR(G12*H12,""))
I13: =IF(A13="","",IFERROR(G13*H13,""))
I14: =IF(A14="","",IFERROR(G14*H14,""))
I15: =IF(A15="","",IFERROR(G15*H15,""))
I16: =IF(A16="","",IFERROR(G16*H16,""))
I17: =IF(A17="","",IFERROR(G17*H17,""))
I18: =IF(A18="","",IFERROR(G18*H18,""))
I19: =IF(A19="","",IFERROR(G19*H19,""))
I20: =IF(A20="","",IFERROR(G20*H20,""))
I21: =IF(A21="","",IFERROR(G21*H21,""))
I22: =IF(A22="","",IFERROR(G22*H22,""))
... I203: =IF(A203="","",IFERROR(G203*H203,""))

Sheet Пользовательские сценарии
A1: Пользовательские сценарии: от проблемы к действию и монетизации
A3: ID сценария | B3: Название сценария | C3: Роль | D3: Этап | E3: Тип сценария | F3: Исходная проблема | G3: Цель пользователя | H3: Триггер | I3: Основной путь | J3: Альтернативный путь / ошибка | K3: Результат для пользователя | L3: Результат для бизнес-модели | M3: Единица монетизации | N3: Частота потребности (1-5) | O3: Значимость проблемы (1-5) | P3: Влияние на выручку (1-5) | Q3: Доказательность (1-4) | R3: Индекс сценария | S3: Приоритет | T3: Статус | U3: Источник анализа
A4: S-001 | B4: Найти инструмент для IDEF0/DFD по поисковому запросу | C4: Посетитель | D4: Привлечение | E4: Вспомогательный | F4: P-001 | G4: Найти, чем быстро построить диаграмму | H4: Задание лабораторной | I4: Поиск → лендинг → блок «проверка правил» → «Открыть редактор» | J4: Уход на draw.io | K4: Понял ценность | L4: Трафик в воронку | M4: — | N4: 4 | O4: 4 | P4: 2 | Q4: 3 | R4: =IF(A4="","",IFERROR(N4*O4*P4*Q4/20,0)) -> 4.8 | S4: =IF(R4="","",IF(R4>=15,"Критический",IF(R4>=9,"Высокий",IF(R4>=5,"Средний",IF(R4>=2,"Низкий","Отложить"))))) -> Низкий | T4: Требует проверки | U4: A-005
A5: S-002 | B5: Сравнить NotaCode с draw.io/PlantUML и проверить на примере | C5: Посетитель | D5: Первичный интерес | E5: Вспомогательный | F5: P-001 | G5: Убедиться, что инструмент подходит | H5: Сомнение после лендинга | I5: Галерея примеров → сравнение → открыть пример в редакторе | J5: Нет нужной нотации → волны 2–3 | K5: Доверие | L5: Конверсия в первый Run | M5: — | N5: 3 | O5: 4 | P5: 2 | Q5: 3 | R5: =IF(A5="","",IFERROR(N5*O5*P5*Q5/20,0)) -> 3.6 | S5: =IF(R5="","",IF(R5>=15,"Критический",IF(R5>=9,"Высокий",IF(R5>=5,"Средний",IF(R5>=2,"Низкий","Отложить"))))) -> Низкий | T5: Требует проверки | U5: A-001
A6: S-003 | B6: Получить первую диаграмму из шаблона без регистрации | C6: Новый пользователь | D6: Получение ценности | E6: Основной | F6: P-005 | G6: Первый результат за минуты | H6: Открыл редактор | I6: Выбор нотации → шаблон → Run → диаграмма + подсветка | J6: Ошибка DSL → Problems | K6: Первая ценность | L6: Активация | M6: Free | N6: 4 | O6: 5 | P6: 3 | Q6: 3 | R6: =IF(A6="","",IFERROR(N6*O6*P6*Q6/20,0)) -> 9 | S6: =IF(R6="","",IF(R6>=15,"Критический",IF(R6>=9,"Высокий",IF(R6>=5,"Средний",IF(R6>=2,"Низкий","Отложить"))))) -> Высокий | T6: Требует проверки | U6: A-004
A7: S-004 | B7: Построить диаграмму IDEF0 по заданию с проверкой правил | C7: Активный пользователь | D7: Получение ценности | E7: Основной | F7: P-001 | G7: Сдать корректную диаграмму | H7: Лабораторная работа | I7: Написать DSL → Run → Problems (код правила, строка) → исправить → OK | J7: Нарушение правила → quick fix (R2) / AI | K7: Корректная диаграмма | L7: Ядро ценности, удержание | M7: Free | N7: 5 | O7: 5 | P7: 3 | Q7: 3 | R7: =IF(A7="","",IFERROR(N7*O7*P7*Q7/20,0)) -> 11.25 | S7: =IF(R7="","",IF(R7>=15,"Критический",IF(R7>=9,"Высокий",IF(R7>=5,"Средний",IF(R7>=2,"Низкий","Отложить"))))) -> Высокий | T7: Требует проверки | U7: A-001
A8: S-005 | B8: Сохранить проект и экспортировать SVG/PNG в отчёт | C8: Активный пользователь | D8: Получение ценности | E8: Основной | F8: P-001 | G8: Вставить диаграмму в отчёт | H8: Диаграмма готова | I8: Save → аккаунт/устройство/GitHub → Export SVG/PNG | J8: Лимит 5 проектов → S-007 | K8: Файл для отчёта | L8: Упор в лимит | M8: Free / Pro | N8: 5 | O8: 4 | P8: 3 | Q8: 4 | R8: =IF(A8="","",IFERROR(N8*O8*P8*Q8/20,0)) -> 12 | S8: =IF(R8="","",IF(R8>=15,"Критический",IF(R8>=9,"Высокий",IF(R8>=5,"Средний",IF(R8>=2,"Низкий","Отложить"))))) -> Высокий | T8: Подтверждено | U8: A-006
A9: S-006 | B9: Вернуться к проекту, сравнить версии и откатиться | C9: Активный пользователь | D9: Повторное использование | E9: Удерживающий | F9: P-003 | G9: Исправить по замечаниям без потери работы | H9: Замечание преподавателя | I9: Проекты → история → diff → откат | J9: 21-я версия → лимит Free | K9: Сохранённая работа | L9: Удержание D7 | M9: Pro (полная история) | N9: 3 | O9: 4 | P9: 3 | Q9: 3 | R9: =IF(A9="","",IFERROR(N9*O9*P9*Q9/20,0)) -> 5.4 | S9: =IF(R9="","",IF(R9>=15,"Критический",IF(R9>=9,"Высокий",IF(R9>=5,"Средний",IF(R9>=2,"Низкий","Отложить"))))) -> Средний | T9: Требует проверки | U9: A-006
A10: S-007 | B10: Перейти на Pro после упора в лимит Free | C10: Потенциальный клиент | D10: Оплата | E10: Монетизационный | F10: P-002 | G10: Продолжить работу без лимитов | H10: Лимит проектов/версий/формата | I10: Модалка лимита → тарифы → заявка «Хочу Pro» (R1) / оплата (R2) → снятие лимита | J10: Ошибка оплаты → повтор, данные сохранены | K10: Работа без ограничений | L10: Поток доходов | M10: Подписка Pro | N10: 3 | O10: 4 | P10: 5 | Q10: 2 | R10: =IF(A10="","",IFERROR(N10*O10*P10*Q10/20,0)) -> 6 | S10: =IF(R10="","",IF(R10>=15,"Критический",IF(R10>=9,"Высокий",IF(R10>=5,"Средний",IF(R10>=2,"Низкий","Отложить"))))) -> Средний | T10: Требует проверки | U10: A-003
A11: S-008 | B11: Восстановиться после ошибки DSL или правила нотации | C11: Активный пользователь | D11: Поддержка | E11: Сервисный | F11: P-006 | G11: Понять и исправить ошибку | H11: Run вернул Error | I11: Маркер в редакторе → Problems → подсветка элемента → AI «Исправить ошибку» | J11: AI недоступен → документация | K11: Исправленная диаграмма | L11: Снижение оттока | M11: — | N11: 5 | O11: 4 | P11: 2 | Q11: 3 | R11: =IF(A11="","",IFERROR(N11*O11*P11*Q11/20,0)) -> 6 | S11: =IF(R11="","",IF(R11>=15,"Критический",IF(R11>=9,"Высокий",IF(R11>=5,"Средний",IF(R11>=2,"Низкий","Отложить"))))) -> Средний | T11: Требует проверки | U11: A-002
A12: S-009 | B12: Спросить по синтаксису и теории нотации | C12: Новый пользователь | D12: Поддержка | E12: Сервисный | F12: P-005 | G12: Узнать, как записать элемент | H12: Не знает синтаксиса | I12: Документация / AI «Спросить по документации» → пример → вставка | J12: Нет ответа → обратная связь | K12: Знание синтаксиса | L12: Активация | M12: — | N12: 4 | O12: 3 | P12: 1 | Q12: 3 | R12: =IF(A12="","",IFERROR(N12*O12*P12*Q12/20,0)) -> 1.8 | S12: =IF(R12="","",IF(R12>=15,"Критический",IF(R12>=9,"Высокий",IF(R12>=5,"Средний",IF(R12>=2,"Низкий","Отложить"))))) -> Отложить | T12: Требует проверки | U12: A-006
A13: S-010 | B13: Сгенерировать DSL по текстовому описанию (AI) | C13: Активный пользователь | D13: Получение ценности | E13: Основной | F13: P-005 | G13: Черновик диаграммы из описания | H13: Есть текст задания | I13: AI «Написать код» → нотация/тип → предпросмотр → Применить → Run | J13: Заглушка/нет ключа → BYOK | K13: Черновик DSL | L13: Pro-квота (R4) | M13: Pro (после MVP) | N13: 3 | O13: 3 | P13: 3 | Q13: 2 | R13: =IF(A13="","",IFERROR(N13*O13*P13*Q13/20,0)) -> 2.7 | S13: =IF(R13="","",IF(R13>=15,"Критический",IF(R13>=9,"Высокий",IF(R13>=5,"Средний",IF(R13>=2,"Низкий","Отложить"))))) -> Низкий | T13: Требует проверки | U13: A-006
A14: S-011 | B14: Опубликовать шаблон и обновить каталог нотаций | C14: Внутренний администратор | D14: Поддержка | E14: Административный | F14: P-005 | G14: Пополнить шаблоны | H14: Новая нотация/запрос | I14: Шаблон → проверка валидатором → публикация | J14: Ошибка валидации | K14: Новый шаблон | L14: Качество товара | M14: — | N14: 2 | O14: 3 | P14: 1 | Q14: 3 | R14: =IF(A14="","",IFERROR(N14*O14*P14*Q14/20,0)) -> 0.9 | S14: =IF(R14="","",IF(R14>=15,"Критический",IF(R14>=9,"Высокий",IF(R14>=5,"Средний",IF(R14>=2,"Низкий","Отложить"))))) -> Отложить | T14: В разработку | U14: A-009
A15: S-012 | B15: Подготовить пример для группы и поделиться ссылкой | C15: Партнер | D15: Расширение потребления | E15: Партнерский | F15: P-008 | G15: Выдать пример студентам | H15: Подготовка занятия | I15: Проект → публичная ссылка → студенты открывают копию | J15: Ссылка недоступна | K15: Готовое задание | L15: Рост через кафедры | M15: Кафедральный тариф (гипотеза) | N15: 2 | O15: 3 | P15: 3 | Q15: 1 | R15: =IF(A15="","",IFERROR(N15*O15*P15*Q15/20,0)) -> 0.9 | S15: =IF(R15="","",IF(R15>=15,"Критический",IF(R15>=9,"Высокий",IF(R15>=5,"Средний",IF(R15>=2,"Низкий","Отложить"))))) -> Отложить | T15: Черновик | U15: A-007
A16: S-013 | B16: Получить уведомление о завершении синхронизации и продолжить работу | C16: Активный пользователь | D16: Удержание | E16: Удерживающий | F16: P-003 | G16: Знать, что работа сохранена | H16: Push в GitHub | I16: Save ▸ GitHub → тост → статус-бар «Pushed» | J16: SyncFailed → повтор | K16: Уверенность в сохранности | L16: Удержание | M16: Pro (автосинхронизация) | N16: 3 | O16: 3 | P16: 2 | Q16: 3 | R16: =IF(A16="","",IFERROR(N16*O16*P16*Q16/20,0)) -> 2.7 | S16: =IF(R16="","",IF(R16>=15,"Критический",IF(R16>=9,"Высокий",IF(R16>=5,"Средний",IF(R16>=2,"Низкий","Отложить"))))) -> Низкий | T16: Требует проверки | U16: A-006
R17: =IF(A17="","",IFERROR(N17*O17*P17*Q17/20,0)) | S17: =IF(R17="","",IF(R17>=15,"Критический",IF(R17>=9,"Высокий",IF(R17>=5,"Средний",IF(R17>=2,"Низкий","Отложить")))))
R18: =IF(A18="","",IFERROR(N18*O18*P18*Q18/20,0)) | S18: =IF(R18="","",IF(R18>=15,"Критический",IF(R18>=9,"Высокий",IF(R18>=5,"Средний",IF(R18>=2,"Низкий","Отложить")))))
R19: =IF(A19="","",IFERROR(N19*O19*P19*Q19/20,0)) | S19: =IF(R19="","",IF(R19>=15,"Критический",IF(R19>=9,"Высокий",IF(R19>=5,"Средний",IF(R19>=2,"Низкий","Отложить")))))
R20: =IF(A20="","",IFERROR(N20*O20*P20*Q20/20,0)) | S20: =IF(R20="","",IF(R20>=15,"Критический",IF(R20>=9,"Высокий",IF(R20>=5,"Средний",IF(R20>=2,"Низкий","Отложить")))))
R21: =IF(A21="","",IFERROR(N21*O21*P21*Q21/20,0)) | S21: =IF(R21="","",IF(R21>=15,"Критический",IF(R21>=9,"Высокий",IF(R21>=5,"Средний",IF(R21>=2,"Низкий","Отложить")))))
R22: =IF(A22="","",IFERROR(N22*O22*P22*Q22/20,0)) | S22: =IF(R22="","",IF(R22>=15,"Критический",IF(R22>=9,"Высокий",IF(R22>=5,"Средний",IF(R22>=2,"Низкий","Отложить")))))
R23: =IF(A23="","",IFERROR(N23*O23*P23*Q23/20,0)) | S23: =IF(R23="","",IF(R23>=15,"Критический",IF(R23>=9,"Высокий",IF(R23>=5,"Средний",IF(R23>=2,"Низкий","Отложить")))))
R24: =IF(A24="","",IFERROR(N24*O24*P24*Q24/20,0)) | S24: =IF(R24="","",IF(R24>=15,"Критический",IF(R24>=9,"Высокий",IF(R24>=5,"Средний",IF(R24>=2,"Низкий","Отложить")))))
R25: =IF(A25="","",IFERROR(N25*O25*P25*Q25/20,0)) | S25: =IF(R25="","",IF(R25>=15,"Критический",IF(R25>=9,"Высокий",IF(R25>=5,"Средний",IF(R25>=2,"Низкий","Отложить")))))
R26: =IF(A26="","",IFERROR(N26*O26*P26*Q26/20,0)) | S26: =IF(R26="","",IF(R26>=15,"Критический",IF(R26>=9,"Высокий",IF(R26>=5,"Средний",IF(R26>=2,"Низкий","Отложить")))))
R27: =IF(A27="","",IFERROR(N27*O27*P27*Q27/20,0)) | S27: =IF(R27="","",IF(R27>=15,"Критический",IF(R27>=9,"Высокий",IF(R27>=5,"Средний",IF(R27>=2,"Низкий","Отложить")))))
R28: =IF(A28="","",IFERROR(N28*O28*P28*Q28/20,0)) | S28: =IF(R28="","",IF(R28>=15,"Критический",IF(R28>=9,"Высокий",IF(R28>=5,"Средний",IF(R28>=2,"Низкий","Отложить")))))
... R203: =IF(A203="","",IFERROR(N203*O203*P203*Q203/20,0)) | S203: =IF(R203="","",IF(R203>=15,"Критический",IF(R203>=9,"Высокий",IF(R203>=5,"Средний",IF(R203>=2,"Низкий","Отложить")))))

Sheet Карта сценариев
A1: Карта прохождения пользовательских сценариев по этапам взаимодействия
A3: ID сценария | B3: Роль | C3: Сценарий | D3: Привлечение | E3: Первичный интерес | F3: Регистрация | G3: Настройка | H3: Получение ценности | I3: Оплата | J3: Повторное использование | K3: Поддержка | L3: Удержание | M3: Разрыв / риск | N3: Критическая точка | O3: Комментарий
A4: S-003 | B4: Новый пользователь | C4: Первая диаграмма из шаблона | D4: Поиск IDEF0 | E4: Лендинг | F4: Не нужна (гость) | G4: Выбор нотации | H4: Первый Run OK | J4: Сохранение в аккаунт | K4: Документация | L4: Предложение сохранить | M4: Ошибка DSL на первом Run | N4: Получение ценности
A5: S-004 | B5: Активный пользователь | C5: IDEF0 по заданию | F5: Аккаунт | G5: Шаблон IDEF0 | H5: Диагностика правил → OK | J5: Следующая лабораторная | K5: Problems + AI | L5: История версий | M5: Непонятный код правила | N5: Получение ценности
A6: S-007 | B6: Потенциальный клиент | C6: Переход на Pro | E6: Страница тарифов | F6: Аккаунт | H6: Работа в Free | I6: Заявка / оплата Pro | J6: Pro без лимитов | K6: Помощь при оплате | L6: Напоминание о продлении | M6: Нет провайдера оплаты в R1 | N6: Оплата | O6: В R1 — заявка «Хочу Pro»
A7: S-008 | B7: Активный пользователь | C7: Восстановление после ошибки | H7: Исправленный Run | K7: Problems, подсветка, AI | L7: Доверие к инструменту | M7: AI-заглушка не исправляет | N7: Поддержка
A8: S-006 | B8: Активный пользователь | C8: История и откат | I8: Лимит 20 версий → Pro | J8: Возврат к проекту | L8: Накопленная история | M8: Нет уведомления о лимите | N8: Повторное использование

Sheet Функциональные требования
A1: Перевод пользовательских сценариев в функциональные требования
A3: ID требования | B3: Требование | C3: Связанный сценарий | D3: Роль | E3: Пользовательская задача | F3: Бизнес-цель | G3: Категория Кано | H3: Уровень товара по Левитту | I3: Влияние на ценность (1-5) | J3: Влияние на монетизацию (1-5) | K3: Сложность реализации (1-5) | L3: Доказательность (1-4) | M3: Индекс приоритета | N3: Приоритет | O3: MVP | P3: Статус | Q3: Источник
A4: F-001 | B4: DSL-редактор с подсветкой и подсказками (Monaco) | C4: S-004 | D4: Активный пользователь | E4: Писать код диаграммы | F4: Ядро товара | G4: Базовое требование | H4: Базовый товар | I4: 5 | J4: 3 | K4: 2 | L4: 4 | M4: =IF(A4="","",IFERROR((I4+J4)*L4/K4,0)) -> 16 | N4: =IF(M4="","",IF(M4>=16,"Критический",IF(M4>=10,"Высокий",IF(M4>=6,"Средний",IF(M4>=3,"Низкий","Отложить"))))) -> Критический | O4: =IF(M4="","",IF(OR(N4="Критический",N4="Высокий"),"Да",IF(N4="Средний","Кандидат","Нет"))) -> Да | P4: В разработку | Q4: BR-01, E4
A5: F-002 | B5: Разбор DSL и валидация правил нотаций волны 1 (код правила, строка) | C5: S-004 | D5: Активный пользователь | E5: Проверить работу до сдачи | F5: Отличие D-02 | G5: Восхищающее требование | H5: Расширенный товар | I5: 5 | J5: 4 | K5: 4 | L5: 3 | M5: =IF(A5="","",IFERROR((I5+J5)*L5/K5,0)) -> 6.75 | N5: =IF(M5="","",IF(M5>=16,"Критический",IF(M5>=10,"Высокий",IF(M5>=6,"Средний",IF(M5>=3,"Низкий","Отложить"))))) -> Средний | O5: =IF(M5="","",IF(OR(N5="Критический",N5="Высокий"),"Да",IF(N5="Средний","Кандидат","Нет"))) -> Кандидат | P5: В разработку | Q5: BR-02, BR-04, E2, E3
A6: F-003 | B6: Холст SVG + elkjs, pan/zoom, сетка | C6: S-003 | D6: Новый пользователь | E6: Увидеть диаграмму | F6: Ядро товара | G6: Базовое требование | H6: Базовый товар | I6: 5 | J6: 3 | K6: 3 | L6: 4 | M6: =IF(A6="","",IFERROR((I6+J6)*L6/K6,0)) -> 10.666667 | N6: =IF(M6="","",IF(M6>=16,"Критический",IF(M6>=10,"Высокий",IF(M6>=6,"Средний",IF(M6>=3,"Низкий","Отложить"))))) -> Высокий | O6: =IF(M6="","",IF(OR(N6="Критический",N6="Высокий"),"Да",IF(N6="Средний","Кандидат","Нет"))) -> Да | P6: В разработку | Q6: BR-08, E5
A7: F-004 | B7: Кросс-подсветка строка ↔ элемент | C7: S-008 | D7: Активный пользователь | E7: Найти место ошибки | F7: Отличие D-03 | G7: Восхищающее требование | H7: Расширенный товар | I7: 4 | J7: 2 | K7: 3 | L7: 3 | M7: =IF(A7="","",IFERROR((I7+J7)*L7/K7,0)) -> 6 | N7: =IF(M7="","",IF(M7>=16,"Критический",IF(M7>=10,"Высокий",IF(M7>=6,"Средний",IF(M7>=3,"Низкий","Отложить"))))) -> Средний | O7: =IF(M7="","",IF(OR(N7="Критический",N7="Высокий"),"Да",IF(N7="Средний","Кандидат","Нет"))) -> Кандидат | P7: В разработку | Q7: BR-07, E5
A8: F-005 | B8: Шаблоны нотаций и вкладка документации | C8: S-003 | D8: Новый пользователь | E8: Начать без знания синтаксиса | F8: Активация | G8: Базовое требование | H8: Ожидаемый товар | I8: 4 | J8: 2 | K8: 2 | L8: 4 | M8: =IF(A8="","",IFERROR((I8+J8)*L8/K8,0)) -> 12 | N8: =IF(M8="","",IF(M8>=16,"Критический",IF(M8>=10,"Высокий",IF(M8>=6,"Средний",IF(M8>=3,"Низкий","Отложить"))))) -> Высокий | O8: =IF(M8="","",IF(OR(N8="Критический",N8="Высокий"),"Да",IF(N8="Средний","Кандидат","Нет"))) -> Да | P8: В разработку | Q8: BR-10, BR-11
A9: F-006 | B9: Сохранение в аккаунт (лимит Free 5 проектов) и на устройство | C9: S-005 | D9: Активный пользователь | E9: Не потерять работу | F9: Упор в лимит → Pro | G9: Базовое требование | H9: Ожидаемый товар | I9: 4 | J9: 4 | K9: 2 | L9: 4 | M9: =IF(A9="","",IFERROR((I9+J9)*L9/K9,0)) -> 16 | N9: =IF(M9="","",IF(M9>=16,"Критический",IF(M9>=10,"Высокий",IF(M9>=6,"Средний",IF(M9>=3,"Низкий","Отложить"))))) -> Критический | O9: =IF(M9="","",IF(OR(N9="Критический",N9="Высокий"),"Да",IF(N9="Средний","Кандидат","Нет"))) -> Да | P9: В разработку | Q9: BR-12, E7
A10: F-007 | B10: Экспорт SVG/PNG/XML | C10: S-005 | D10: Активный пользователь | E10: Вставить в отчёт | F10: Результат наружу | G10: Базовое требование | H10: Базовый товар | I10: 5 | J10: 3 | K10: 2 | L10: 4 | M10: =IF(A10="","",IFERROR((I10+J10)*L10/K10,0)) -> 16 | N10: =IF(M10="","",IF(M10>=16,"Критический",IF(M10>=10,"Высокий",IF(M10>=6,"Средний",IF(M10>=3,"Низкий","Отложить"))))) -> Критический | O10: =IF(M10="","",IF(OR(N10="Критический",N10="Высокий"),"Да",IF(N10="Средний","Кандидат","Нет"))) -> Да | P10: В разработку | Q10: BR-13, E8
A11: F-008 | B11: История версий, diff, откат (Free — 20 версий) | C11: S-006 | D11: Активный пользователь | E11: Исправить по замечаниям | F11: Удержание, Pro | G11: Линейное требование | H11: Ожидаемый товар | I11: 4 | J11: 4 | K11: 3 | L11: 3 | M11: =IF(A11="","",IFERROR((I11+J11)*L11/K11,0)) -> 8 | N11: =IF(M11="","",IF(M11>=16,"Критический",IF(M11>=10,"Высокий",IF(M11>=6,"Средний",IF(M11>=3,"Низкий","Отложить"))))) -> Средний | O11: =IF(M11="","",IF(OR(N11="Критический",N11="Высокий"),"Да",IF(N11="Средний","Кандидат","Нет"))) -> Кандидат | P11: В разработку | Q11: BR-16, E6
A12: F-009 | B12: Страница тарифов + заявка «Хочу Pro» + модалка лимита | C12: S-007 | D12: Потенциальный клиент | E12: Понять, за что платить | F12: Проверка монетизации | G12: Линейное требование | H12: Ожидаемый товар | I12: 3 | J12: 5 | K12: 1 | L12: 2 | M12: =IF(A12="","",IFERROR((I12+J12)*L12/K12,0)) -> 16 | N12: =IF(M12="","",IF(M12>=16,"Критический",IF(M12>=10,"Высокий",IF(M12>=6,"Средний",IF(M12>=3,"Низкий","Отложить"))))) -> Критический | O12: =IF(M12="","",IF(OR(N12="Критический",N12="Высокий"),"Да",IF(N12="Средний","Кандидат","Нет"))) -> Да | P12: Требует проверки | Q12: BR-24
A13: F-010 | B13: AI-ассистент: заглушка + BYOK, 4 режима | C13: S-010 | D13: Активный пользователь | E13: Черновик по описанию | F13: Восхищающий признак рынка | G13: Восхищающее требование | H13: Расширенный товар | I13: 3 | J13: 3 | K13: 3 | L13: 2 | M13: =IF(A13="","",IFERROR((I13+J13)*L13/K13,0)) -> 4 | N13: =IF(M13="","",IF(M13>=16,"Критический",IF(M13>=10,"Высокий",IF(M13>=6,"Средний",IF(M13>=3,"Низкий","Отложить"))))) -> Низкий | O13: =IF(M13="","",IF(OR(N13="Критический",N13="Высокий"),"Да",IF(N13="Средний","Кандидат","Нет"))) -> Нет | P13: В разработку | Q13: BR-15, E9
A14: F-011 | B14: События аналитики + форма обратной связи | C14: S-003 | D14: Внутренний администратор | E14: Измерить поведение | F14: Решение о R2 | G14: Нейтральный признак | H14: Базовый товар | I14: 3 | J14: 3 | K14: 1 | L14: 3 | M14: =IF(A14="","",IFERROR((I14+J14)*L14/K14,0)) -> 18 | N14: =IF(M14="","",IF(M14>=16,"Критический",IF(M14>=10,"Высокий",IF(M14>=6,"Средний",IF(M14>=3,"Низкий","Отложить"))))) -> Критический | O14: =IF(M14="","",IF(OR(N14="Критический",N14="Высокий"),"Да",IF(N14="Средний","Кандидат","Нет"))) -> Да | P14: Требует проверки | Q14: Методика 6.5
A15: F-012 | B15: Автоисправление quick fix | C15: S-008 | D15: Активный пользователь | E15: Исправить в один клик | F15: Отличие D-02 | G15: Восхищающее требование | H15: Расширенный товар | I15: 4 | J15: 2 | K15: 4 | L15: 2 | M15: =IF(A15="","",IFERROR((I15+J15)*L15/K15,0)) -> 3 | N15: =IF(M15="","",IF(M15>=16,"Критический",IF(M15>=10,"Высокий",IF(M15>=6,"Средний",IF(M15>=3,"Низкий","Отложить"))))) -> Низкий | O15: =IF(M15="","",IF(OR(N15="Критический",N15="Высокий"),"Да",IF(N15="Средний","Кандидат","Нет"))) -> Нет | P15: Черновик | Q15: BR-05 (Should)
... A17: F-014 | B17: Публичная ссылка на проект | C17: S-012 | D17: Партнер | E17: Поделиться примером | F17: Рост | G17: Линейное требование | H17: Потенциальный товар | I17: 3 | J17: 2 | K17: 3 | L17: 1 | M17: =IF(A17="","",IFERROR((I17+J17)*L17/K17,0)) -> 1.6666667 | N17: =IF(M17="","",IF(M17>=16,"Критический",IF(M17>=10,"Высокий",IF(M17>=6,"Средний",IF(M17>=3,"Низкий","Отложить"))))) -> Отложить | O17: =IF(M17="","",IF(OR(N17="Критический",N17="Высокий"),"Да",IF(N17="Средний","Кандидат","Нет"))) -> Нет | P17: Черновик | Q17: R3
M18: =IF(A18="","",IFERROR((I18+J18)*L18/K18,0)) | N18: =IF(M18="","",IF(M18>=16,"Критический",IF(M18>=10,"Высокий",IF(M18>=6,"Средний",IF(M18>=3,"Низкий","Отложить"))))) | O18: =IF(M18="","",IF(OR(N18="Критический",N18="Высокий"),"Да",IF(N18="Средний","Кандидат","Нет")))
M19: =IF(A19="","",IFERROR((I19+J19)*L19/K19,0)) | N19: =IF(M19="","",IF(M19>=16,"Критический",IF(M19>=10,"Высокий",IF(M19>=6,"Средний",IF(M19>=3,"Низкий","Отложить"))))) | O19: =IF(M19="","",IF(OR(N19="Критический",N19="Высокий"),"Да",IF(N19="Средний","Кандидат","Нет")))
M20: =IF(A20="","",IFERROR((I20+J20)*L20/K20,0)) | N20: =IF(M20="","",IF(M20>=16,"Критический",IF(M20>=10,"Высокий",IF(M20>=6,"Средний",IF(M20>=3,"Низкий","Отложить"))))) | O20: =IF(M20="","",IF(OR(N20="Критический",N20="Высокий"),"Да",IF(N20="Средний","Кандидат","Нет")))
M21: =IF(A21="","",IFERROR((I21+J21)*L21/K21,0)) | N21: =IF(M21="","",IF(M21>=16,"Критический",IF(M21>=10,"Высокий",IF(M21>=6,"Средний",IF(M21>=3,"Низкий","Отложить"))))) | O21: =IF(M21="","",IF(OR(N21="Критический",N21="Высокий"),"Да",IF(N21="Средний","Кандидат","Нет")))
M22: =IF(A22="","",IFERROR((I22+J22)*L22/K22,0)) | N22: =IF(M22="","",IF(M22>=16,"Критический",IF(M22>=10,"Высокий",IF(M22>=6,"Средний",IF(M22>=3,"Низкий","Отложить"))))) | O22: =IF(M22="","",IF(OR(N22="Критический",N22="Высокий"),"Да",IF(N22="Средний","Кандидат","Нет")))
M23: =IF(A23="","",IFERROR((I23+J23)*L23/K23,0)) | N23: =IF(M23="","",IF(M23>=16,"Критический",IF(M23>=10,"Высокий",IF(M23>=6,"Средний",IF(M23>=3,"Низкий","Отложить"))))) | O23: =IF(M23="","",IF(OR(N23="Критический",N23="Высокий"),"Да",IF(N23="Средний","Кандидат","Нет")))
M24: =IF(A24="","",IFERROR((I24+J24)*L24/K24,0)) | N24: =IF(M24="","",IF(M24>=16,"Критический",IF(M24>=10,"Высокий",IF(M24>=6,"Средний",IF(M24>=3,"Низкий","Отложить"))))) | O24: =IF(M24="","",IF(OR(N24="Критический",N24="Высокий"),"Да",IF(N24="Средний","Кандидат","Нет")))
M25: =IF(A25="","",IFERROR((I25+J25)*L25/K25,0)) | N25: =IF(M25="","",IF(M25>=16,"Критический",IF(M25>=10,"Высокий",IF(M25>=6,"Средний",IF(M25>=3,"Низкий","Отложить"))))) | O25: =IF(M25="","",IF(OR(N25="Критический",N25="Высокий"),"Да",IF(N25="Средний","Кандидат","Нет")))
M26: =IF(A26="","",IFERROR((I26+J26)*L26/K26,0)) | N26: =IF(M26="","",IF(M26>=16,"Критический",IF(M26>=10,"Высокий",IF(M26>=6,"Средний",IF(M26>=3,"Низкий","Отложить"))))) | O26: =IF(M26="","",IF(OR(N26="Критический",N26="Высокий"),"Да",IF(N26="Средний","Кандидат","Нет")))
M27: =IF(A27="","",IFERROR((I27+J27)*L27/K27,0)) | N27: =IF(M27="","",IF(M27>=16,"Критический",IF(M27>=10,"Высокий",IF(M27>=6,"Средний",IF(M27>=3,"Низкий","Отложить"))))) | O27: =IF(M27="","",IF(OR(N27="Критический",N27="Высокий"),"Да",IF(N27="Средний","Кандидат","Нет")))
M28: =IF(A28="","",IFERROR((I28+J28)*L28/K28,0)) | N28: =IF(M28="","",IF(M28>=16,"Критический",IF(M28>=10,"Высокий",IF(M28>=6,"Средний",IF(M28>=3,"Низкий","Отложить"))))) | O28: =IF(M28="","",IF(OR(N28="Критический",N28="Высокий"),"Да",IF(N28="Средний","Кандидат","Нет")))
M29: =IF(A29="","",IFERROR((I29+J29)*L29/K29,0)) | N29: =IF(M29="","",IF(M29>=16,"Критический",IF(M29>=10,"Высокий",IF(M29>=6,"Средний",IF(M29>=3,"Низкий","Отложить"))))) | O29: =IF(M29="","",IF(OR(N29="Критический",N29="Высокий"),"Да",IF(N29="Средний","Кандидат","Нет")))
... M203: =IF(A203="","",IFERROR((I203+J203)*L203/K203,0)) | N203: =IF(M203="","",IF(M203>=16,"Критический",IF(M203>=10,"Высокий",IF(M203>=6,"Средний",IF(M203>=3,"Низкий","Отложить"))))) | O203: =IF(M203="","",IF(OR(N203="Критический",N203="Высокий"),"Да",IF(N203="Средний","Кандидат","Нет")))

Sheet Приоритизация
A1: Приоритизация сценариев, функций и продуктовых инициатив
A3: ID инициативы | B3: Инициатива | C3: Тип | D3: Связанный сценарий | E3: Связанное требование | F3: Пользовательская ценность (1-5) | G3: Бизнес-эффект (1-5) | H3: Доказательность (1-4) | I3: Сложность (1-5) | J3: Риск (1-5) | K3: Итоговый индекс | L3: Решение | M3: Период реализации | N3: Комментарий
A4: P-001 | B4: Ядро: редактор + разбор + валидация + холст | C4: Сценарий + функция | D4: S-004 | E4: F-001, F-002, F-003 | F4: 5 | G4: 5 | H4: 3 | I4: 4 | J4: 3 | K4: =IF(A4="","",IFERROR((F4+G4+H4)*((6-J4)/5)/I4,0)) -> 1.95 | L4: =IF(K4="","",IF(K4>=6,"Включить в первую версию",IF(K4>=4,"Включить после проверки",IF(K4>=2.5,"Проверить дополнительно",IF(K4>=1.5,"Отложить","Исключить"))))) -> Отложить | M4: Первая версия (S2–S7)
A5: P-002 | B5: Первая диаграмма из шаблона без регистрации | C5: Сценарий + функция | D5: S-003 | E5: F-005 | F5: 5 | G5: 4 | H5: 3 | I5: 2 | J5: 2 | K5: =IF(A5="","",IFERROR((F5+G5+H5)*((6-J5)/5)/I5,0)) -> 4.8 | L5: =IF(K5="","",IF(K5>=6,"Включить в первую версию",IF(K5>=4,"Включить после проверки",IF(K5>=2.5,"Проверить дополнительно",IF(K5>=1.5,"Отложить","Исключить"))))) -> Включить после проверки | M5: Первая версия
A6: P-003 | B6: Сохранение и экспорт SVG/PNG | C6: Функция | D6: S-005 | E6: F-006, F-007 | F6: 5 | G6: 4 | H6: 4 | I6: 2 | J6: 1 | K6: =IF(A6="","",IFERROR((F6+G6+H6)*((6-J6)/5)/I6,0)) -> 6.5 | L6: =IF(K6="","",IF(K6>=6,"Включить в первую версию",IF(K6>=4,"Включить после проверки",IF(K6>=2.5,"Проверить дополнительно",IF(K6>=1.5,"Отложить","Исключить"))))) -> Включить в первую версию | M6: Первая версия
A7: P-004 | B7: Тарифы + заявка «Хочу Pro» | C7: Монетизация | D7: S-007 | E7: F-009 | F7: 3 | G7: 5 | H7: 2 | I7: 1 | J7: 2 | K7: =IF(A7="","",IFERROR((F7+G7+H7)*((6-J7)/5)/I7,0)) -> 8 | L7: =IF(K7="","",IF(K7>=6,"Включить в первую версию",IF(K7>=4,"Включить после проверки",IF(K7>=2.5,"Проверить дополнительно",IF(K7>=1.5,"Отложить","Исключить"))))) -> Включить в первую версию | M7: Первая версия
A8: P-005 | B8: Аналитика и обратная связь | C8: Аналитика | D8: S-003 | E8: F-011 | F8: 3 | G8: 4 | H8: 3 | I8: 1 | J8: 1 | K8: =IF(A8="","",IFERROR((F8+G8+H8)*((6-J8)/5)/I8,0)) -> 10 | L8: =IF(K8="","",IF(K8>=6,"Включить в первую версию",IF(K8>=4,"Включить после проверки",IF(K8>=2.5,"Проверить дополнительно",IF(K8>=1.5,"Отложить","Исключить"))))) -> Включить в первую версию | M8: Первая версия | N8: Нельзя переносить (6.5)
A9: P-006 | B9: История, diff, откат | C9: Функция | D9: S-006 | E9: F-008 | F9: 4 | G9: 4 | H9: 3 | I9: 3 | J9: 2 | K9: =IF(A9="","",IFERROR((F9+G9+H9)*((6-J9)/5)/I9,0)) -> 2.9333333 | L9: =IF(K9="","",IF(K9>=6,"Включить в первую версию",IF(K9>=4,"Включить после проверки",IF(K9>=2.5,"Проверить дополнительно",IF(K9>=1.5,"Отложить","Исключить"))))) -> Проверить дополнительно | M9: Первая версия (S8–S9)
A10: P-007 | B10: Кросс-подсветка | C10: Функция | D10: S-008 | E10: F-004 | F10: 4 | G10: 3 | H10: 3 | I10: 3 | J10: 2 | K10: =IF(A10="","",IFERROR((F10+G10+H10)*((6-J10)/5)/I10,0)) -> 2.6666667 | L10: =IF(K10="","",IF(K10>=6,"Включить в первую версию",IF(K10>=4,"Включить после проверки",IF(K10>=2.5,"Проверить дополнительно",IF(K10>=1.5,"Отложить","Исключить"))))) -> Проверить дополнительно | M10: Первая версия
A11: P-008 | B11: AI-заглушка/BYOK | C11: Функция | D11: S-010 | E11: F-010 | F11: 3 | G11: 3 | H11: 2 | I11: 3 | J11: 3 | K11: =IF(A11="","",IFERROR((F11+G11+H11)*((6-J11)/5)/I11,0)) -> 1.6 | L11: =IF(K11="","",IF(K11>=6,"Включить в первую версию",IF(K11>=4,"Включить после проверки",IF(K11>=2.5,"Проверить дополнительно",IF(K11>=1.5,"Отложить","Исключить"))))) -> Отложить | M11: Первая версия (заглушка)
A12: P-009 | B12: Quick fix | C12: Функция | D12: S-008 | E12: F-012 | F12: 4 | G12: 3 | H12: 2 | I12: 4 | J12: 3 | K12: =IF(A12="","",IFERROR((F12+G12+H12)*((6-J12)/5)/I12,0)) -> 1.35 | L12: =IF(K12="","",IF(K12>=6,"Включить в первую версию",IF(K12>=4,"Включить после проверки",IF(K12>=2.5,"Проверить дополнительно",IF(K12>=1.5,"Отложить","Исключить"))))) -> Исключить | M12: R2
A13: P-010 | B13: Оплата Pro | C13: Монетизация | D13: S-007 | E13: F-013 | F13: 2 | G13: 5 | H13: 2 | I13: 4 | J13: 4 | K13: =IF(A13="","",IFERROR((F13+G13+H13)*((6-J13)/5)/I13,0)) -> 0.9 | L13: =IF(K13="","",IF(K13>=6,"Включить в первую версию",IF(K13>=4,"Включить после проверки",IF(K13>=2.5,"Проверить дополнительно",IF(K13>=1.5,"Отложить","Исключить"))))) -> Исключить | M13: R2
A14: P-011 | B14: Публичные ссылки для преподавателей | C14: Сценарий + функция | D14: S-012 | E14: F-014 | F14: 3 | G14: 3 | H14: 1 | I14: 3 | J14: 3 | K14: =IF(A14="","",IFERROR((F14+G14+H14)*((6-J14)/5)/I14,0)) -> 1.4 | L14: =IF(K14="","",IF(K14>=6,"Включить в первую версию",IF(K14>=4,"Включить после проверки",IF(K14>=2.5,"Проверить дополнительно",IF(K14>=1.5,"Отложить","Исключить"))))) -> Исключить | M14: R3
K15: =IF(A15="","",IFERROR((F15+G15+H15)*((6-J15)/5)/I15,0)) | L15: =IF(K15="","",IF(K15>=6,"Включить в первую версию",IF(K15>=4,"Включить после проверки",IF(K15>=2.5,"Проверить дополнительно",IF(K15>=1.5,"Отложить","Исключить")))))
K16: =IF(A16="","",IFERROR((F16+G16+H16)*((6-J16)/5)/I16,0)) | L16: =IF(K16="","",IF(K16>=6,"Включить в первую версию",IF(K16>=4,"Включить после проверки",IF(K16>=2.5,"Проверить дополнительно",IF(K16>=1.5,"Отложить","Исключить")))))
K17: =IF(A17="","",IFERROR((F17+G17+H17)*((6-J17)/5)/I17,0)) | L17: =IF(K17="","",IF(K17>=6,"Включить в первую версию",IF(K17>=4,"Включить после проверки",IF(K17>=2.5,"Проверить дополнительно",IF(K17>=1.5,"Отложить","Исключить")))))
K18: =IF(A18="","",IFERROR((F18+G18+H18)*((6-J18)/5)/I18,0)) | L18: =IF(K18="","",IF(K18>=6,"Включить в первую версию",IF(K18>=4,"Включить после проверки",IF(K18>=2.5,"Проверить дополнительно",IF(K18>=1.5,"Отложить","Исключить")))))
K19: =IF(A19="","",IFERROR((F19+G19+H19)*((6-J19)/5)/I19,0)) | L19: =IF(K19="","",IF(K19>=6,"Включить в первую версию",IF(K19>=4,"Включить после проверки",IF(K19>=2.5,"Проверить дополнительно",IF(K19>=1.5,"Отложить","Исключить")))))
K20: =IF(A20="","",IFERROR((F20+G20+H20)*((6-J20)/5)/I20,0)) | L20: =IF(K20="","",IF(K20>=6,"Включить в первую версию",IF(K20>=4,"Включить после проверки",IF(K20>=2.5,"Проверить дополнительно",IF(K20>=1.5,"Отложить","Исключить")))))
K21: =IF(A21="","",IFERROR((F21+G21+H21)*((6-J21)/5)/I21,0)) | L21: =IF(K21="","",IF(K21>=6,"Включить в первую версию",IF(K21>=4,"Включить после проверки",IF(K21>=2.5,"Проверить дополнительно",IF(K21>=1.5,"Отложить","Исключить")))))
K22: =IF(A22="","",IFERROR((F22+G22+H22)*((6-J22)/5)/I22,0)) | L22: =IF(K22="","",IF(K22>=6,"Включить в первую версию",IF(K22>=4,"Включить после проверки",IF(K22>=2.5,"Проверить дополнительно",IF(K22>=1.5,"Отложить","Исключить")))))
K23: =IF(A23="","",IFERROR((F23+G23+H23)*((6-J23)/5)/I23,0)) | L23: =IF(K23="","",IF(K23>=6,"Включить в первую версию",IF(K23>=4,"Включить после проверки",IF(K23>=2.5,"Проверить дополнительно",IF(K23>=1.5,"Отложить","Исключить")))))
K24: =IF(A24="","",IFERROR((F24+G24+H24)*((6-J24)/5)/I24,0)) | L24: =IF(K24="","",IF(K24>=6,"Включить в первую версию",IF(K24>=4,"Включить после проверки",IF(K24>=2.5,"Проверить дополнительно",IF(K24>=1.5,"Отложить","Исключить")))))
K25: =IF(A25="","",IFERROR((F25+G25+H25)*((6-J25)/5)/I25,0)) | L25: =IF(K25="","",IF(K25>=6,"Включить в первую версию",IF(K25>=4,"Включить после проверки",IF(K25>=2.5,"Проверить дополнительно",IF(K25>=1.5,"Отложить","Исключить")))))
K26: =IF(A26="","",IFERROR((F26+G26+H26)*((6-J26)/5)/I26,0)) | L26: =IF(K26="","",IF(K26>=6,"Включить в первую версию",IF(K26>=4,"Включить после проверки",IF(K26>=2.5,"Проверить дополнительно",IF(K26>=1.5,"Отложить","Исключить")))))
... K203: =IF(A203="","",IFERROR((F203+G203+H203)*((6-J203)/5)/I203,0)) | L203: =IF(K203="","",IF(K203>=6,"Включить в первую версию",IF(K203>=4,"Включить после проверки",IF(K203>=2.5,"Проверить дополнительно",IF(K203>=1.5,"Отложить","Исключить")))))

Sheet Связность
A1: Проверка связности: анализ → бизнес-логика → сценарии → требования → монетизация
A3: Контрольная точка | B3: Что проверяется | C3: Проверочный вопрос | D3: Источник листа | E3: Критерий прохождения | F3: Количество | G3: Порог | H3: Статус | I3: Комментарий
A4: Единая доказательная база | B4: Наличие выводов анализа | C4: Есть ли перенесенные выводы из предыдущих видов анализа? | D4: Банк анализа | E4: Не менее 5 выводов | F4: =COUNTA('Банк анализа'!A4:A203) -> 10 | G4: 5 | H4: =IF(F4>=G4,"Пройдено","Недостаточно") -> Пройдено
A5: Подтвержденные основания | B5: Качество доказательств | C5: Есть ли сильные основания для решений? | D5: Банк анализа | E5: Не менее 3 выводов с силой доказательства 3-4 | F5: =COUNTIF('Банк анализа'!G4:G203,">=3") -> 8 | G5: 3 | H5: =IF(F5>=G5,"Пройдено","Недостаточно") -> Пройдено
A6: Бизнес-логика | B6: Наличие элементов логики | C6: Сформулировано ли, за счет чего создается и монетизируется ценность? | D6: Бизнес-логика | E6: Не менее 3 элементов | F6: =COUNTA('Бизнес-логика'!A4:A203) -> 7 | G6: 3 | H6: =IF(F6>=G6,"Пройдено","Недостаточно") -> Пройдено
A7: Роли и сегменты | B7: Наличие ролей | C7: Понятно ли, для кого создаются сценарии? | D7: Роли и сегменты | E7: Не менее 2 ролей | F7: =COUNTA('Роли и сегменты'!A4:A203) -> 7 | G7: 2 | H7: =IF(F7>=G7,"Пройдено","Недостаточно") -> Пройдено
A8: Сценарии | B8: Наличие пользовательских сценариев | C8: Описаны ли действия пользователя от проблемы до результата? | D8: Пользовательские сценарии | E8: Не менее 5 сценариев | F8: =COUNTA('Пользовательские сценарии'!A4:A203) -> 13 | G8: 5 | H8: =IF(F8>=G8,"Пройдено","Недостаточно") -> Пройдено
A9: Монетизационные сценарии | B9: Связь сценариев с доходами | C9: Есть ли сценарии, напрямую связанные с оплатой или удержанием? | D9: Пользовательские сценарии | E9: Не менее 1 монетизационного сценария | F9: =COUNTIF('Пользовательские сценарии'!E4:E203,"Монетизационный") -> 1 | G9: 1 | H9: =IF(F9>=G9,"Пройдено","Недостаточно") -> Пройдено
A10: Требования | B10: Перевод сценариев в функции | C10: Есть ли функциональные требования, выведенные из сценариев? | D10: Функциональные требования | E10: Не менее 5 требований | F10: =COUNTA('Функциональные требования'!A4:A203) -> 14 | G10: 5 | H10: =IF(F10>=G10,"Пройдено","Недостаточно") -> Пройдено
A11: MVP | B11: Фокус первой версии | C11: Есть ли требования, рекомендованные в первую версию? | D11: Функциональные требования | E11: Не менее 3 требований MVP | F11: =COUNTIF('Функциональные требования'!O4:O203,"Да") -> 7 | G11: 3 | H11: =IF(F11>=G11,"Пройдено","Недостаточно") -> Пройдено
A12: Приоритизация | B12: Очередность реализации | C12: Определены ли инициативы и решения по ним? | D12: Приоритизация | E12: Не менее 5 инициатив | F12: =COUNTA(Приоритизация!A4:A203) -> 11 | G12: 5 | H12: =IF(F12>=G12,"Пройдено","Недостаточно") -> Пройдено
A13: Общая связность | B13: Прохождение контрольных точек | C13: Прошла ли модель ключевые проверки? | D13: Связность | E13: Не менее 7 пройденных точек | F13: =COUNTIF(H4:H12,"Пройдено") -> 9 | G13: 7 | H13: =IF(F13>=G13,"Пройдено","Недостаточно") -> Пройдено

Sheet Дашборд
A1: Дашборд готовности бизнес-логики и пользовательских сценариев
A3: Ключевые показатели | F3: Распределение сценариев и требований по приоритетам
A4: Показатель | B4: Значение | C4: Единица | D4: Интерпретация | F4: Приоритет | G4: Сценарии | H4: Требования | I4: Инициативы
A5: Выводов анализа | B5: =COUNTA('Банк анализа'!A4:A203) -> 10 | C5: шт. | D5: Объем доказательной базы | F5: Критический | G5: =COUNTIF('Пользовательские сценарии'!S4:S203,F5) -> 0 | H5: =COUNTIF('Функциональные требования'!N4:N203,F5) -> 5 | I5: =COUNTIF(Приоритизация!L4:L203,"*"&F5&"*") -> 0
A6: Сильных выводов | B6: =COUNTIF('Банк анализа'!G4:G203,">=3") -> 8 | C6: шт. | D6: Сила доказательной базы | F6: Высокий | G6: =COUNTIF('Пользовательские сценарии'!S4:S203,F6) -> 3 | H6: =COUNTIF('Функциональные требования'!N4:N203,F6) -> 2 | I6: =COUNTIF(Приоритизация!L4:L203,"*"&F6&"*") -> 0
A7: Элементов бизнес-логики | B7: =COUNTA('Бизнес-логика'!A4:A203) -> 7 | C7: шт. | D7: Сформированность логики | F7: Средний | G7: =COUNTIF('Пользовательские сценарии'!S4:S203,F7) -> 3 | H7: =COUNTIF('Функциональные требования'!N4:N203,F7) -> 3 | I7: =COUNTIF(Приоритизация!L4:L203,"*"&F7&"*") -> 0
A8: Средний индекс надежности логики | B8: =IFERROR(AVERAGEIF('Бизнес-логика'!M4:M203,">0",'Бизнес-логика'!M4:M203),0) -> 0.55714286 | C8: 0-1 | D8: Качество связности элементов | F8: Низкий | G8: =COUNTIF('Пользовательские сценарии'!S4:S203,F8) -> 4 | H8: =COUNTIF('Функциональные требования'!N4:N203,F8) -> 3 | I8: =COUNTIF(Приоритизация!L4:L203,"*"&F8&"*") -> 0
A9: Ролей и сегментов | B9: =COUNTA('Роли и сегменты'!A4:A203) -> 7 | C9: шт. | D9: Покрытие пользователей | F9: Отложить | G9: =COUNTIF('Пользовательские сценарии'!S4:S203,F9) -> 3 | H9: =COUNTIF('Функциональные требования'!N4:N203,F9) -> 1 | I9: =COUNTIF(Приоритизация!L4:L203,"*"&F9&"*") -> 2
A10: Пользовательских сценариев | B10: =COUNTA('Пользовательские сценарии'!A4:A203) -> 13 | C10: шт. | D10: Полнота сценарной модели
A11: Критических и высоких сценариев | B11: =COUNTIF('Пользовательские сценарии'!S4:S203,"Критический")+COUNTIF('Пользовательские сценарии'!S4:S203,"Высокий") -> 3 | C11: шт. | D11: Фокус для проектирования
A12: Функциональных требований | B12: =COUNTA('Функциональные требования'!A4:A203) -> 14 | C12: шт. | D12: Перевод сценариев в продукт | F12: Контрольные точки связности
A13: Требований MVP | B13: =COUNTIF('Функциональные требования'!O4:O203,"Да") -> 7 | C13: шт. | D13: Состав первой версии | F13: Контрольная точка | G13: Количество | H13: Порог | I13: Статус
A14: Пройденных контрольных точек | B14: =COUNTIF(Связность!H4:H13,"Пройдено") -> 10 | C14: из 10 | D14: Общая проверка | F14: =Связность!A4 -> Единая доказательная база | G14: =Связность!F4 -> 10 | H14: =Связность!G4 -> 5 | I14: =Связность!H4 -> Пройдено
A15: Индекс готовности | B15: =IFERROR(COUNTIF(Связность!H4:H13,"Пройдено")/10,0) -> 1 | C15: % | D15: Итоговая готовность | F15: =Связность!A5 -> Подтвержденные основания | G15: =Связность!F5 -> 8 | H15: =Связность!G5 -> 3 | I15: =Связность!H5 -> Пройдено
F16: =Связность!A6 -> Бизнес-логика | G16: =Связность!F6 -> 7 | H16: =Связность!G6 -> 3 | I16: =Связность!H6 -> Пройдено
F17: =Связность!A7 -> Роли и сегменты | G17: =Связность!F7 -> 7 | H17: =Связность!G7 -> 2 | I17: =Связность!H7 -> Пройдено
A18: Итоговая интерпретация | F18: =Связность!A8 -> Сценарии | G18: =Связность!F8 -> 13 | H18: =Связность!G8 -> 5 | I18: =Связность!H8 -> Пройдено
A19: Индекс готовности менее 50% | B19: Модель неполная: сначала усилить доказательную базу, роли и сценарии. | F19: =Связность!A9 -> Монетизационные сценарии | G19: =Связность!F9 -> 1 | H19: =Связность!G9 -> 1 | I19: =Связность!H9 -> Пройдено
A20: Индекс готовности 50–79% | B20: Модель рабочая, но требует проверки слабых связей и уточнения монетизационных сценариев. | F20: =Связность!A10 -> Требования | G20: =Связность!F10 -> 14 | H20: =Связность!G10 -> 5 | I20: =Связность!H10 -> Пройдено
A21: Индекс готовности 80–100% | B21: Модель готова к переводу в техническое задание, прототипирование и план первой версии. | F21: =Связность!A11 -> MVP | G21: =Связность!F11 -> 7 | H21: =Связность!G11 -> 3 | I21: =Связность!H11 -> Пройдено
A22: Главный риск | B22: Сценарии без связи с проблемой, товаром или единицей монетизации не должны попадать в первую версию. | F22: =Связность!A12 -> Приоритизация | G22: =Связность!F12 -> 11 | H22: =Связность!G12 -> 5 | I22: =Связность!H12 -> Пройдено
A23: Главное правило | B23: Функция включается в продукт только если она поддерживает ценность, сценарий или монетизацию. | F23: =Связность!A13 -> Общая связность | G23: =Связность!F13 -> 9 | H23: =Связность!G13 -> 7 | I23: =Связность!H13 -> Пройдено

Sheet Справочники
A1: Справочники для выпадающих списков и шкал оценки
A3: Источник анализа | D3: Блок Канвас | G3: Уровень доказательности | J3: Роль пользователя
A4: Анализ проблем клиентов | D4: Потребительские сегменты | G4: 1 — слабый сигнал | J4: Посетитель
A5: Анализ отзывов | D5: Ценностные предложения | G5: 2 — частично подтверждено | J5: Потенциальный клиент
A6: Анализ конкурентов по сайтам | D6: Каналы | G6: 3 — подтверждено несколькими источниками | J6: Новый пользователь
A7: Анализ бизнес-моделей конкурентов | D7: Отношения с клиентами | G7: 4 — проверенное основание | J7: Активный пользователь
A8: Классификация компаний по уровням конкуренции | D8: Потоки доходов | J8: Платящий клиент
A9: Анализ цифрового товара и рыночного стандарта | D9: Ключевые ресурсы | J9: Администратор клиента
A10: Ценностное предложение и цифровой товар | D10: Ключевые виды деятельности | J10: Менеджер/оператор
A11: Канвас бизнес-модели | D11: Ключевые партнеры | J11: Партнер
A12: Экономика монетизации | D12: Структура затрат | J12: Внутренний администратор
A13: Проверка пользовательских сценариев
A17: Этап сценария | D17: Тип сценария | G17: Приоритет | J17: Статус
A18: Привлечение | D18: Основной | G18: Критический | J18: Черновик
A19: Первичный интерес | D19: Вспомогательный | G19: Высокий | J19: Требует проверки
A20: Регистрация | D20: Монетизационный | G20: Средний | J20: Подтверждено
A21: Первичная настройка | D21: Сервисный | G21: Низкий | J21: В разработку
A22: Получение ценности | D22: Административный | G22: Отложить | J22: Исключено
A23: Оплата | D23: Удерживающий
A24: Повторное использование | D24: Партнерский
A25: Поддержка
A26: Удержание
A27: Расширение потребления
A28: Отказ/возврат
A31: Тип бизнес-логики | D31: Категория Кано | G31: Уровень товара по Левитту | J31: Тип цифрового товара
A32: Клиентская | D32: Базовое требование | G32: Ядро выгоды | J32: Подписка
A33: Продуктовая | D33: Линейное требование | G33: Базовый товар | J33: Доступ к сервису
A34: Монетизационная | D34: Восхищающее требование | G34: Ожидаемый товар | J34: Цифровой контент
A35: Канальная | D35: Нейтральный признак | G35: Расширенный товар | J35: Транзакционная услуга
