Workbook

Sheet Ввод_NotaCode
A1: № | B1: Что снять / проверить | C1: Где и как | D1: Куда вписать | E1: Значение (заполнить) | F1: Статус
A2: 1 | B2: Даты повторного просмотра сайтов и скриншоты (C05, C08, C09) | C2: Сайт → тарифы, продукт, регистрация | D2: 02_Конкуренты: I; 03_Факты_сайта: J, K | F2: 🔲 не сделано
A3: 2 | B3: Цены и лимиты Gleek, Lucidchart; условия Ramus Educational | C3: Страницы тарифов/лицензии | D3: 06_Монетизация; 03_Факты_сайта (новые строки) | F3: 🔲 не сделано
A4: 3 | B4: Платность плагинов draw.io в Atlassian Marketplace | C4: marketplace.atlassian.com → draw.io | D4: 03_Факты_сайта; 06_Монетизация: N | F4: 🔲 не сделано
A5: 4 | B5: Вакансии конкурентов (ключевые процессы) | C5: Раздел Careers/Jobs | D5: 03_Факты_сайта (элемент «ключевые виды деятельности») | F5: 🔲 не сделано
A6: 5 | B6: После дозаполнения сменить статус на «завершен» | C6: — | D6: 02_Конкуренты: H | F6: 🔲 не сделано

Sheet 00_Паспорт_NotaCode
A1: Паспорт исследования бизнес-моделей конкурентов (NotaCode)
A2: Поле | B2: Содержание
A3: Цель исследования | B3: Выбрать элементы бизнес-модели NotaCode (freemium Free/Pro 4 USD) для запуска MVP к 06.12.2026: стандарт рынка, модель доходов, путь первой покупки
A4: Рынок | B4: Инструменты построения диаграмм (diagram as code и графические редакторы), Беларусь/СНГ, B2C (студенты) + B2B-лайт (аналитики, архитекторы)
A5: Единица анализа | B5: Конкретное предложение: веб-/настольный доступ к редактору диаграмм и его платные расширения
A6: Период сбора данных | B6: 2026-09-17 — 2026-09-25 (архив) + 🔲 ДОСНЯТЬ: повторный просмотр сайтов (даты фиксировать)
A7: Список конкурентов | B7: 8: PlantUML, Eraser, Mermaid, D2, Gleek, draw.io, Ramus, Lucidchart (прямые и косвенные из части A)
A8: Источники | B8: Главная, продукт, тарифы, регистрация/демо, документация, интеграции, FAQ/лицензия, команда/спонсоры; вакансии — 🔲

Sheet 13_Справочники
A1: Справочники для раскрывающихся списков
A2: Используйте эти значения в рабочих листах, чтобы результаты можно было сопоставлять между конкурентами.
A3: Тип конкурента | B3: Приоритет | C3: Статус анализа | D3: Элемент бизнес-модели | E3: Уровень доказательности | F3: Модель монетизации | G3: Тип воронки | H3: Классификация практики | I3: Тип преимущества
A4: прямой | B4: высокий | C4: не начат | D4: целевые сегменты | E4: 1 | F4: подписка | G4: самостоятельная покупка | H4: рыночный стандарт | I4: товарное
A5: косвенный | B5: средний | C5: в работе | D5: ценностное предложение | E5: 2 | F5: разовая покупка | G5: заявка на консультацию | H5: формирующийся стандарт | I5: ценовое
A6: заменитель | B6: низкий | C6: требует проверки | D6: цифровой товар | E6: 3 | F6: комиссия | G6: демонстрация продукта | H6: зона дифференциации | I6: канальное
A7: эталон лучшей практики | C7: завершен | D7: каналы | E7: 4 | F7: транзакционная оплата | G7: регистрация | H7: нишевой признак | I7: технологическое
A8: смежная модель | D8: отношения с клиентами | E8: 5 | F8: условно-бесплатная модель | G8: пробный доступ | H8: слабый сигнал | I8: данные
D9: потоки доходов | F9: лицензия | G9: контентная воронка | I9: партнерское
D10: ключевые ресурсы | F10: реклама | G10: корпоративные продажи | I10: брендовое
D11: ключевые виды деятельности | F11: оплата за использование | G11: маркетплейс | I11: сервисное
D12: ключевые партнеры | F12: пакетная продажа | I12: операционное
D13: структура затрат | F13: смешанная
D14: данные и сетевые эффекты
D15: масштабирование

Sheet 01_Инструкция
A1: Методика анализа бизнес-модели конкурентов по их сайтам
A2: Рабочая книга предназначена для восстановления бизнес-модели конкурента по публичным данным сайта: продукт, ценность, монетизация, каналы, ресурсы, партнерства, данные, масштабируемость и конкурентные преимущества.
A4: Этап | B4: Что сделать | C4: Где заполнять | D4: Результат | F4: Шкала | G4: Интерпретация
A5: 1. Сформировать контур анализа | B5: Внести список конкурентов, тип конкурента, географию, сегмент, приоритет и статус анализа. | C5: 02_Конкуренты | D5: Единый перечень объектов наблюдения. | F5: 1 | G5: Слабый косвенный признак: предположение без прямого подтверждения на сайте.
A6: 2. Собрать факты с сайтов | B6: Фиксировать URL, раздел сайта, наблюдаемый факт, элемент бизнес-модели, уровень доказательности и вывод. | C6: 03_Факты_сайта | D6: Проверяемая база фактов, на которой строятся гипотезы. | F6: 2 | G6: Косвенное подтверждение: факт есть, но связь с блоком бизнес-модели неочевидна.
A7: 3. Восстановить бизнес-модель | B7: По каждому конкуренту заполнить блоки бизнес-модели: сегменты, ценность, цифровой товар, каналы, отношения, доходы, ресурсы, деятельность, партнеры, издержки, данные. | C7: 04_Бизнес_модель | D7: Профиль бизнес-модели конкурента с оценкой полноты и доказательности. | F7: 3 | G7: Достаточное подтверждение: факт прямо указывает на элемент бизнес-модели.
A8: 4. Уточнить товар и ценность | B8: Разложить предложение на ядро цифрового товара, ожидаемый уровень, расширенный уровень, потенциальное развитие и клиентский результат. | C8: 05_Товар_ценность | D8: Понимание того, что фактически продается и за счет чего создается ценность. | F8: 4 | G8: Сильное подтверждение: несколько страниц или блоков сайта подтверждают один вывод.
A9: 5. Оценить монетизацию | B9: Зафиксировать признаки ценовой модели, тарифы, пробный доступ, ограничения, платежные условия и логику получения выручки. | C9: 06_Монетизация | D9: Вывод о потоках доходов и зрелости коммерческой модели. | F9: 5 | G9: Высокая доказательность: прямое описание, тариф, оферта, демонстрация, кейс или документация подтверждают вывод.
A10: 6. Описать каналы и воронку | B10: Выявить источники привлечения, точки конверсии, призывы к действию, контент, регистрацию, демонстрацию, заявки и продажи. | C10: 07_Каналы | D10: Понимание способа выхода на рынок и механики превращения посетителя в клиента.
A11: 7. Описать операционную основу | B11: Оценить ресурсы, процессы, данные, интеграции, партнеров, поддержку, признаки масштабируемости и операционных ограничений. | C11: 08_Операц_модель | D11: Оценка устойчивости и воспроизводимости бизнес-модели.
A12: 8. Сравнить конкурентов | B12: Поставить оценки по ключевым блокам, использовать веса и получить итоговый индекс силы бизнес-модели. | C12: 09_Матрица | D12: Рейтинг бизнес-моделей конкурентов.
A13: 9. Определить рыночный стандарт | B13: Сгруппировать повторяющиеся практики и рассчитать долю конкурентов, у которых они присутствуют. | C13: 10_Стандарт | D13: Отделение обязательного рыночного минимума от зон дифференциации.
A14: 10. Сформулировать преимущества | B14: Выделить преимущества конкурентов и оценить силу, трудность копирования, коммерческую значимость и доказательность. | C14: 11_Преимущества | D14: Список проверяемых преимуществ и угроз.
A15: 11. Подготовить итог | B15: Использовать сводный лист для контроля заполнения, рейтинга и общей интерпретации. | C15: 12_Сводка | D15: Сводная картина рынка и рекомендации к дальнейшему анализу.

Sheet 02_Конкуренты
A1: Реестр конкурентов
A2: Заполняется первым. Один конкурент — одна строка. ID используется во всех остальных листах.
A3: ID | B3: Название конкурента | C3: Сайт | D3: Сегмент | E3: Тип конкурента | F3: География | G3: Приоритет | H3: Статус анализа | I3: Дата фиксации | J3: Ответственный | K3: Примечание
A4: C01 | B4: PlantUML | C4: https://plantuml.com | D4: Разработчики, студенты | E4: прямой | F4: Международный (RU-трафик 9,07 %) | G4: высокий | H4: завершен | I4: 2026-09-17 | J4: Хаджинова К. | K4: Open source (GPL-3.0)
A5: C02 | B5: Eraser (DiagramGPT) | C5: https://www.eraser.io | D5: Команды разработки | E5: прямой | F5: Международный (Индия 40,81 %) | G5: высокий | H5: завершен | I5: 2026-09-23 | J5: Хаджинова К. | K5: Freemium + подписка по местам
A6: C03 | B6: Mermaid (open source) | C6: https://mermaid.js.org | D6: Разработчики, техписатели | E6: косвенный | F6: Международный | G6: высокий | H6: завершен | I6: 2026-09-17 | J6: Хаджинова К. | K6: MIT, GitHub Sponsors
A7: C04 | B7: D2 | C7: https://d2lang.com | D7: Разработчики | E7: косвенный | F7: Международный | G7: средний | H7: завершен | I7: 2026-09-23 | J7: Хаджинова К. | K7: MPL-2.0, Hack Club
A8: C05 | B8: Gleek | C8: https://www.gleek.io | D8: Разработчики, аналитики | E8: косвенный | F8: Международный | G8: средний | H8: требует проверки | I8: 🔲 дата просмотра | J8: Хаджинова К. | K8: Freemium — 🔲 проверить
A9: C07 | B9: draw.io / diagrams.net | C9: https://www.drawio.com | D9: Все сегменты | E9: заменитель | F9: Международный | G9: высокий | H9: завершен | I9: 2026-09-23 | J9: Хаджинова К. | K9: Apache 2.0, «Not VC-funded»
A10: C08 | B10: Ramus (Educational) | C10: 🔲 URL Ramus | D10: Студенты СНГ | E10: косвенный | F10: СНГ | G10: средний | H10: требует проверки | I10: 2026-09-17 | J10: Хаджинова К. | K10: Настольная лицензия
A11: C09 | B11: Lucidchart | C11: https://www.lucidchart.com | D11: Аналитики, корпоративные команды | E11: заменитель | F11: Международный | G11: средний | H11: требует проверки | I11: 2026-09-17 | J11: Хаджинова К. | K11: SaaS-подписка

Sheet 03_Факты_сайта
A1: Факты, извлеченные с сайтов конкурентов
A2: Каждый вывод по бизнес-модели должен иметь источник: URL, наблюдаемый факт и уровень доказательности.
A3: Факт_ID | B3: ID конкурента | C3: Название | D3: Раздел сайта | E3: URL | F3: Блок/страница | G3: Наблюдаемый факт | H3: Элемент бизнес-модели | I3: Доказательность 1-5 | J3: Дата фиксации | K3: Цитата/скриншот | L3: Аналитический вывод
A4: F001 | B4: C01 | C4: =IF($B4="","",IFERROR(VLOOKUP($B4,'02_Конкуренты'!$A$4:$B$203,2,FALSE),"не найдено")) -> PlantUML | D4: Главная | E4: https://plantuml.com | F4: Первый экран | G4: «No server. No tokens. No tracking» | H4: ценностное предложение | I4: 5 | J4: 2026-09-17 | K4: цитата; Рисунки/scr_05 | L4: Ценность — приватность и локальная работа
A5: F002 | B5: C01 | C5: =IF($B5="","",IFERROR(VLOOKUP($B5,'02_Конкуренты'!$A$4:$B$203,2,FALSE),"не найдено")) -> PlantUML | D5: Лицензия | E5: https://plantuml.com | F5: Загрузка | G5: GPL-3.0, open source | H5: потоки доходов | I5: 4 | J5: 2026-09-17 | K5: kursach.md | L5: Прямой выручки от товара нет
A6: F003 | B6: C01 | C6: =IF($B6="","",IFERROR(VLOOKUP($B6,'02_Конкуренты'!$A$4:$B$203,2,FALSE),"не найдено")) -> PlantUML | D6: Интеграции | E6: https://plantuml.com | F6: IDE/CI | G6: Плагины IntelliJ, VS Code; расширение для GitHub | H6: каналы | I6: 4 | J6: 2026-09-17 | K6: архив ЛР5 | L6: Канал — экосистема IDE
A7: F004 | B7: C01 | C7: =IF($B7="","",IFERROR(VLOOKUP($B7,'02_Конкуренты'!$A$4:$B$203,2,FALSE),"не найдено")) -> PlantUML | D7: SimilarWeb | E7: https://www.similarweb.com/website/plantuml.com/ | F7: Трафик | G7: ≈507 тыс. визитов; РФ 9,07 % | H7: целевые сегменты | I7: 4 | J7: 2026-09-17 | K7: Рисунки/scr_06 | L7: Русскоязычная аудитория
A8: F005 | B8: C01 | C8: =IF($B8="","",IFERROR(VLOOKUP($B8,'02_Конкуренты'!$A$4:$B$203,2,FALSE),"не найдено")) -> PlantUML | D8: Тарифы | E8: https://plantuml.com | F8: — | G8: Страницы тарифов нет (отрицательный признак) | H8: потоки доходов | I8: 3 | J8: 2026-09-17 | K8: — | L8: Модель не коммерческая
A9: F006 | B9: C02 | C9: =IF($B9="","",IFERROR(VLOOKUP($B9,'02_Конкуренты'!$A$4:$B$203,2,FALSE),"не найдено")) -> Eraser (DiagramGPT) | D9: Тарифы | E9: 🔲 URL тарифов Eraser | F9: Тарифная сетка | G9: Free/Starter 15–20/Business 45–60 USD/Enterprise по запросу; лимиты AI 3/40/250/∞ | H9: потоки доходов | I9: 5 | J9: 2026-09-17 | K9: Рисунки/scr_10 | L9: Подписка по местам с лимитом AI
A10: F007 | B10: C02 | C10: =IF($B10="","",IFERROR(VLOOKUP($B10,'02_Конкуренты'!$A$4:$B$203,2,FALSE),"не найдено")) -> Eraser (DiagramGPT) | D10: Тарифы | E10: 🔲 URL тарифов Eraser | F10: Enterprise | G10: SSO, usage reporting на старших тарифах | H10: отношения с клиентами | I10: 4 | J10: 2026-09-17 | K10: архив ЛР5 | L10: Переход к корпоративным продажам
A11: F008 | B11: C02 | C11: =IF($B11="","",IFERROR(VLOOKUP($B11,'02_Конкуренты'!$A$4:$B$203,2,FALSE),"не найдено")) -> Eraser (DiagramGPT) | D11: Продукт | E11: https://www.eraser.io/product/ai-diagrams | F11: AI | G11: AI-генерация, MCP-сервер для агентов, git-синхронизация | H11: цифровой товар | I11: 5 | J11: 2026-09-17 | K11: 00-competitive-analysis.md | L11: Ядро — AI + DSL
A12: F009 | B12: C02 | C12: =IF($B12="","",IFERROR(VLOOKUP($B12,'02_Конкуренты'!$A$4:$B$203,2,FALSE),"не найдено")) -> Eraser (DiagramGPT) | D12: Интеграции | E12: https://www.eraser.io | F12: Интеграции | G12: GitHub, Notion, Confluence, VS Code | H12: ключевые партнеры | I12: 4 | J12: 2026-09-17 | K12: архив ЛР5 | L12: Платформенные партнёрства
A13: F010 | B13: C02 | C13: =IF($B13="","",IFERROR(VLOOKUP($B13,'02_Конкуренты'!$A$4:$B$203,2,FALSE),"не найдено")) -> Eraser (DiagramGPT) | D13: SimilarWeb | E13: https://www.similarweb.com/website/eraser.io/ | F13: Трафик | G13: 678,5 тыс. визитов; прямые заходы 49,05 % | H13: каналы | I13: 4 | J13: 2026-09-23 | K13: Рисунки/scr_12 | L13: PLG + бренд
A14: F011 | B14: C03 | C14: =IF($B14="","",IFERROR(VLOOKUP($B14,'02_Конкуренты'!$A$4:$B$203,2,FALSE),"не найдено")) -> Mermaid (open source) | D14: Главная | E14: https://mermaid.js.org | F14: Интеграции | G14: Нативный рендер в GitHub/GitLab/Notion | H14: данные и сетевые эффекты | I14: 5 | J14: 2026-09-17 | K14: Рисунки/scr_07 | L14: Стандарт де-факто — сетевой эффект платформ
A15: F012 | B15: C03 | C15: =IF($B15="","",IFERROR(VLOOKUP($B15,'02_Конкуренты'!$A$4:$B$203,2,FALSE),"не найдено")) -> Mermaid (open source) | D15: Команда | E15: 🔲 URL Meet the Team | F15: Спонсоры | G15: Кнопки GitHub Sponsors | H15: потоки доходов | I15: 4 | J15: 2026-09-17 | K15: архив ЛР5 | L15: Донаты
... A32: F029 | B32: C09 | C32: =IF($B32="","",IFERROR(VLOOKUP($B32,'02_Конкуренты'!$A$4:$B$203,2,FALSE),"не найдено")) -> Lucidchart | D32: Тарифы | E32: 🔲 URL тарифов Lucidchart | F32: Тарифы | G32: SaaS-подписка (цены 🔲) | H32: потоки доходов | I32: 2 | J32: 2026-09-17 | K32: архив ЛР5 | L32: 🔲 проверить
C33: =IF($B33="","",IFERROR(VLOOKUP($B33,'02_Конкуренты'!$A$4:$B$203,2,FALSE),"не найдено"))
C34: =IF($B34="","",IFERROR(VLOOKUP($B34,'02_Конкуренты'!$A$4:$B$203,2,FALSE),"не найдено"))
C35: =IF($B35="","",IFERROR(VLOOKUP($B35,'02_Конкуренты'!$A$4:$B$203,2,FALSE),"не найдено"))
C36: =IF($B36="","",IFERROR(VLOOKUP($B36,'02_Конкуренты'!$A$4:$B$203,2,FALSE),"не найдено"))
C37: =IF($B37="","",IFERROR(VLOOKUP($B37,'02_Конкуренты'!$A$4:$B$203,2,FALSE),"не найдено"))
C38: =IF($B38="","",IFERROR(VLOOKUP($B38,'02_Конкуренты'!$A$4:$B$203,2,FALSE),"не найдено"))
C39: =IF($B39="","",IFERROR(VLOOKUP($B39,'02_Конкуренты'!$A$4:$B$203,2,FALSE),"не найдено"))
C40: =IF($B40="","",IFERROR(VLOOKUP($B40,'02_Конкуренты'!$A$4:$B$203,2,FALSE),"не найдено"))
C41: =IF($B41="","",IFERROR(VLOOKUP($B41,'02_Конкуренты'!$A$4:$B$203,2,FALSE),"не найдено"))
C42: =IF($B42="","",IFERROR(VLOOKUP($B42,'02_Конкуренты'!$A$4:$B$203,2,FALSE),"не найдено"))
C43: =IF($B43="","",IFERROR(VLOOKUP($B43,'02_Конкуренты'!$A$4:$B$203,2,FALSE),"не найдено"))
C44: =IF($B44="","",IFERROR(VLOOKUP($B44,'02_Конкуренты'!$A$4:$B$203,2,FALSE),"не найдено"))
... C503: =IF($B503="","",IFERROR(VLOOKUP($B503,'02_Конкуренты'!$A$4:$B$203,2,FALSE),"не найдено"))

Sheet 04_Бизнес_модель
A1: Профиль бизнес-модели конкурента
A2: Заполняется на основе фактов с сайта. Полнота и доказательность рассчитываются автоматически.
A3: ID конкурента | B3: Название | C3: Целевые сегменты | D3: Ценностное предложение | E3: Цифровой товар | F3: Каналы | G3: Отношения с клиентами | H3: Потоки доходов | I3: Ключевые ресурсы | J3: Ключевые виды деятельности | K3: Ключевые партнеры | L3: Структура затрат | M3: Данные и сетевые эффекты | N3: Главная гипотеза бизнес-модели | O3: Полнота профиля | P3: Средняя доказательность | Q3: Качество профиля
A4: C01 | B4: =IF($A4="","",IFERROR(VLOOKUP($A4,'02_Конкуренты'!$A$4:$B$203,2,FALSE),"не найдено")) -> PlantUML | C4: Разработчики, студенты, техписатели; РФ — 1-я страна трафика | D4: Бесплатные UML-диаграммы из текста, локально и без слежки | E4: DSL + рендер (онлайн-сервер, jar, плагины IDE) | F4: Поиск, IDE-плагины, GitHub-расширение | G4: Самообслуживание, сообщество | H4: Нет прямой выручки (open source) | I4: Язык PlantUML, документация, сообщество | J4: Развитие языка и рендера силами автора и сообщества | K4: IDE и CI-инструменты (встраивание) | L4: Низкие: хостинг сервера, поддержка кода | M4: Сетевой эффект — встроенность в инструменты | N4: Некоммерческий стандарт де-факто для UML-as-code | O4: =IF($A4="","",COUNTA($C4:$N4)/12) -> 1 | P4: =IF($A4="","",IFERROR(AVERAGEIF('03_Факты_сайта'!$B$4:$B$503,$A4,'03_Факты_сайта'!$I$4:$I$503),0)) -> 4 | Q4: =IF($A4="","",IF($O4<0.5,"недостаточно данных",IF($P4<3,"низкая доказательность",IF($O4>=0.85,"готов к сравнению","требует дополнения")))) -> готов к сравнению
A5: C02 | B5: =IF($A5="","",IFERROR(VLOOKUP($A5,'02_Конкуренты'!$A$4:$B$203,2,FALSE),"не найдено")) -> Eraser (DiagramGPT) | C5: Команды разработки от индивидуальных до Enterprise | D5: AI + diagram as code в одном рабочем пространстве | E5: SaaS: DSL, AI, канвас, заметки | F5: PLG через Free (3 AI-диаграммы), прямые заходы 49 % | G5: Самообслуживание → корпоративные продажи (SSO) | H5: Подписка по местам 15–60 USD; Enterprise по запросу | I5: Собственная AI-генерация, интеграции | J5: Разработка AI, продажи Enterprise | K5: GitHub, Notion, Confluence, VS Code | L5: Разработка AI, инференс, продажи | M5: История пользователя, git-синхронизация | N5: Freemium с апгрейдом по лимиту AI-кредитов | O5: =IF($A5="","",COUNTA($C5:$N5)/12) -> 1 | P5: =IF($A5="","",IFERROR(AVERAGEIF('03_Факты_сайта'!$B$4:$B$503,$A5,'03_Факты_сайта'!$I$4:$I$503),0)) -> 4.4 | Q5: =IF($A5="","",IF($O5<0.5,"недостаточно данных",IF($P5<3,"низкая доказательность",IF($O5>=0.85,"готов к сравнению","требует дополнения")))) -> готов к сравнению
A6: C03 | B6: =IF($A6="","",IFERROR(VLOOKUP($A6,'02_Конкуренты'!$A$4:$B$203,2,FALSE),"не найдено")) -> Mermaid (open source) | C6: Разработчики и техписатели в GitHub/GitLab/Notion | D6: Диаграммы в Markdown без плагинов | E6: JS-библиотека + Live Editor | F6: Нативно в платформах документации | G6: Сообщество | H6: Донаты (GitHub Sponsors) + отдельный SaaS Mermaid Chart | I6: Открытый код MIT, сообщество | J6: Развитие библиотеки | K6: GitHub, GitLab, Notion | L6: Низкие | M6: Сетевой эффект платформ-хостов | N6: Стандарт де-факто, монетизируемый через SaaS-надстройку | O6: =IF($A6="","",COUNTA($C6:$N6)/12) -> 1 | P6: =IF($A6="","",IFERROR(AVERAGEIF('03_Факты_сайта'!$B$4:$B$503,$A6,'03_Факты_сайта'!$I$4:$I$503),0)) -> 3.75 | Q6: =IF($A6="","",IF($O6<0.5,"недостаточно данных",IF($P6<3,"низкая доказательность",IF($O6>=0.85,"готов к сравнению","требует дополнения")))) -> готов к сравнению
A7: C04 | B7: =IF($A7="","",IFERROR(VLOOKUP($A7,'02_Конкуренты'!$A$4:$B$203,2,FALSE),"не найдено")) -> D2 | C7: Разработчики | D7: Быстрый современный язык диаграмм | E7: DSL + CLI + playground | F7: Open-source дистрибуция, Discord | G7: Сообщество | H7: Нет (fiscal sponsor Hack Club) | I7: Язык D2, 3 движка раскладки | J7: Развитие языка | K7: Плагины VS Code/Vim | L7: Низкие, не венчурные | N7: Некоммерческий проект с технологическим отличием в раскладке | O7: =IF($A7="","",COUNTA($C7:$N7)/12) -> 0.91666667 | P7: =IF($A7="","",IFERROR(AVERAGEIF('03_Факты_сайта'!$B$4:$B$503,$A7,'03_Факты_сайта'!$I$4:$I$503),0)) -> 4.25 | Q7: =IF($A7="","",IF($O7<0.5,"недостаточно данных",IF($P7<3,"низкая доказательность",IF($O7>=0.85,"готов к сравнению","требует дополнения")))) -> готов к сравнению
A8: C05 | B8: =IF($A8="","",IFERROR(VLOOKUP($A8,'02_Конкуренты'!$A$4:$B$203,2,FALSE),"не найдено")) -> Gleek | C8: Разработчики, аналитики (🔲) | D8: Диаграммы из текста в вебе (🔲) | E8: SaaS с DSL | H8: Freemium (🔲 цены) | N8: Freemium SaaS — модель, близкая к NotaCode (🔲) | O8: =IF($A8="","",COUNTA($C8:$N8)/12) -> 0.41666667 | P8: =IF($A8="","",IFERROR(AVERAGEIF('03_Факты_сайта'!$B$4:$B$503,$A8,'03_Факты_сайта'!$I$4:$I$503),0)) -> 2.5 | Q8: =IF($A8="","",IF($O8<0.5,"недостаточно данных",IF($P8<3,"низкая доказательность",IF($O8>=0.85,"готов к сравнению","требует дополнения")))) -> недостаточно данных
A9: C07 | B9: =IF($A9="","",IFERROR(VLOOKUP($A9,'02_Конкуренты'!$A$4:$B$203,2,FALSE),"не найдено")) -> draw.io / diagrams.net | C9: Все: от индивидуальных пользователей до команд | D9: Профессионально, бесплатно, приватно | E9: Web/desktop-редактор, библиотеки фигур | F9: Прямые заходы 68,65 %, интеграции как канал | G9: Самообслуживание | H9: Нет платного тарифа редактора; плагины Atlassian Marketplace (🔲 платность) | I9: 20-летняя история, совместимость файлов | J9: Развитие редактора и интеграций | K9: Google, Microsoft, Atlassian, GitHub | L9: Разработка; инфраструктура — хранилище у пользователя | M9: Хранение у пользователя, «100M+ users» (заявление) | N9: Бесплатный стандарт GUI-редактора, монетизация через интеграции (🔲) | O9: =IF($A9="","",COUNTA($C9:$N9)/12) -> 1 | P9: =IF($A9="","",IFERROR(AVERAGEIF('03_Факты_сайта'!$B$4:$B$503,$A9,'03_Факты_сайта'!$I$4:$I$503),0)) -> 4.4 | Q9: =IF($A9="","",IF($O9<0.5,"недостаточно данных",IF($P9<3,"низкая доказательность",IF($O9>=0.85,"готов к сравнению","требует дополнения")))) -> готов к сравнению
A10: C08 | B10: =IF($A10="","",IFERROR(VLOOKUP($A10,'02_Конкуренты'!$A$4:$B$203,2,FALSE),"не найдено")) -> Ramus (Educational) | C10: Студенты методологических курсов СНГ | D10: IDEF0/DFD-моделирование | E10: Настольное CASE-приложение | H10: Лицензия (Educational — 🔲) | N10: Нишевая лицензионная модель для вузов (🔲) | O10: =IF($A10="","",COUNTA($C10:$N10)/12) -> 0.41666667 | P10: =IF($A10="","",IFERROR(AVERAGEIF('03_Факты_сайта'!$B$4:$B$503,$A10,'03_Факты_сайта'!$I$4:$I$503),0)) -> 3 | Q10: =IF($A10="","",IF($O10<0.5,"недостаточно данных",IF($P10<3,"низкая доказательность",IF($O10>=0.85,"готов к сравнению","требует дополнения")))) -> недостаточно данных
A11: C09 | B11: =IF($A11="","",IFERROR(VLOOKUP($A11,'02_Конкуренты'!$A$4:$B$203,2,FALSE),"не найдено")) -> Lucidchart | C11: Аналитики, корпоративные команды | D11: Совместная визуальная работа | E11: SaaS-редактор + AI | F11: 🔲 | H11: Подписка (🔲 цены) | N11: SaaS-подписка для команд (🔲) | O11: =IF($A11="","",COUNTA($C11:$N11)/12) -> 0.5 | P11: =IF($A11="","",IFERROR(AVERAGEIF('03_Факты_сайта'!$B$4:$B$503,$A11,'03_Факты_сайта'!$I$4:$I$503),0)) -> 2.5 | Q11: =IF($A11="","",IF($O11<0.5,"недостаточно данных",IF($P11<3,"низкая доказательность",IF($O11>=0.85,"готов к сравнению","требует дополнения")))) -> низкая доказательность
B12: =IF($A12="","",IFERROR(VLOOKUP($A12,'02_Конкуренты'!$A$4:$B$203,2,FALSE),"не найдено")) | O12: =IF($A12="","",COUNTA($C12:$N12)/12) | P12: =IF($A12="","",IFERROR(AVERAGEIF('03_Факты_сайта'!$B$4:$B$503,$A12,'03_Факты_сайта'!$I$4:$I$503),0)) | Q12: =IF($A12="","",IF($O12<0.5,"недостаточно данных",IF($P12<3,"низкая доказательность",IF($O12>=0.85,"готов к сравнению","требует дополнения"))))
B13: =IF($A13="","",IFERROR(VLOOKUP($A13,'02_Конкуренты'!$A$4:$B$203,2,FALSE),"не найдено")) | O13: =IF($A13="","",COUNTA($C13:$N13)/12) | P13: =IF($A13="","",IFERROR(AVERAGEIF('03_Факты_сайта'!$B$4:$B$503,$A13,'03_Факты_сайта'!$I$4:$I$503),0)) | Q13: =IF($A13="","",IF($O13<0.5,"недостаточно данных",IF($P13<3,"низкая доказательность",IF($O13>=0.85,"готов к сравнению","требует дополнения"))))
B14: =IF($A14="","",IFERROR(VLOOKUP($A14,'02_Конкуренты'!$A$4:$B$203,2,FALSE),"не найдено")) | O14: =IF($A14="","",COUNTA($C14:$N14)/12) | P14: =IF($A14="","",IFERROR(AVERAGEIF('03_Факты_сайта'!$B$4:$B$503,$A14,'03_Факты_сайта'!$I$4:$I$503),0)) | Q14: =IF($A14="","",IF($O14<0.5,"недостаточно данных",IF($P14<3,"низкая доказательность",IF($O14>=0.85,"готов к сравнению","требует дополнения"))))
B15: =IF($A15="","",IFERROR(VLOOKUP($A15,'02_Конкуренты'!$A$4:$B$203,2,FALSE),"не найдено")) | O15: =IF($A15="","",COUNTA($C15:$N15)/12) | P15: =IF($A15="","",IFERROR(AVERAGEIF('03_Факты_сайта'!$B$4:$B$503,$A15,'03_Факты_сайта'!$I$4:$I$503),0)) | Q15: =IF($A15="","",IF($O15<0.5,"недостаточно данных",IF($P15<3,"низкая доказательность",IF($O15>=0.85,"готов к сравнению","требует дополнения"))))
B16: =IF($A16="","",IFERROR(VLOOKUP($A16,'02_Конкуренты'!$A$4:$B$203,2,FALSE),"не найдено")) | O16: =IF($A16="","",COUNTA($C16:$N16)/12) | P16: =IF($A16="","",IFERROR(AVERAGEIF('03_Факты_сайта'!$B$4:$B$503,$A16,'03_Факты_сайта'!$I$4:$I$503),0)) | Q16: =IF($A16="","",IF($O16<0.5,"недостаточно данных",IF($P16<3,"низкая доказательность",IF($O16>=0.85,"готов к сравнению","требует дополнения"))))
B17: =IF($A17="","",IFERROR(VLOOKUP($A17,'02_Конкуренты'!$A$4:$B$203,2,FALSE),"не найдено")) | O17: =IF($A17="","",COUNTA($C17:$N17)/12) | P17: =IF($A17="","",IFERROR(AVERAGEIF('03_Факты_сайта'!$B$4:$B$503,$A17,'03_Факты_сайта'!$I$4:$I$503),0)) | Q17: =IF($A17="","",IF($O17<0.5,"недостаточно данных",IF($P17<3,"низкая доказательность",IF($O17>=0.85,"готов к сравнению","требует дополнения"))))
B18: =IF($A18="","",IFERROR(VLOOKUP($A18,'02_Конкуренты'!$A$4:$B$203,2,FALSE),"не найдено")) | O18: =IF($A18="","",COUNTA($C18:$N18)/12) | P18: =IF($A18="","",IFERROR(AVERAGEIF('03_Факты_сайта'!$B$4:$B$503,$A18,'03_Факты_сайта'!$I$4:$I$503),0)) | Q18: =IF($A18="","",IF($O18<0.5,"недостаточно данных",IF($P18<3,"низкая доказательность",IF($O18>=0.85,"готов к сравнению","требует дополнения"))))
B19: =IF($A19="","",IFERROR(VLOOKUP($A19,'02_Конкуренты'!$A$4:$B$203,2,FALSE),"не найдено")) | O19: =IF($A19="","",COUNTA($C19:$N19)/12) | P19: =IF($A19="","",IFERROR(AVERAGEIF('03_Факты_сайта'!$B$4:$B$503,$A19,'03_Факты_сайта'!$I$4:$I$503),0)) | Q19: =IF($A19="","",IF($O19<0.5,"недостаточно данных",IF($P19<3,"низкая доказательность",IF($O19>=0.85,"готов к сравнению","требует дополнения"))))
B20: =IF($A20="","",IFERROR(VLOOKUP($A20,'02_Конкуренты'!$A$4:$B$203,2,FALSE),"не найдено")) | O20: =IF($A20="","",COUNTA($C20:$N20)/12) | P20: =IF($A20="","",IFERROR(AVERAGEIF('03_Факты_сайта'!$B$4:$B$503,$A20,'03_Факты_сайта'!$I$4:$I$503),0)) | Q20: =IF($A20="","",IF($O20<0.5,"недостаточно данных",IF($P20<3,"низкая доказательность",IF($O20>=0.85,"готов к сравнению","требует дополнения"))))
B21: =IF($A21="","",IFERROR(VLOOKUP($A21,'02_Конкуренты'!$A$4:$B$203,2,FALSE),"не найдено")) | O21: =IF($A21="","",COUNTA($C21:$N21)/12) | P21: =IF($A21="","",IFERROR(AVERAGEIF('03_Факты_сайта'!$B$4:$B$503,$A21,'03_Факты_сайта'!$I$4:$I$503),0)) | Q21: =IF($A21="","",IF($O21<0.5,"недостаточно данных",IF($P21<3,"низкая доказательность",IF($O21>=0.85,"готов к сравнению","требует дополнения"))))
B22: =IF($A22="","",IFERROR(VLOOKUP($A22,'02_Конкуренты'!$A$4:$B$203,2,FALSE),"не найдено")) | O22: =IF($A22="","",COUNTA($C22:$N22)/12) | P22: =IF($A22="","",IFERROR(AVERAGEIF('03_Факты_сайта'!$B$4:$B$503,$A22,'03_Факты_сайта'!$I$4:$I$503),0)) | Q22: =IF($A22="","",IF($O22<0.5,"недостаточно данных",IF($P22<3,"низкая доказательность",IF($O22>=0.85,"готов к сравнению","требует дополнения"))))
B23: =IF($A23="","",IFERROR(VLOOKUP($A23,'02_Конкуренты'!$A$4:$B$203,2,FALSE),"не найдено")) | O23: =IF($A23="","",COUNTA($C23:$N23)/12) | P23: =IF($A23="","",IFERROR(AVERAGEIF('03_Факты_сайта'!$B$4:$B$503,$A23,'03_Факты_сайта'!$I$4:$I$503),0)) | Q23: =IF($A23="","",IF($O23<0.5,"недостаточно данных",IF($P23<3,"низкая доказательность",IF($O23>=0.85,"готов к сравнению","требует дополнения"))))
... B203: =IF($A203="","",IFERROR(VLOOKUP($A203,'02_Конкуренты'!$A$4:$B$203,2,FALSE),"не найдено")) | O203: =IF($A203="","",COUNTA($C203:$N203)/12) | P203: =IF($A203="","",IFERROR(AVERAGEIF('03_Факты_сайта'!$B$4:$B$503,$A203,'03_Факты_сайта'!$I$4:$I$503),0)) | Q203: =IF($A203="","",IF($O203<0.5,"недостаточно данных",IF($P203<3,"низкая доказательность",IF($O203>=0.85,"готов к сравнению","требует дополнения"))))
A205: Примечание: сначала заполните ID конкурента, затем восстановите блоки бизнес-модели на основе листа 03_Факты_сайта. Не заполняйте гипотезу без ссылок на доказательства. | B205: Примечание: сначала заполните ID конкурента, затем восстановите блоки бизнес-модели на основе листа 03_Факты_сайта. Не заполняйте гипотезу без ссылок на доказательства. | C205: Примечание: сначала заполните ID конкурента, затем восстановите блоки бизнес-модели на основе листа 03_Факты_сайта. Не заполняйте гипотезу без ссылок на доказательства. | D205: Примечание: сначала заполните ID конкурента, затем восстановите блоки бизнес-модели на основе листа 03_Факты_сайта. Не заполняйте гипотезу без ссылок на доказательства. | E205: Примечание: сначала заполните ID конкурента, затем восстановите блоки бизнес-модели на основе листа 03_Факты_сайта. Не заполняйте гипотезу без ссылок на доказательства. | F205: Примечание: сначала заполните ID конкурента, затем восстановите блоки бизнес-модели на основе листа 03_Факты_сайта. Не заполняйте гипотезу без ссылок на доказательства. | G205: Примечание: сначала заполните ID конкурента, затем восстановите блоки бизнес-модели на основе листа 03_Факты_сайта. Не заполняйте гипотезу без ссылок на доказательства. | H205: Примечание: сначала заполните ID конкурента, затем восстановите блоки бизнес-модели на основе листа 03_Факты_сайта. Не заполняйте гипотезу без ссылок на доказательства. | I205: Примечание: сначала заполните ID конкурента, затем восстановите блоки бизнес-модели на основе листа 03_Факты_сайта. Не заполняйте гипотезу без ссылок на доказательства. | J205: Примечание: сначала заполните ID конкурента, затем восстановите блоки бизнес-модели на основе листа 03_Факты_сайта. Не заполняйте гипотезу без ссылок на доказательства. | K205: Примечание: сначала заполните ID конкурента, затем восстановите блоки бизнес-модели на основе листа 03_Факты_сайта. Не заполняйте гипотезу без ссылок на доказательства. | L205: Примечание: сначала заполните ID конкурента, затем восстановите блоки бизнес-модели на основе листа 03_Факты_сайта. Не заполняйте гипотезу без ссылок на доказательства. | M205: Примечание: сначала заполните ID конкурента, затем восстановите блоки бизнес-модели на основе листа 03_Факты_сайта. Не заполняйте гипотезу без ссылок на доказательства. | N205: Примечание: сначала заполните ID конкурента, затем восстановите блоки бизнес-модели на основе листа 03_Факты_сайта. Не заполняйте гипотезу без ссылок на доказательства. | O205: Примечание: сначала заполните ID конкурента, затем восстановите блоки бизнес-модели на основе листа 03_Факты_сайта. Не заполняйте гипотезу без ссылок на доказательства. | P205: Примечание: сначала заполните ID конкурента, затем восстановите блоки бизнес-модели на основе листа 03_Факты_сайта. Не заполняйте гипотезу без ссылок на доказательства. | Q205: Примечание: сначала заполните ID конкурента, затем восстановите блоки бизнес-модели на основе листа 03_Факты_сайта. Не заполняйте гипотезу без ссылок на доказательства.

Sheet 05_Товар_ценность
A1: Цифровой товар и ценностное предложение
A2: Лист помогает отделить сам цифровой товар от упаковки, сервиса, каналов продажи и обещаний на сайте.
A3: ID конкурента | B3: Название | C3: Ядро цифрового товара | D3: Базовое предложение | E3: Ожидаемый уровень | F3: Расширенный уровень | G3: Потенциальное развитие | H3: Клиентская проблема | I3: Клиентский результат | J3: Задача клиента | K3: Отличие от рынка | L3: Подтверждающие страницы | M3: Вывод о роли товара в бизнес-модели
A4: C01 | B4: =IF($A4="","",IFERROR(VLOOKUP($A4,'02_Конкуренты'!$A$4:$B$203,2,FALSE),"не найдено")) -> PlantUML | C4: Рендер UML из текста | D4: Онлайн-сервер и jar | E4: Плагины IDE, документация | F4: GitHub-расширение | G4: Не заявлено | H4: Ручное рисование UML | I4: Диаграмма в документации за минуты | J4: Документировать ПО | K4: Бесплатен, работает локально | L4: Главная, загрузка | M4: Товар — ядро некоммерческой экосистемы
A5: C02 | B5: =IF($A5="","",IFERROR(VLOOKUP($A5,'02_Конкуренты'!$A$4:$B$203,2,FALSE),"не найдено")) -> Eraser (DiagramGPT) | C5: Диаграмма из текста/AI | D5: Free: канвас + DSL + 3 AI | E5: Интеграции, история версий | F5: SSO, API, usage reporting | G5: MCP-агенты, git-синхронизация | H5: Долго рисовать архитектуру | I5: Диаграммы для документации команды | J5: Документировать архитектуру | K5: AI + DSL + канвас | L5: Тарифы, AI diagrams | M5: Товар — драйвер подписки
A6: C03 | B6: =IF($A6="","",IFERROR(VLOOKUP($A6,'02_Конкуренты'!$A$4:$B$203,2,FALSE),"не найдено")) -> Mermaid (open source) | C6: Диаграмма в Markdown | D6: Библиотека + Live Editor | E6: Встроенность в GitHub/GitLab/Notion | F6: Mermaid Chart для команд | G6: Развитие сообществом | H6: Диаграммы отдельно от документации | I6: Диаграмма живёт в репозитории | J6: Документировать в Markdown | K6: Нативность в платформах | L6: Главная, интеграции | M6: Товар — стандарт, монетизируемый надстройкой
A7: C04 | B7: =IF($A7="","",IFERROR(VLOOKUP($A7,'02_Конкуренты'!$A$4:$B$203,2,FALSE),"не найдено")) -> D2 | C7: Текст → диаграмма | D7: CLI + playground | E7: Экспорт 6 форматов | F7: Плагины редакторов | G7: UML class/sequence | H7: Некрасивые авто-схемы | I7: Красивая раскладка | J7: Архитектурные схемы | K7: 3 движка раскладки | L7: Главная, FAQ | M7: Товар — технология раскладки
A8: C05 | B8: =IF($A8="","",IFERROR(VLOOKUP($A8,'02_Конкуренты'!$A$4:$B$203,2,FALSE),"не найдено")) -> Gleek | C8: Текст → диаграмма (🔲) | D8: Free-план (🔲) | E8: 🔲 | F8: Pro (🔲) | G8: 🔲 | H8: 🔲 | I8: 🔲 | J8: 🔲 | K8: Собственный DSL | L8: Главная (🔲) | M8: 🔲
A9: C07 | B9: =IF($A9="","",IFERROR(VLOOKUP($A9,'02_Конкуренты'!$A$4:$B$203,2,FALSE),"не найдено")) -> draw.io / diagrams.net | C9: Нарисовать любую диаграмму | D9: Бесплатный редактор | E9: Без регистрации, хранение у пользователя | F9: Интеграции с офисными платформами | G9: Без VC — стабильность | H9: Дорогие корпоративные редакторы | I9: Профессиональная схема бесплатно | J9: Нарисовать схему | K9: Цена 0 и приватность | L9: Главная | M9: Товар — бесплатный стандарт GUI
A10: C08 | B10: =IF($A10="","",IFERROR(VLOOKUP($A10,'02_Конкуренты'!$A$4:$B$203,2,FALSE),"не найдено")) -> Ramus (Educational) | C10: IDEF0/DFD-модель | D10: Настольное приложение | E10: 🔲 | F10: 🔲 | G10: Не обнаружено | H10: Нет инструмента IDEF | I10: Сдать учебную модель | J10: Лабораторные по IDEF | K10: IDEF на русском | L10: 🔲 | M10: Нишевой учебный товар
A11: C09 | B11: =IF($A11="","",IFERROR(VLOOKUP($A11,'02_Конкуренты'!$A$4:$B$203,2,FALSE),"не найдено")) -> Lucidchart | C11: Совместная диаграмма | D11: SaaS-редактор | E11: Шаблоны, совместная работа | F11: AI-генерация | G11: 🔲 | H11: Разрозненная командная работа | I11: Схема в команде | J11: Командная работа | K11: Совместное редактирование | L11: 🔲 | M11: Товар — командная подписка
B12: =IF($A12="","",IFERROR(VLOOKUP($A12,'02_Конкуренты'!$A$4:$B$203,2,FALSE),"не найдено"))
B13: =IF($A13="","",IFERROR(VLOOKUP($A13,'02_Конкуренты'!$A$4:$B$203,2,FALSE),"не найдено"))
B14: =IF($A14="","",IFERROR(VLOOKUP($A14,'02_Конкуренты'!$A$4:$B$203,2,FALSE),"не найдено"))
B15: =IF($A15="","",IFERROR(VLOOKUP($A15,'02_Конкуренты'!$A$4:$B$203,2,FALSE),"не найдено"))
B16: =IF($A16="","",IFERROR(VLOOKUP($A16,'02_Конкуренты'!$A$4:$B$203,2,FALSE),"не найдено"))
B17: =IF($A17="","",IFERROR(VLOOKUP($A17,'02_Конкуренты'!$A$4:$B$203,2,FALSE),"не найдено"))
B18: =IF($A18="","",IFERROR(VLOOKUP($A18,'02_Конкуренты'!$A$4:$B$203,2,FALSE),"не найдено"))
B19: =IF($A19="","",IFERROR(VLOOKUP($A19,'02_Конкуренты'!$A$4:$B$203,2,FALSE),"не найдено"))
B20: =IF($A20="","",IFERROR(VLOOKUP($A20,'02_Конкуренты'!$A$4:$B$203,2,FALSE),"не найдено"))
B21: =IF($A21="","",IFERROR(VLOOKUP($A21,'02_Конкуренты'!$A$4:$B$203,2,FALSE),"не найдено"))
B22: =IF($A22="","",IFERROR(VLOOKUP($A22,'02_Конкуренты'!$A$4:$B$203,2,FALSE),"не найдено"))
B23: =IF($A23="","",IFERROR(VLOOKUP($A23,'02_Конкуренты'!$A$4:$B$203,2,FALSE),"не найдено"))
... B203: =IF($A203="","",IFERROR(VLOOKUP($A203,'02_Конкуренты'!$A$4:$B$203,2,FALSE),"не найдено"))

Sheet 06_Монетизация
A1: Монетизация и потоки доходов
A2: Фиксируются признаки получения выручки: тарифы, пробный доступ, условия оплаты, ограничения и коммерческая логика.
A3: ID конкурента | B3: Название | C3: Модель монетизации | D3: Страница с тарифами/ценой | E3: Наличие бесплатного уровня | F3: Пробный доступ | G3: Тарифные уровни | H3: Единица оплаты | I3: Ограничения тарифа | J3: Платежная периодичность | K3: Признаки корпоративных продаж | L3: Прозрачность цены 1-5 | M3: Гибкость модели 1-5 | N3: Вывод о потоках доходов
A4: C01 | B4: =IF($A4="","",IFERROR(VLOOKUP($A4,'02_Конкуренты'!$A$4:$B$203,2,FALSE),"не найдено")) -> PlantUML | C4: условно-бесплатная модель | D4: нет (бесплатно) | E4: да, полностью | F4: не требуется | G4: нет | H4: — | I4: нет | J4: — | K4: нет | L4: 5 | M4: 1 | N4: Выручки от товара нет; конкурирует ценой 0
A5: C02 | B5: =IF($A5="","",IFERROR(VLOOKUP($A5,'02_Конкуренты'!$A$4:$B$203,2,FALSE),"не найдено")) -> Eraser (DiagramGPT) | C5: подписка | D5: да | E5: да, Free | F5: Free-тариф | G5: 4 уровня | H5: участник/мес | I5: лимит AI 3/40/250/∞, история 90 дней → безлимит | J5: мес/год (скидка за год) | K5: Enterprise по запросу, SSO | L5: 5 | M5: 4 | N5: Подписка по местам с лимитом AI
A6: C03 | B6: =IF($A6="","",IFERROR(VLOOKUP($A6,'02_Конкуренты'!$A$4:$B$203,2,FALSE),"не найдено")) -> Mermaid (open source) | C6: смешанная | D6: нет (Mermaid Chart — скрыто) | E6: да | F6: не требуется | G6: нет | H6: — | I6: нет | J6: — | K6: нет | L6: 2 | M6: 2 | N6: Донаты + отдельный SaaS
A7: C04 | B7: =IF($A7="","",IFERROR(VLOOKUP($A7,'02_Конкуренты'!$A$4:$B$203,2,FALSE),"не найдено")) -> D2 | C7: условно-бесплатная модель | D7: нет | E7: да | F7: не требуется | G7: нет | H7: — | I7: нет | J7: — | K7: нет | L7: 5 | M7: 1 | N7: Некоммерческий
A8: C05 | B8: =IF($A8="","",IFERROR(VLOOKUP($A8,'02_Конкуренты'!$A$4:$B$203,2,FALSE),"не найдено")) -> Gleek | C8: условно-бесплатная модель | D8: 🔲 | E8: да (kursach.md) | F8: 🔲 | G8: 🔲 | H8: 🔲 | I8: 🔲 | J8: 🔲 | K8: 🔲 | L8: 2 | M8: 3 | N8: 🔲 проверить
A9: C07 | B9: =IF($A9="","",IFERROR(VLOOKUP($A9,'02_Конкуренты'!$A$4:$B$203,2,FALSE),"не найдено")) -> draw.io / diagrams.net | C9: условно-бесплатная модель | D9: нет | E9: да, полностью | F9: не требуется | G9: нет | H9: — | I9: «no artificial scarcity» | J9: — | K9: нет Enterprise-тарифа | L9: 5 | M9: 2 | N9: Бесплатный редактор; доход — 🔲 (Atlassian Marketplace)
A10: C08 | B10: =IF($A10="","",IFERROR(VLOOKUP($A10,'02_Конкуренты'!$A$4:$B$203,2,FALSE),"не найдено")) -> Ramus (Educational) | C10: лицензия | D10: 🔲 | E10: Educational (🔲) | F10: 🔲 | G10: 🔲 | H10: лицензия | I10: 🔲 | J10: разово (🔲) | K10: 🔲 | L10: 1 | M10: 1 | N10: 🔲 проверить
A11: C09 | B11: =IF($A11="","",IFERROR(VLOOKUP($A11,'02_Конкуренты'!$A$4:$B$203,2,FALSE),"не найдено")) -> Lucidchart | C11: подписка | D11: 🔲 | E11: 🔲 | F11: 🔲 | G11: 🔲 | H11: 🔲 | I11: 🔲 | J11: 🔲 | K11: 🔲 | L11: 2 | M11: 3 | N11: 🔲 проверить
B12: =IF($A12="","",IFERROR(VLOOKUP($A12,'02_Конкуренты'!$A$4:$B$203,2,FALSE),"не найдено"))
B13: =IF($A13="","",IFERROR(VLOOKUP($A13,'02_Конкуренты'!$A$4:$B$203,2,FALSE),"не найдено"))
B14: =IF($A14="","",IFERROR(VLOOKUP($A14,'02_Конкуренты'!$A$4:$B$203,2,FALSE),"не найдено"))
B15: =IF($A15="","",IFERROR(VLOOKUP($A15,'02_Конкуренты'!$A$4:$B$203,2,FALSE),"не найдено"))
B16: =IF($A16="","",IFERROR(VLOOKUP($A16,'02_Конкуренты'!$A$4:$B$203,2,FALSE),"не найдено"))
B17: =IF($A17="","",IFERROR(VLOOKUP($A17,'02_Конкуренты'!$A$4:$B$203,2,FALSE),"не найдено"))
B18: =IF($A18="","",IFERROR(VLOOKUP($A18,'02_Конкуренты'!$A$4:$B$203,2,FALSE),"не найдено"))
B19: =IF($A19="","",IFERROR(VLOOKUP($A19,'02_Конкуренты'!$A$4:$B$203,2,FALSE),"не найдено"))
B20: =IF($A20="","",IFERROR(VLOOKUP($A20,'02_Конкуренты'!$A$4:$B$203,2,FALSE),"не найдено"))
B21: =IF($A21="","",IFERROR(VLOOKUP($A21,'02_Конкуренты'!$A$4:$B$203,2,FALSE),"не найдено"))
B22: =IF($A22="","",IFERROR(VLOOKUP($A22,'02_Конкуренты'!$A$4:$B$203,2,FALSE),"не найдено"))
B23: =IF($A23="","",IFERROR(VLOOKUP($A23,'02_Конкуренты'!$A$4:$B$203,2,FALSE),"не найдено"))
... B203: =IF($A203="","",IFERROR(VLOOKUP($A203,'02_Конкуренты'!$A$4:$B$203,2,FALSE),"не найдено"))

Sheet 07_Каналы
A1: Каналы, воронка и механика продаж
A2: Анализируется, как сайт превращает посетителя в пользователя, лид или покупателя.
A3: ID конкурента | B3: Название | C3: Главные каналы привлечения | D3: Контентная стратегия | E3: Поисковая видимость по сайту | F3: Призыв к действию | G3: Первичная конверсия | H3: Тип воронки | I3: Регистрация/заявка | J3: Демонстрация/пробный доступ | K3: Доверительные элементы | L3: Сложность пути клиента 1-5 | M3: Сила воронки 1-5 | N3: Вывод о рынке и каналах
A4: C01 | B4: =IF($A4="","",IFERROR(VLOOKUP($A4,'02_Конкуренты'!$A$4:$B$203,2,FALSE),"не найдено")) -> PlantUML | C4: Поиск, IDE, GitHub | D4: Документация, примеры | E4: Высокая (РФ 9,07 %) | F4: Попробовать онлайн | G4: Первая диаграмма без регистрации | H4: самостоятельная покупка | I4: не требуется | J4: онлайн-сервер | K4: open source, «no tracking» | L4: 1 | M4: 4 | N4: Контентно-продуктовая воронка без оплаты
A5: C02 | B5: =IF($A5="","",IFERROR(VLOOKUP($A5,'02_Конкуренты'!$A$4:$B$203,2,FALSE),"не найдено")) -> Eraser (DiagramGPT) | C5: Прямые заходы 49 %, поиск | D5: Блог, AI-лендинги | E5: Средняя (Индия 40,81 %) | F5: Try for free / Book demo | G5: Регистрация во Free | H5: пробный доступ | I5: да | J5: Free-тариф | K5: клиенты, интеграции | L5: 2 | M5: 5 | N5: PLG + корпоративные продажи
A6: C03 | B6: =IF($A6="","",IFERROR(VLOOKUP($A6,'02_Конкуренты'!$A$4:$B$203,2,FALSE),"не найдено")) -> Mermaid (open source) | C6: GitHub/GitLab/Notion | D6: Документация | E6: Высокая | F6: Live Editor | G6: Использование в Markdown | H6: контентная воронка | I6: не требуется | J6: Live Editor | K6: список контрибьюторов | L6: 1 | M6: 4 | N6: Воронка через платформы
A7: C04 | B7: =IF($A7="","",IFERROR(VLOOKUP($A7,'02_Конкуренты'!$A$4:$B$203,2,FALSE),"не найдено")) -> D2 | C7: GitHub, Discord, Homebrew | D7: Документация, tour | E7: 🔲 | F7: Playground | G7: Установка CLI | H7: самостоятельная покупка | I7: не требуется | J7: playground | K7: open source | L7: 2 | M7: 3 | N7: Open-source дистрибуция
A8: C05 | B8: =IF($A8="","",IFERROR(VLOOKUP($A8,'02_Конкуренты'!$A$4:$B$203,2,FALSE),"не найдено")) -> Gleek | C8: 🔲 | D8: 🔲 | E8: 🔲 | F8: 🔲 | G8: 🔲 | H8: регистрация | I8: 🔲 | J8: 🔲 | K8: 🔲 | L8: 3 | M8: 2 | N8: 🔲
A9: C07 | B9: =IF($A9="","",IFERROR(VLOOKUP($A9,'02_Конкуренты'!$A$4:$B$203,2,FALSE),"не найдено")) -> draw.io / diagrams.net | C9: Прямые заходы 68,65 %, интеграции | D9: Документация | E9: Очень высокая (7,8 млн визитов) | F9: Start now | G9: Диаграмма без регистрации | H9: самостоятельная покупка | I9: не требуется | J9: сразу редактор | K9: 100M+ users, open source | L9: 1 | M9: 5 | N9: Нулевой барьер и интеграции
A10: C08 | B10: =IF($A10="","",IFERROR(VLOOKUP($A10,'02_Конкуренты'!$A$4:$B$203,2,FALSE),"не найдено")) -> Ramus (Educational) | C10: Методички вузов (🔲) | D10: 🔲 | E10: Низкая (🔲) | F10: Скачать (🔲) | G10: Установка | H10: самостоятельная покупка | I10: 🔲 | J10: 🔲 | K10: 🔲 | L10: 4 | M10: 2 | N10: Канал — рекомендации преподавателей (🔲)
A11: C09 | B11: =IF($A11="","",IFERROR(VLOOKUP($A11,'02_Конкуренты'!$A$4:$B$203,2,FALSE),"не найдено")) -> Lucidchart | C11: 🔲 | D11: 🔲 | E11: 🔲 | F11: 🔲 | G11: Регистрация (🔲) | H11: регистрация | I11: да (🔲) | J11: 🔲 | K11: 🔲 | L11: 3 | M11: 4 | N11: 🔲
B12: =IF($A12="","",IFERROR(VLOOKUP($A12,'02_Конкуренты'!$A$4:$B$203,2,FALSE),"не найдено"))
B13: =IF($A13="","",IFERROR(VLOOKUP($A13,'02_Конкуренты'!$A$4:$B$203,2,FALSE),"не найдено"))
B14: =IF($A14="","",IFERROR(VLOOKUP($A14,'02_Конкуренты'!$A$4:$B$203,2,FALSE),"не найдено"))
B15: =IF($A15="","",IFERROR(VLOOKUP($A15,'02_Конкуренты'!$A$4:$B$203,2,FALSE),"не найдено"))
B16: =IF($A16="","",IFERROR(VLOOKUP($A16,'02_Конкуренты'!$A$4:$B$203,2,FALSE),"не найдено"))
B17: =IF($A17="","",IFERROR(VLOOKUP($A17,'02_Конкуренты'!$A$4:$B$203,2,FALSE),"не найдено"))
B18: =IF($A18="","",IFERROR(VLOOKUP($A18,'02_Конкуренты'!$A$4:$B$203,2,FALSE),"не найдено"))
B19: =IF($A19="","",IFERROR(VLOOKUP($A19,'02_Конкуренты'!$A$4:$B$203,2,FALSE),"не найдено"))
B20: =IF($A20="","",IFERROR(VLOOKUP($A20,'02_Конкуренты'!$A$4:$B$203,2,FALSE),"не найдено"))
B21: =IF($A21="","",IFERROR(VLOOKUP($A21,'02_Конкуренты'!$A$4:$B$203,2,FALSE),"не найдено"))
B22: =IF($A22="","",IFERROR(VLOOKUP($A22,'02_Конкуренты'!$A$4:$B$203,2,FALSE),"не найдено"))
B23: =IF($A23="","",IFERROR(VLOOKUP($A23,'02_Конкуренты'!$A$4:$B$203,2,FALSE),"не найдено"))
... B203: =IF($A203="","",IFERROR(VLOOKUP($A203,'02_Конкуренты'!$A$4:$B$203,2,FALSE),"не найдено"))

Sheet 08_Операц_модель
A1: Операционная основа бизнес-модели
A2: Лист фиксирует, за счет каких ресурсов, процессов, партнерств и данных конкурент поддерживает цифровой товар.
A3: ID конкурента | B3: Название | C3: Ключевые ресурсы | D3: Ключевые процессы | E3: Технологические признаки на сайте | F3: Использование данных | G3: Интеграции | H3: Партнеры | I3: Поддержка и сервис | J3: Признаки структуры затрат | K3: Масштабируемость 1-5 | L3: Трудность копирования 1-5 | M3: Операционный риск | N3: Вывод об устойчивости модели
A4: C01 | B4: =IF($A4="","",IFERROR(VLOOKUP($A4,'02_Конкуренты'!$A$4:$B$203,2,FALSE),"не найдено")) -> PlantUML | C4: Язык, рендер, документация | D4: Поддержка языка | E4: Java, JS-рендер | F4: Не собирает («no tracking») | G4: IDE, CI, GitHub | H4: Экосистема IDE | I4: Сообщество, документация | J4: Хостинг сервера | K4: 5 | L4: 3 | M4: Зависимость от автора | N4: Устойчив как стандарт, без выручки
A5: C02 | B5: =IF($A5="","",IFERROR(VLOOKUP($A5,'02_Конкуренты'!$A$4:$B$203,2,FALSE),"не найдено")) -> Eraser (DiagramGPT) | C5: AI-модель, интеграции | D5: Разработка AI, продажи | E5: AI, MCP | F5: История диаграмм пользователей | G5: GitHub, Notion, Confluence, VS Code | H5: Платформы | I5: Поддержка по тарифам | J5: Инференс AI, продажи | K5: 4 | L5: 4 | M5: Стоимость инференса | N5: Сильная, но дорогая модель
A6: C03 | B6: =IF($A6="","",IFERROR(VLOOKUP($A6,'02_Конкуренты'!$A$4:$B$203,2,FALSE),"не найдено")) -> Mermaid (open source) | C6: Код, сообщество | D6: Мейнтейнинг | E6: JS | F6: — | G6: GitHub, GitLab, Notion | H6: Платформы-хосты | I6: Сообщество | J6: Низкие | K6: 5 | L6: 5 | M6: Зависимость от волонтёров | N6: Очень устойчив за счёт встроенности
A7: C04 | B7: =IF($A7="","",IFERROR(VLOOKUP($A7,'02_Конкуренты'!$A$4:$B$203,2,FALSE),"не найдено")) -> D2 | C7: Язык, раскладка | D7: Разработка | E7: Go, 3 движка | F7: — | G7: VS Code, Vim | H7: Hack Club | I7: Discord | J7: Низкие | K7: 4 | L7: 3 | M7: Финансирование донатами | N7: Технологически сильный, коммерчески слабый
A8: C05 | B8: =IF($A8="","",IFERROR(VLOOKUP($A8,'02_Конкуренты'!$A$4:$B$203,2,FALSE),"не найдено")) -> Gleek | C8: 🔲 | D8: 🔲 | E8: 🔲 | F8: 🔲 | G8: 🔲 | H8: 🔲 | I8: 🔲 | J8: 🔲 | K8: 3 | L8: 2 | M8: 🔲 | N8: 🔲
A9: C07 | B9: =IF($A9="","",IFERROR(VLOOKUP($A9,'02_Конкуренты'!$A$4:$B$203,2,FALSE),"не найдено")) -> draw.io / diagrams.net | C9: История, бренд, совместимость | D9: Разработка | E9: JS, desktop | F9: Хранение у пользователя | G9: Google, Microsoft, Atlassian, GitHub | H9: Atlassian и др. | I9: Документация | J9: Разработка | K9: 5 | L9: 4 | M9: Нет прямой выручки (🔲) | N9: Устойчив благодаря интеграциям
A10: C08 | B10: =IF($A10="","",IFERROR(VLOOKUP($A10,'02_Конкуренты'!$A$4:$B$203,2,FALSE),"не найдено")) -> Ramus (Educational) | C10: 🔲 | D10: 🔲 | E10: Desktop | F10: 🔲 | G10: 🔲 | H10: Вузы (🔲) | I10: 🔲 | J10: 🔲 | K10: 2 | L10: 2 | M10: Устаревание | N10: 🔲
A11: C09 | B11: =IF($A11="","",IFERROR(VLOOKUP($A11,'02_Конкуренты'!$A$4:$B$203,2,FALSE),"не найдено")) -> Lucidchart | C11: 🔲 | D11: 🔲 | E11: SaaS, AI | F11: 🔲 | G11: 🔲 | H11: 🔲 | I11: 🔲 | J11: 🔲 | K11: 4 | L11: 3 | M11: 🔲 | N11: 🔲
B12: =IF($A12="","",IFERROR(VLOOKUP($A12,'02_Конкуренты'!$A$4:$B$203,2,FALSE),"не найдено"))
B13: =IF($A13="","",IFERROR(VLOOKUP($A13,'02_Конкуренты'!$A$4:$B$203,2,FALSE),"не найдено"))
B14: =IF($A14="","",IFERROR(VLOOKUP($A14,'02_Конкуренты'!$A$4:$B$203,2,FALSE),"не найдено"))
B15: =IF($A15="","",IFERROR(VLOOKUP($A15,'02_Конкуренты'!$A$4:$B$203,2,FALSE),"не найдено"))
B16: =IF($A16="","",IFERROR(VLOOKUP($A16,'02_Конкуренты'!$A$4:$B$203,2,FALSE),"не найдено"))
B17: =IF($A17="","",IFERROR(VLOOKUP($A17,'02_Конкуренты'!$A$4:$B$203,2,FALSE),"не найдено"))
B18: =IF($A18="","",IFERROR(VLOOKUP($A18,'02_Конкуренты'!$A$4:$B$203,2,FALSE),"не найдено"))
B19: =IF($A19="","",IFERROR(VLOOKUP($A19,'02_Конкуренты'!$A$4:$B$203,2,FALSE),"не найдено"))
B20: =IF($A20="","",IFERROR(VLOOKUP($A20,'02_Конкуренты'!$A$4:$B$203,2,FALSE),"не найдено"))
B21: =IF($A21="","",IFERROR(VLOOKUP($A21,'02_Конкуренты'!$A$4:$B$203,2,FALSE),"не найдено"))
B22: =IF($A22="","",IFERROR(VLOOKUP($A22,'02_Конкуренты'!$A$4:$B$203,2,FALSE),"не найдено"))
B23: =IF($A23="","",IFERROR(VLOOKUP($A23,'02_Конкуренты'!$A$4:$B$203,2,FALSE),"не найдено"))
... B203: =IF($A203="","",IFERROR(VLOOKUP($A203,'02_Конкуренты'!$A$4:$B$203,2,FALSE),"не найдено"))

Sheet 09_Матрица
A1: Сравнительная матрица бизнес-моделей
A2: Вес | C2: 10 | D2: 15 | E2: 15 | F2: 10 | G2: 5 | H2: 15 | I2: 5 | J2: 5 | K2: 5 | L2: 10 | M2: 5
A3: ID конкурента | B3: Название | C3: Сегменты | D3: Ценность | E3: Товар | F3: Каналы | G3: Отношения | H3: Доходы | I3: Ресурсы | J3: Партнеры | K3: Данные/сеть | L3: Масштаб | M3: Защищенность | N3: Индекс силы | O3: Доказательность | P3: Полнота | Q3: Итог с учетом надежности
A4: C01 | B4: =IF($A4="","",IFERROR(VLOOKUP($A4,'02_Конкуренты'!$A$4:$B$203,2,FALSE),"не найдено")) -> PlantUML | C4: 4 | D4: 4 | E4: 4 | F4: 4 | G4: 3 | H4: 1 | I4: 4 | J4: 4 | K4: 3 | L4: 5 | M4: 4 | N4: =IF($A4="","",SUMPRODUCT($C4:$M4,$C$2:$M$2)/SUM($C$2:$M$2)) -> 3.55 | O4: =IF($A4="","",IFERROR(VLOOKUP($A4,'04_Бизнес_модель'!$A$4:$P$203,16,FALSE),0)) -> 4 | P4: =IF($A4="","",IFERROR(VLOOKUP($A4,'04_Бизнес_модель'!$A$4:$O$203,15,FALSE),0)) -> 1 | Q4: =IF($A4="","",$N4*0.6+$O4*0.25+$P4*5*0.15) -> 3.88
A5: C02 | B5: =IF($A5="","",IFERROR(VLOOKUP($A5,'02_Конкуренты'!$A$4:$B$203,2,FALSE),"не найдено")) -> Eraser (DiagramGPT) | C5: 4 | D5: 5 | E5: 5 | F5: 4 | G5: 4 | H5: 5 | I5: 4 | J5: 4 | K5: 3 | L5: 4 | M5: 4 | N5: =IF($A5="","",SUMPRODUCT($C5:$M5,$C$2:$M$2)/SUM($C$2:$M$2)) -> 4.4 | O5: =IF($A5="","",IFERROR(VLOOKUP($A5,'04_Бизнес_модель'!$A$4:$P$203,16,FALSE),0)) -> 4.4 | P5: =IF($A5="","",IFERROR(VLOOKUP($A5,'04_Бизнес_модель'!$A$4:$O$203,15,FALSE),0)) -> 1 | Q5: =IF($A5="","",$N5*0.6+$O5*0.25+$P5*5*0.15) -> 4.49
A6: C03 | B6: =IF($A6="","",IFERROR(VLOOKUP($A6,'02_Конкуренты'!$A$4:$B$203,2,FALSE),"не найдено")) -> Mermaid (open source) | C6: 4 | D6: 4 | E6: 4 | F6: 5 | G6: 3 | H6: 1 | I6: 4 | J6: 5 | K6: 4 | L6: 5 | M6: 5 | N6: =IF($A6="","",SUMPRODUCT($C6:$M6,$C$2:$M$2)/SUM($C$2:$M$2)) -> 3.8 | O6: =IF($A6="","",IFERROR(VLOOKUP($A6,'04_Бизнес_модель'!$A$4:$P$203,16,FALSE),0)) -> 3.75 | P6: =IF($A6="","",IFERROR(VLOOKUP($A6,'04_Бизнес_модель'!$A$4:$O$203,15,FALSE),0)) -> 1 | Q6: =IF($A6="","",$N6*0.6+$O6*0.25+$P6*5*0.15) -> 3.9675
A7: C04 | B7: =IF($A7="","",IFERROR(VLOOKUP($A7,'02_Конкуренты'!$A$4:$B$203,2,FALSE),"не найдено")) -> D2 | C7: 3 | D7: 4 | E7: 4 | F7: 3 | G7: 3 | H7: 1 | I7: 3 | J7: 3 | K7: 2 | L7: 4 | M7: 3 | N7: =IF($A7="","",SUMPRODUCT($C7:$M7,$C$2:$M$2)/SUM($C$2:$M$2)) -> 3.05 | O7: =IF($A7="","",IFERROR(VLOOKUP($A7,'04_Бизнес_модель'!$A$4:$P$203,16,FALSE),0)) -> 4.25 | P7: =IF($A7="","",IFERROR(VLOOKUP($A7,'04_Бизнес_модель'!$A$4:$O$203,15,FALSE),0)) -> 0.91666667 | Q7: =IF($A7="","",$N7*0.6+$O7*0.25+$P7*5*0.15) -> 3.58
A8: C05 | B8: =IF($A8="","",IFERROR(VLOOKUP($A8,'02_Конкуренты'!$A$4:$B$203,2,FALSE),"не найдено")) -> Gleek | C8: 3 | D8: 3 | E8: 3 | F8: 2 | G8: 2 | H8: 3 | I8: 2 | J8: 1 | K8: 1 | L8: 3 | M8: 2 | N8: =IF($A8="","",SUMPRODUCT($C8:$M8,$C$2:$M$2)/SUM($C$2:$M$2)) -> 2.55 | O8: =IF($A8="","",IFERROR(VLOOKUP($A8,'04_Бизнес_модель'!$A$4:$P$203,16,FALSE),0)) -> 2.5 | P8: =IF($A8="","",IFERROR(VLOOKUP($A8,'04_Бизнес_модель'!$A$4:$O$203,15,FALSE),0)) -> 0.41666667 | Q8: =IF($A8="","",$N8*0.6+$O8*0.25+$P8*5*0.15) -> 2.4675
A9: C07 | B9: =IF($A9="","",IFERROR(VLOOKUP($A9,'02_Конкуренты'!$A$4:$B$203,2,FALSE),"не найдено")) -> draw.io / diagrams.net | C9: 5 | D9: 5 | E9: 4 | F9: 5 | G9: 3 | H9: 2 | I9: 5 | J9: 5 | K9: 3 | L9: 5 | M9: 4 | N9: =IF($A9="","",SUMPRODUCT($C9:$M9,$C$2:$M$2)/SUM($C$2:$M$2)) -> 4.15 | O9: =IF($A9="","",IFERROR(VLOOKUP($A9,'04_Бизнес_модель'!$A$4:$P$203,16,FALSE),0)) -> 4.4 | P9: =IF($A9="","",IFERROR(VLOOKUP($A9,'04_Бизнес_модель'!$A$4:$O$203,15,FALSE),0)) -> 1 | Q9: =IF($A9="","",$N9*0.6+$O9*0.25+$P9*5*0.15) -> 4.34
A10: C08 | B10: =IF($A10="","",IFERROR(VLOOKUP($A10,'02_Конкуренты'!$A$4:$B$203,2,FALSE),"не найдено")) -> Ramus (Educational) | C10: 3 | D10: 3 | E10: 3 | F10: 1 | G10: 2 | H10: 2 | I10: 2 | J10: 1 | K10: 1 | L10: 2 | M10: 2 | N10: =IF($A10="","",SUMPRODUCT($C10:$M10,$C$2:$M$2)/SUM($C$2:$M$2)) -> 2.2 | O10: =IF($A10="","",IFERROR(VLOOKUP($A10,'04_Бизнес_модель'!$A$4:$P$203,16,FALSE),0)) -> 3 | P10: =IF($A10="","",IFERROR(VLOOKUP($A10,'04_Бизнес_модель'!$A$4:$O$203,15,FALSE),0)) -> 0.41666667 | Q10: =IF($A10="","",$N10*0.6+$O10*0.25+$P10*5*0.15) -> 2.3825
A11: C09 | B11: =IF($A11="","",IFERROR(VLOOKUP($A11,'02_Конкуренты'!$A$4:$B$203,2,FALSE),"не найдено")) -> Lucidchart | C11: 4 | D11: 4 | E11: 4 | F11: 4 | G11: 4 | H11: 4 | I11: 4 | J11: 3 | K11: 3 | L11: 4 | M11: 4 | N11: =IF($A11="","",SUMPRODUCT($C11:$M11,$C$2:$M$2)/SUM($C$2:$M$2)) -> 3.9 | O11: =IF($A11="","",IFERROR(VLOOKUP($A11,'04_Бизнес_модель'!$A$4:$P$203,16,FALSE),0)) -> 2.5 | P11: =IF($A11="","",IFERROR(VLOOKUP($A11,'04_Бизнес_модель'!$A$4:$O$203,15,FALSE),0)) -> 0.5 | Q11: =IF($A11="","",$N11*0.6+$O11*0.25+$P11*5*0.15) -> 3.34
B12: =IF($A12="","",IFERROR(VLOOKUP($A12,'02_Конкуренты'!$A$4:$B$203,2,FALSE),"не найдено")) | N12: =IF($A12="","",SUMPRODUCT($C12:$M12,$C$2:$M$2)/SUM($C$2:$M$2)) | O12: =IF($A12="","",IFERROR(VLOOKUP($A12,'04_Бизнес_модель'!$A$4:$P$203,16,FALSE),0)) | P12: =IF($A12="","",IFERROR(VLOOKUP($A12,'04_Бизнес_модель'!$A$4:$O$203,15,FALSE),0)) | Q12: =IF($A12="","",$N12*0.6+$O12*0.25+$P12*5*0.15)
B13: =IF($A13="","",IFERROR(VLOOKUP($A13,'02_Конкуренты'!$A$4:$B$203,2,FALSE),"не найдено")) | N13: =IF($A13="","",SUMPRODUCT($C13:$M13,$C$2:$M$2)/SUM($C$2:$M$2)) | O13: =IF($A13="","",IFERROR(VLOOKUP($A13,'04_Бизнес_модель'!$A$4:$P$203,16,FALSE),0)) | P13: =IF($A13="","",IFERROR(VLOOKUP($A13,'04_Бизнес_модель'!$A$4:$O$203,15,FALSE),0)) | Q13: =IF($A13="","",$N13*0.6+$O13*0.25+$P13*5*0.15)
B14: =IF($A14="","",IFERROR(VLOOKUP($A14,'02_Конкуренты'!$A$4:$B$203,2,FALSE),"не найдено")) | N14: =IF($A14="","",SUMPRODUCT($C14:$M14,$C$2:$M$2)/SUM($C$2:$M$2)) | O14: =IF($A14="","",IFERROR(VLOOKUP($A14,'04_Бизнес_модель'!$A$4:$P$203,16,FALSE),0)) | P14: =IF($A14="","",IFERROR(VLOOKUP($A14,'04_Бизнес_модель'!$A$4:$O$203,15,FALSE),0)) | Q14: =IF($A14="","",$N14*0.6+$O14*0.25+$P14*5*0.15)
B15: =IF($A15="","",IFERROR(VLOOKUP($A15,'02_Конкуренты'!$A$4:$B$203,2,FALSE),"не найдено")) | N15: =IF($A15="","",SUMPRODUCT($C15:$M15,$C$2:$M$2)/SUM($C$2:$M$2)) | O15: =IF($A15="","",IFERROR(VLOOKUP($A15,'04_Бизнес_модель'!$A$4:$P$203,16,FALSE),0)) | P15: =IF($A15="","",IFERROR(VLOOKUP($A15,'04_Бизнес_модель'!$A$4:$O$203,15,FALSE),0)) | Q15: =IF($A15="","",$N15*0.6+$O15*0.25+$P15*5*0.15)
B16: =IF($A16="","",IFERROR(VLOOKUP($A16,'02_Конкуренты'!$A$4:$B$203,2,FALSE),"не найдено")) | N16: =IF($A16="","",SUMPRODUCT($C16:$M16,$C$2:$M$2)/SUM($C$2:$M$2)) | O16: =IF($A16="","",IFERROR(VLOOKUP($A16,'04_Бизнес_модель'!$A$4:$P$203,16,FALSE),0)) | P16: =IF($A16="","",IFERROR(VLOOKUP($A16,'04_Бизнес_модель'!$A$4:$O$203,15,FALSE),0)) | Q16: =IF($A16="","",$N16*0.6+$O16*0.25+$P16*5*0.15)
B17: =IF($A17="","",IFERROR(VLOOKUP($A17,'02_Конкуренты'!$A$4:$B$203,2,FALSE),"не найдено")) | N17: =IF($A17="","",SUMPRODUCT($C17:$M17,$C$2:$M$2)/SUM($C$2:$M$2)) | O17: =IF($A17="","",IFERROR(VLOOKUP($A17,'04_Бизнес_модель'!$A$4:$P$203,16,FALSE),0)) | P17: =IF($A17="","",IFERROR(VLOOKUP($A17,'04_Бизнес_модель'!$A$4:$O$203,15,FALSE),0)) | Q17: =IF($A17="","",$N17*0.6+$O17*0.25+$P17*5*0.15)
B18: =IF($A18="","",IFERROR(VLOOKUP($A18,'02_Конкуренты'!$A$4:$B$203,2,FALSE),"не найдено")) | N18: =IF($A18="","",SUMPRODUCT($C18:$M18,$C$2:$M$2)/SUM($C$2:$M$2)) | O18: =IF($A18="","",IFERROR(VLOOKUP($A18,'04_Бизнес_модель'!$A$4:$P$203,16,FALSE),0)) | P18: =IF($A18="","",IFERROR(VLOOKUP($A18,'04_Бизнес_модель'!$A$4:$O$203,15,FALSE),0)) | Q18: =IF($A18="","",$N18*0.6+$O18*0.25+$P18*5*0.15)
B19: =IF($A19="","",IFERROR(VLOOKUP($A19,'02_Конкуренты'!$A$4:$B$203,2,FALSE),"не найдено")) | N19: =IF($A19="","",SUMPRODUCT($C19:$M19,$C$2:$M$2)/SUM($C$2:$M$2)) | O19: =IF($A19="","",IFERROR(VLOOKUP($A19,'04_Бизнес_модель'!$A$4:$P$203,16,FALSE),0)) | P19: =IF($A19="","",IFERROR(VLOOKUP($A19,'04_Бизнес_модель'!$A$4:$O$203,15,FALSE),0)) | Q19: =IF($A19="","",$N19*0.6+$O19*0.25+$P19*5*0.15)
B20: =IF($A20="","",IFERROR(VLOOKUP($A20,'02_Конкуренты'!$A$4:$B$203,2,FALSE),"не найдено")) | N20: =IF($A20="","",SUMPRODUCT($C20:$M20,$C$2:$M$2)/SUM($C$2:$M$2)) | O20: =IF($A20="","",IFERROR(VLOOKUP($A20,'04_Бизнес_модель'!$A$4:$P$203,16,FALSE),0)) | P20: =IF($A20="","",IFERROR(VLOOKUP($A20,'04_Бизнес_модель'!$A$4:$O$203,15,FALSE),0)) | Q20: =IF($A20="","",$N20*0.6+$O20*0.25+$P20*5*0.15)
B21: =IF($A21="","",IFERROR(VLOOKUP($A21,'02_Конкуренты'!$A$4:$B$203,2,FALSE),"не найдено")) | N21: =IF($A21="","",SUMPRODUCT($C21:$M21,$C$2:$M$2)/SUM($C$2:$M$2)) | O21: =IF($A21="","",IFERROR(VLOOKUP($A21,'04_Бизнес_модель'!$A$4:$P$203,16,FALSE),0)) | P21: =IF($A21="","",IFERROR(VLOOKUP($A21,'04_Бизнес_модель'!$A$4:$O$203,15,FALSE),0)) | Q21: =IF($A21="","",$N21*0.6+$O21*0.25+$P21*5*0.15)
B22: =IF($A22="","",IFERROR(VLOOKUP($A22,'02_Конкуренты'!$A$4:$B$203,2,FALSE),"не найдено")) | N22: =IF($A22="","",SUMPRODUCT($C22:$M22,$C$2:$M$2)/SUM($C$2:$M$2)) | O22: =IF($A22="","",IFERROR(VLOOKUP($A22,'04_Бизнес_модель'!$A$4:$P$203,16,FALSE),0)) | P22: =IF($A22="","",IFERROR(VLOOKUP($A22,'04_Бизнес_модель'!$A$4:$O$203,15,FALSE),0)) | Q22: =IF($A22="","",$N22*0.6+$O22*0.25+$P22*5*0.15)
B23: =IF($A23="","",IFERROR(VLOOKUP($A23,'02_Конкуренты'!$A$4:$B$203,2,FALSE),"не найдено")) | N23: =IF($A23="","",SUMPRODUCT($C23:$M23,$C$2:$M$2)/SUM($C$2:$M$2)) | O23: =IF($A23="","",IFERROR(VLOOKUP($A23,'04_Бизнес_модель'!$A$4:$P$203,16,FALSE),0)) | P23: =IF($A23="","",IFERROR(VLOOKUP($A23,'04_Бизнес_модель'!$A$4:$O$203,15,FALSE),0)) | Q23: =IF($A23="","",$N23*0.6+$O23*0.25+$P23*5*0.15)
... B203: =IF($A203="","",IFERROR(VLOOKUP($A203,'02_Конкуренты'!$A$4:$B$203,2,FALSE),"не найдено")) | N203: =IF($A203="","",SUMPRODUCT($C203:$M203,$C$2:$M$2)/SUM($C$2:$M$2)) | O203: =IF($A203="","",IFERROR(VLOOKUP($A203,'04_Бизнес_модель'!$A$4:$P$203,16,FALSE),0)) | P203: =IF($A203="","",IFERROR(VLOOKUP($A203,'04_Бизнес_модель'!$A$4:$O$203,15,FALSE),0)) | Q203: =IF($A203="","",$N203*0.6+$O203*0.25+$P203*5*0.15)

Sheet 10_Стандарт
A1: Определение рыночного стандарта бизнес-модели
A2: Повторяющиеся практики отделяются от настоящих конкурентных преимуществ. Порог стандарта можно корректировать в методике, базово используется 70%.
A3: Практика/элемент | B3: Блок бизнес-модели | C3: Описание признака | D3: Кол-во конкурентов с признаком | E3: Доля конкурентов | F3: Статус | G3: Управленческий вывод | H3: Подтверждающие URL/факты
A4: Бесплатный доступ к основной функции | B4: потоки доходов | C4: Free-тариф или open source | D4: 7 | E4: =IF($D4="","",IFERROR($D4/'12_Сводка'!$B$5,0)) -> 0.875 | F4: =IF($A4="","",IF($E4>=0.7,"рыночный стандарт",IF($E4>=0.4,"формирующийся стандарт",IF($E4>=0.2,"зона дифференциации","слабый сигнал")))) -> рыночный стандарт | G4: =IF($A4="","",IF($F4="рыночный стандарт","необходимо включить в минимально приемлемое предложение",IF($F4="формирующийся стандарт","проверить значимость для клиента и вероятность закрепления",IF($F4="зона дифференциации","может использоваться как поле позиционирования","не использовать без дополнительной проверки")))) -> необходимо включить в минимально приемлемое предложение | H4: PlantUML, Eraser Free, Mermaid, D2, Gleek Free, draw.io, (Lucidchart 🔲); Ramus — лицензия
