Workbook

Sheet Панель
A1: Панель оценки тренда, сезонности и циклов спроса
A3: Файл предназначен для анализа интереса аудитории на основе выгрузок из Google Trends и Яндекс Вордстат. Заполните лист «Ввод_данных», после чего показатели на этой панели обновятся автоматически
A5: Блок | B5: Показатель | C5: Значение | D5: Как использовать
A6: Данные | B6: Количество месяцев | C6: =Оценка_тренда!B4 | D6: проверка достаточности ряда
A7: Тренд | B7: Классификация тренда | C7: =Оценка_тренда!B10 | D7: основа вывода о росте или снижении интереса
A8: Тренд | B8: Изменение последних 12 мес. к первым 12 мес | C8: =Оценка_тренда!B8 | D8: оценка силы изменения
A9: Сезонность | B9: Сила сезонности | C9: =Сезонность!B22 | D9: нужна для планирования месяцев продвижения
A10: Сезонность | B10: Месяц максимума | C10: =Сезонность!B23 | D10: период вероятного повышения интереса
A11: Сезонность | B11: Месяц минимума | C11: =Сезонность!B24 | D11: период вероятного снижения интереса
A12: Циклы | B12: Текущая фаза | C12: =Деловые_циклы!B7 | D12: оценка текущего состояния спроса относительно нормы
A13: Циклы | B13: Текущий коэффициент | C13: =Деловые_циклы!B6 | D13: значение выше 1 означает спрос выше трендово-сезонного уровня
A16: Итоговая формулировка для отчета
A17: =Оценка_тренда!B11&" Сезонность: "&Сезонность!B22&"; максимум интереса — "&Сезонность!B23&", минимум — "&Сезонность!B24&". Текущая фаза спроса: "&Деловые_циклы!B7&"."

Sheet Ввод_данных
A1: Ввод данных из Google Trends и Яндекс Вордстат
A2: Заполните строки по месяцам. Google Trends вводится как индекс 0–100. Яндекс Вордстат вводится как абсолютное число запросов по выбранному семантическому кластеру. В демонстрационном примере приведены условные данные для бизнеса на основе компетенции «маркетинг»
A4: Период | B4: Кластер запросов | C4: Google Trends, 0–100 | D4: Яндекс Вордстат, запросов | E4: Регион / рынок | F4: Комментарий
A5: 45536 | B5: plantuml | D5: 191 | E5: Беларусь
A6: 45566 | B6: plantuml | D6: 434 | E6: Беларусь
A7: 45597 | B7: plantuml | D7: 385 | E7: Беларусь
A8: 45627 | B8: plantuml | D8: 352 | E8: Беларусь
A9: 45658 | B9: plantuml | D9: 217 | E9: Беларусь
A10: 45689 | B10: plantuml | D10: 368 | E10: Беларусь
A11: 45717 | B11: plantuml | D11: 467 | E11: Беларусь
A12: 45748 | B12: plantuml | D12: 449 | E12: Беларусь
A13: 45778 | B13: plantuml | D13: 605 | E13: Беларусь
A14: 45809 | B14: plantuml | D14: 493 | E14: Беларусь
A15: 45839 | B15: plantuml | D15: 231 | E15: Беларусь
A16: 45870 | B16: plantuml | D16: 176 | E16: Беларусь
... A28: 46235 | B28: plantuml | D28: 84 | E28: Беларусь

Sheet Расчет
A1: Расчет тренда, сезонности и циклических отклонений
A2: Расчет построен по мультипликативной логике: наблюдаемый интерес = тренд × сезонность × циклическое отклонение × случайные колебания. Для практической оценки используются скользящее среднее, сезонные индексы и коэффициент отклонения от трендово-сезонного уровня
A4: Период | B4: Месяц № | C4: Месяц | D4: Google Trends | E4: Вордстат | F4: Вордстат норм. 0–100 | G4: Сводный индекс | H4: Тренд: скользящее среднее 12 мес | I4: Y/T | J4: Сезонно очищенный индекс | K4: Циклический коэффициент | L4: Фаза цикла | M4: Комментарий | N4: Порядковый №
A5: =IF(Ввод_данных!A5="","",Ввод_данных!A5) | B5: =IF(A5="","",MONTH(A5)) | C5: =IF(A5="","",CHOOSE(MONTH(A5),"январь","февраль","март","апрель","май","июнь","июль","август","сентябрь","октябрь","ноябрь","декабрь")) | D5: =IF(Ввод_данных!C5="","",Ввод_данных!C5) | E5: =IF(Ввод_данных!D5="","",Ввод_данных!D5) | F5: =IF(E5="","",IF(MAX($E5 у.е.:$E6 у.е.4)=0,"",E5/MAX($E5 у.е.:$E6 у.е.4)*100)) | G5: =IF(COUNT(D5,F5)=0,"",IF(COUNT(D5,F5)=2,D5*Настройки!$B4 у.е.+F5*Настройки!$B5 у.е.,IF(D5<>"",D5,F5))) | H5: =IF(OR(G5="",COUNT($G5 у.е.:G5)<12),"","") | I5: =IF(OR(G5="",H5="",H5=0),"",G5/H5) | J5: =IF(OR(G5="",IFERROR(VLOOKUP(B5,Сезонность!$A4 у.е.:$D1 у.е.5,4,FALSE),0)=0),"",G5/IFERROR(VLOOKUP(B5,Сезонность!$A4 у.е.:$D1 у.е.5,4,FALSE),1)) | K5: =IF(OR(G5="",H5="",H5=0,IFERROR(VLOOKUP(B5,Сезонность!$A4 у.е.:$D1 у.е.5,4,FALSE),0)=0),"",G5/(H5*IFERROR(VLOOKUP(B5,Сезонность!$A4 у.е.:$D1 у.е.5,4,FALSE),1))) | L5: =IF(K5="","",IF(K5<Настройки!$B1 у.е.1,"ниже тренда",IF(K5>Настройки!$B1 у.е.2,"выше тренда","норма"))) | M5: =IF(L5="","",IF(L5="ниже тренда","возможное ослабление интереса",IF(L5="выше тренда","возможная фаза повышенного интереса","без выраженного отклонения"))) | N5: =IF(G5="","",COUNT($G5 у.е.:G5))
A6: =IF(Ввод_данных!A6="","",Ввод_данных!A6) | B6: =IF(A6="","",MONTH(A6)) | C6: =IF(A6="","",CHOOSE(MONTH(A6),"январь","февраль","март","апрель","май","июнь","июль","август","сентябрь","октябрь","ноябрь","декабрь")) | D6: =IF(Ввод_данных!C6="","",Ввод_данных!C6) | E6: =IF(Ввод_данных!D6="","",Ввод_данных!D6) | F6: =IF(E6="","",IF(MAX($E5 у.е.:$E6 у.е.4)=0,"",E6/MAX($E5 у.е.:$E6 у.е.4)*100)) | G6: =IF(COUNT(D6,F6)=0,"",IF(COUNT(D6,F6)=2,D6*Настройки!$B4 у.е.+F6*Настройки!$B5 у.е.,IF(D6<>"",D6,F6))) | H6: =IF(OR(G6="",COUNT($G5 у.е.:G6)<12),"","") | I6: =IF(OR(G6="",H6="",H6=0),"",G6/H6) | J6: =IF(OR(G6="",IFERROR(VLOOKUP(B6,Сезонность!$A4 у.е.:$D1 у.е.5,4,FALSE),0)=0),"",G6/IFERROR(VLOOKUP(B6,Сезонность!$A4 у.е.:$D1 у.е.5,4,FALSE),1)) | K6: =IF(OR(G6="",H6="",H6=0,IFERROR(VLOOKUP(B6,Сезонность!$A4 у.е.:$D1 у.е.5,4,FALSE),0)=0),"",G6/(H6*IFERROR(VLOOKUP(B6,Сезонность!$A4 у.е.:$D1 у.е.5,4,FALSE),1))) | L6: =IF(K6="","",IF(K6<Настройки!$B1 у.е.1,"ниже тренда",IF(K6>Настройки!$B1 у.е.2,"выше тренда","норма"))) | M6: =IF(L6="","",IF(L6="ниже тренда","возможное ослабление интереса",IF(L6="выше тренда","возможная фаза повышенного интереса","без выраженного отклонения"))) | N6: =IF(G6="","",COUNT($G5 у.е.:G6))
A7: =IF(Ввод_данных!A7="","",Ввод_данных!A7) | B7: =IF(A7="","",MONTH(A7)) | C7: =IF(A7="","",CHOOSE(MONTH(A7),"январь","февраль","март","апрель","май","июнь","июль","август","сентябрь","октябрь","ноябрь","декабрь")) | D7: =IF(Ввод_данных!C7="","",Ввод_данных!C7) | E7: =IF(Ввод_данных!D7="","",Ввод_данных!D7) | F7: =IF(E7="","",IF(MAX($E5 у.е.:$E6 у.е.4)=0,"",E7/MAX($E5 у.е.:$E6 у.е.4)*100)) | G7: =IF(COUNT(D7,F7)=0,"",IF(COUNT(D7,F7)=2,D7*Настройки!$B4 у.е.+F7*Настройки!$B5 у.е.,IF(D7<>"",D7,F7))) | H7: =IF(OR(G7="",COUNT($G5 у.е.:G7)<12),"","") | I7: =IF(OR(G7="",H7="",H7=0),"",G7/H7) | J7: =IF(OR(G7="",IFERROR(VLOOKUP(B7,Сезонность!$A4 у.е.:$D1 у.е.5,4,FALSE),0)=0),"",G7/IFERROR(VLOOKUP(B7,Сезонность!$A4 у.е.:$D1 у.е.5,4,FALSE),1)) | K7: =IF(OR(G7="",H7="",H7=0,IFERROR(VLOOKUP(B7,Сезонность!$A4 у.е.:$D1 у.е.5,4,FALSE),0)=0),"",G7/(H7*IFERROR(VLOOKUP(B7,Сезонность!$A4 у.е.:$D1 у.е.5,4,FALSE),1))) | L7: =IF(K7="","",IF(K7<Настройки!$B1 у.е.1,"ниже тренда",IF(K7>Настройки!$B1 у.е.2,"выше тренда","норма"))) | M7: =IF(L7="","",IF(L7="ниже тренда","возможное ослабление интереса",IF(L7="выше тренда","возможная фаза повышенного интереса","без выраженного отклонения"))) | N7: =IF(G7="","",COUNT($G5 у.е.:G7))
A8: =IF(Ввод_данных!A8="","",Ввод_данных!A8) | B8: =IF(A8="","",MONTH(A8)) | C8: =IF(A8="","",CHOOSE(MONTH(A8),"январь","февраль","март","апрель","май","июнь","июль","август","сентябрь","октябрь","ноябрь","декабрь")) | D8: =IF(Ввод_данных!C8="","",Ввод_данных!C8) | E8: =IF(Ввод_данных!D8="","",Ввод_данных!D8) | F8: =IF(E8="","",IF(MAX($E5 у.е.:$E6 у.е.4)=0,"",E8/MAX($E5 у.е.:$E6 у.е.4)*100)) | G8: =IF(COUNT(D8,F8)=0,"",IF(COUNT(D8,F8)=2,D8*Настройки!$B4 у.е.+F8*Настройки!$B5 у.е.,IF(D8<>"",D8,F8))) | H8: =IF(OR(G8="",COUNT($G5 у.е.:G8)<12),"","") | I8: =IF(OR(G8="",H8="",H8=0),"",G8/H8) | J8: =IF(OR(G8="",IFERROR(VLOOKUP(B8,Сезонность!$A4 у.е.:$D1 у.е.5,4,FALSE),0)=0),"",G8/IFERROR(VLOOKUP(B8,Сезонность!$A4 у.е.:$D1 у.е.5,4,FALSE),1)) | K8: =IF(OR(G8="",H8="",H8=0,IFERROR(VLOOKUP(B8,Сезонность!$A4 у.е.:$D1 у.е.5,4,FALSE),0)=0),"",G8/(H8*IFERROR(VLOOKUP(B8,Сезонность!$A4 у.е.:$D1 у.е.5,4,FALSE),1))) | L8: =IF(K8="","",IF(K8<Настройки!$B1 у.е.1,"ниже тренда",IF(K8>Настройки!$B1 у.е.2,"выше тренда","норма"))) | M8: =IF(L8="","",IF(L8="ниже тренда","возможное ослабление интереса",IF(L8="выше тренда","возможная фаза повышенного интереса","без выраженного отклонения"))) | N8: =IF(G8="","",COUNT($G5 у.е.:G8))
A9: =IF(Ввод_данных!A9="","",Ввод_данных!A9) | B9: =IF(A9="","",MONTH(A9)) | C9: =IF(A9="","",CHOOSE(MONTH(A9),"январь","февраль","март","апрель","май","июнь","июль","август","сентябрь","октябрь","ноябрь","декабрь")) | D9: =IF(Ввод_данных!C9="","",Ввод_данных!C9) | E9: =IF(Ввод_данных!D9="","",Ввод_данных!D9) | F9: =IF(E9="","",IF(MAX($E5 у.е.:$E6 у.е.4)=0,"",E9/MAX($E5 у.е.:$E6 у.е.4)*100)) | G9: =IF(COUNT(D9,F9)=0,"",IF(COUNT(D9,F9)=2,D9*Настройки!$B4 у.е.+F9*Настройки!$B5 у.е.,IF(D9<>"",D9,F9))) | H9: =IF(OR(G9="",COUNT($G5 у.е.:G9)<12),"","") | I9: =IF(OR(G9="",H9="",H9=0),"",G9/H9) | J9: =IF(OR(G9="",IFERROR(VLOOKUP(B9,Сезонность!$A4 у.е.:$D1 у.е.5,4,FALSE),0)=0),"",G9/IFERROR(VLOOKUP(B9,Сезонность!$A4 у.е.:$D1 у.е.5,4,FALSE),1)) | K9: =IF(OR(G9="",H9="",H9=0,IFERROR(VLOOKUP(B9,Сезонность!$A4 у.е.:$D1 у.е.5,4,FALSE),0)=0),"",G9/(H9*IFERROR(VLOOKUP(B9,Сезонность!$A4 у.е.:$D1 у.е.5,4,FALSE),1))) | L9: =IF(K9="","",IF(K9<Настройки!$B1 у.е.1,"ниже тренда",IF(K9>Настройки!$B1 у.е.2,"выше тренда","норма"))) | M9: =IF(L9="","",IF(L9="ниже тренда","возможное ослабление интереса",IF(L9="выше тренда","возможная фаза повышенного интереса","без выраженного отклонения"))) | N9: =IF(G9="","",COUNT($G5 у.е.:G9))
A10: =IF(Ввод_данных!A10="","",Ввод_данных!A10) | B10: =IF(A10="","",MONTH(A10)) | C10: =IF(A10="","",CHOOSE(MONTH(A10),"январь","февраль","март","апрель","май","июнь","июль","август","сентябрь","октябрь","ноябрь","декабрь")) | D10: =IF(Ввод_данных!C10="","",Ввод_данных!C10) | E10: =IF(Ввод_данных!D10="","",Ввод_данных!D10) | F10: =IF(E10="","",IF(MAX($E5 у.е.:$E6 у.е.4)=0,"",E10/MAX($E5 у.е.:$E6 у.е.4)*100)) | G10: =IF(COUNT(D10,F10)=0,"",IF(COUNT(D10,F10)=2,D10*Настройки!$B4 у.е.+F10*Настройки!$B5 у.е.,IF(D10<>"",D10,F10))) | H10: =IF(OR(G10="",COUNT($G5 у.е.:G10)<12),"","") | I10: =IF(OR(G10="",H10="",H10=0),"",G10/H10) | J10: =IF(OR(G10="",IFERROR(VLOOKUP(B10,Сезонность!$A4 у.е.:$D1 у.е.5,4,FALSE),0)=0),"",G10/IFERROR(VLOOKUP(B10,Сезонность!$A4 у.е.:$D1 у.е.5,4,FALSE),1)) | K10: =IF(OR(G10="",H10="",H10=0,IFERROR(VLOOKUP(B10,Сезонность!$A4 у.е.:$D1 у.е.5,4,FALSE),0)=0),"",G10/(H10*IFERROR(VLOOKUP(B10,Сезонность!$A4 у.е.:$D1 у.е.5,4,FALSE),1))) | L10: =IF(K10="","",IF(K10<Настройки!$B1 у.е.1,"ниже тренда",IF(K10>Настройки!$B1 у.е.2,"выше тренда","норма"))) | M10: =IF(L10="","",IF(L10="ниже тренда","возможное ослабление интереса",IF(L10="выше тренда","возможная фаза повышенного интереса","без выраженного отклонения"))) | N10: =IF(G10="","",COUNT($G5 у.е.:G10))
A11: =IF(Ввод_данных!A11="","",Ввод_данных!A11) | B11: =IF(A11="","",MONTH(A11)) | C11: =IF(A11="","",CHOOSE(MONTH(A11),"январь","февраль","март","апрель","май","июнь","июль","август","сентябрь","октябрь","ноябрь","декабрь")) | D11: =IF(Ввод_данных!C11="","",Ввод_данных!C11) | E11: =IF(Ввод_данных!D11="","",Ввод_данных!D11) | F11: =IF(E11="","",IF(MAX($E5 у.е.:$E6 у.е.4)=0,"",E11/MAX($E5 у.е.:$E6 у.е.4)*100)) | G11: =IF(COUNT(D11,F11)=0,"",IF(COUNT(D11,F11)=2,D11*Настройки!$B4 у.е.+F11*Настройки!$B5 у.е.,IF(D11<>"",D11,F11))) | H11: =IF(OR(G11="",COUNT($G5 у.е.:G11)<12),"","") | I11: =IF(OR(G11="",H11="",H11=0),"",G11/H11) | J11: =IF(OR(G11="",IFERROR(VLOOKUP(B11,Сезонность!$A4 у.е.:$D1 у.е.5,4,FALSE),0)=0),"",G11/IFERROR(VLOOKUP(B11,Сезонность!$A4 у.е.:$D1 у.е.5,4,FALSE),1)) | K11: =IF(OR(G11="",H11="",H11=0,IFERROR(VLOOKUP(B11,Сезонность!$A4 у.е.:$D1 у.е.5,4,FALSE),0)=0),"",G11/(H11*IFERROR(VLOOKUP(B11,Сезонность!$A4 у.е.:$D1 у.е.5,4,FALSE),1))) | L11: =IF(K11="","",IF(K11<Настройки!$B1 у.е.1,"ниже тренда",IF(K11>Настройки!$B1 у.е.2,"выше тренда","норма"))) | M11: =IF(L11="","",IF(L11="ниже тренда","возможное ослабление интереса",IF(L11="выше тренда","возможная фаза повышенного интереса","без выраженного отклонения"))) | N11: =IF(G11="","",COUNT($G5 у.е.:G11))
A12: =IF(Ввод_данных!A12="","",Ввод_данных!A12) | B12: =IF(A12="","",MONTH(A12)) | C12: =IF(A12="","",CHOOSE(MONTH(A12),"январь","февраль","март","апрель","май","июнь","июль","август","сентябрь","октябрь","ноябрь","декабрь")) | D12: =IF(Ввод_данных!C12="","",Ввод_данных!C12) | E12: =IF(Ввод_данных!D12="","",Ввод_данных!D12) | F12: =IF(E12="","",IF(MAX($E5 у.е.:$E6 у.е.4)=0,"",E12/MAX($E5 у.е.:$E6 у.е.4)*100)) | G12: =IF(COUNT(D12,F12)=0,"",IF(COUNT(D12,F12)=2,D12*Настройки!$B4 у.е.+F12*Настройки!$B5 у.е.,IF(D12<>"",D12,F12))) | H12: =IF(OR(G12="",COUNT($G5 у.е.:G12)<12),"","") | I12: =IF(OR(G12="",H12="",H12=0),"",G12/H12) | J12: =IF(OR(G12="",IFERROR(VLOOKUP(B12,Сезонность!$A4 у.е.:$D1 у.е.5,4,FALSE),0)=0),"",G12/IFERROR(VLOOKUP(B12,Сезонность!$A4 у.е.:$D1 у.е.5,4,FALSE),1)) | K12: =IF(OR(G12="",H12="",H12=0,IFERROR(VLOOKUP(B12,Сезонность!$A4 у.е.:$D1 у.е.5,4,FALSE),0)=0),"",G12/(H12*IFERROR(VLOOKUP(B12,Сезонность!$A4 у.е.:$D1 у.е.5,4,FALSE),1))) | L12: =IF(K12="","",IF(K12<Настройки!$B1 у.е.1,"ниже тренда",IF(K12>Настройки!$B1 у.е.2,"выше тренда","норма"))) | M12: =IF(L12="","",IF(L12="ниже тренда","возможное ослабление интереса",IF(L12="выше тренда","возможная фаза повышенного интереса","без выраженного отклонения"))) | N12: =IF(G12="","",COUNT($G5 у.е.:G12))
A13: =IF(Ввод_данных!A13="","",Ввод_данных!A13) | B13: =IF(A13="","",MONTH(A13)) | C13: =IF(A13="","",CHOOSE(MONTH(A13),"январь","февраль","март","апрель","май","июнь","июль","август","сентябрь","октябрь","ноябрь","декабрь")) | D13: =IF(Ввод_данных!C13="","",Ввод_данных!C13) | E13: =IF(Ввод_данных!D13="","",Ввод_данных!D13) | F13: =IF(E13="","",IF(MAX($E5 у.е.:$E6 у.е.4)=0,"",E13/MAX($E5 у.е.:$E6 у.е.4)*100)) | G13: =IF(COUNT(D13,F13)=0,"",IF(COUNT(D13,F13)=2,D13*Настройки!$B4 у.е.+F13*Настройки!$B5 у.е.,IF(D13<>"",D13,F13))) | H13: =IF(OR(G13="",COUNT($G5 у.е.:G13)<12),"","") | I13: =IF(OR(G13="",H13="",H13=0),"",G13/H13) | J13: =IF(OR(G13="",IFERROR(VLOOKUP(B13,Сезонность!$A4 у.е.:$D1 у.е.5,4,FALSE),0)=0),"",G13/IFERROR(VLOOKUP(B13,Сезонность!$A4 у.е.:$D1 у.е.5,4,FALSE),1)) | K13: =IF(OR(G13="",H13="",H13=0,IFERROR(VLOOKUP(B13,Сезонность!$A4 у.е.:$D1 у.е.5,4,FALSE),0)=0),"",G13/(H13*IFERROR(VLOOKUP(B13,Сезонность!$A4 у.е.:$D1 у.е.5,4,FALSE),1))) | L13: =IF(K13="","",IF(K13<Настройки!$B1 у.е.1,"ниже тренда",IF(K13>Настройки!$B1 у.е.2,"выше тренда","норма"))) | M13: =IF(L13="","",IF(L13="ниже тренда","возможное ослабление интереса",IF(L13="выше тренда","возможная фаза повышенного интереса","без выраженного отклонения"))) | N13: =IF(G13="","",COUNT($G5 у.е.:G13))
A14: =IF(Ввод_данных!A14="","",Ввод_данных!A14) | B14: =IF(A14="","",MONTH(A14)) | C14: =IF(A14="","",CHOOSE(MONTH(A14),"январь","февраль","март","апрель","май","июнь","июль","август","сентябрь","октябрь","ноябрь","декабрь")) | D14: =IF(Ввод_данных!C14="","",Ввод_данных!C14) | E14: =IF(Ввод_данных!D14="","",Ввод_данных!D14) | F14: =IF(E14="","",IF(MAX($E5 у.е.:$E6 у.е.4)=0,"",E14/MAX($E5 у.е.:$E6 у.е.4)*100)) | G14: =IF(COUNT(D14,F14)=0,"",IF(COUNT(D14,F14)=2,D14*Настройки!$B4 у.е.+F14*Настройки!$B5 у.е.,IF(D14<>"",D14,F14))) | H14: =IF(OR(G14="",COUNT($G5 у.е.:G14)<12),"","") | I14: =IF(OR(G14="",H14="",H14=0),"",G14/H14) | J14: =IF(OR(G14="",IFERROR(VLOOKUP(B14,Сезонность!$A4 у.е.:$D1 у.е.5,4,FALSE),0)=0),"",G14/IFERROR(VLOOKUP(B14,Сезонность!$A4 у.е.:$D1 у.е.5,4,FALSE),1)) | K14: =IF(OR(G14="",H14="",H14=0,IFERROR(VLOOKUP(B14,Сезонность!$A4 у.е.:$D1 у.е.5,4,FALSE),0)=0),"",G14/(H14*IFERROR(VLOOKUP(B14,Сезонность!$A4 у.е.:$D1 у.е.5,4,FALSE),1))) | L14: =IF(K14="","",IF(K14<Настройки!$B1 у.е.1,"ниже тренда",IF(K14>Настройки!$B1 у.е.2,"выше тренда","норма"))) | M14: =IF(L14="","",IF(L14="ниже тренда","возможное ослабление интереса",IF(L14="выше тренда","возможная фаза повышенного интереса","без выраженного отклонения"))) | N14: =IF(G14="","",COUNT($G5 у.е.:G14))
A15: =IF(Ввод_данных!A15="","",Ввод_данных!A15) | B15: =IF(A15="","",MONTH(A15)) | C15: =IF(A15="","",CHOOSE(MONTH(A15),"январь","февраль","март","апрель","май","июнь","июль","август","сентябрь","октябрь","ноябрь","декабрь")) | D15: =IF(Ввод_данных!C15="","",Ввод_данных!C15) | E15: =IF(Ввод_данных!D15="","",Ввод_данных!D15) | F15: =IF(E15="","",IF(MAX($E5 у.е.:$E6 у.е.4)=0,"",E15/MAX($E5 у.е.:$E6 у.е.4)*100)) | G15: =IF(COUNT(D15,F15)=0,"",IF(COUNT(D15,F15)=2,D15*Настройки!$B4 у.е.+F15*Настройки!$B5 у.е.,IF(D15<>"",D15,F15))) | H15: =IF(OR(G15="",COUNT($G5 у.е.:G15)<12),"","") | I15: =IF(OR(G15="",H15="",H15=0),"",G15/H15) | J15: =IF(OR(G15="",IFERROR(VLOOKUP(B15,Сезонность!$A4 у.е.:$D1 у.е.5,4,FALSE),0)=0),"",G15/IFERROR(VLOOKUP(B15,Сезонность!$A4 у.е.:$D1 у.е.5,4,FALSE),1)) | K15: =IF(OR(G15="",H15="",H15=0,IFERROR(VLOOKUP(B15,Сезонность!$A4 у.е.:$D1 у.е.5,4,FALSE),0)=0),"",G15/(H15*IFERROR(VLOOKUP(B15,Сезонность!$A4 у.е.:$D1 у.е.5,4,FALSE),1))) | L15: =IF(K15="","",IF(K15<Настройки!$B1 у.е.1,"ниже тренда",IF(K15>Настройки!$B1 у.е.2,"выше тренда","норма"))) | M15: =IF(L15="","",IF(L15="ниже тренда","возможное ослабление интереса",IF(L15="выше тренда","возможная фаза повышенного интереса","без выраженного отклонения"))) | N15: =IF(G15="","",COUNT($G5 у.е.:G15))
A16: =IF(Ввод_данных!A16="","",Ввод_данных!A16) | B16: =IF(A16="","",MONTH(A16)) | C16: =IF(A16="","",CHOOSE(MONTH(A16),"январь","февраль","март","апрель","май","июнь","июль","август","сентябрь","октябрь","ноябрь","декабрь")) | D16: =IF(Ввод_данных!C16="","",Ввод_данных!C16) | E16: =IF(Ввод_данных!D16="","",Ввод_данных!D16) | F16: =IF(E16="","",IF(MAX($E5 у.е.:$E6 у.е.4)=0,"",E16/MAX($E5 у.е.:$E6 у.е.4)*100)) | G16: =IF(COUNT(D16,F16)=0,"",IF(COUNT(D16,F16)=2,D16*Настройки!$B4 у.е.+F16*Настройки!$B5 у.е.,IF(D16<>"",D16,F16))) | H16: =IF(OR(G16="",COUNT($G5 у.е.:G16)<12),"",AVERAGE(G5:G16)) | I16: =IF(OR(G16="",H16="",H16=0),"",G16/H16) | J16: =IF(OR(G16="",IFERROR(VLOOKUP(B16,Сезонность!$A4 у.е.:$D1 у.е.5,4,FALSE),0)=0),"",G16/IFERROR(VLOOKUP(B16,Сезонность!$A4 у.е.:$D1 у.е.5,4,FALSE),1)) | K16: =IF(OR(G16="",H16="",H16=0,IFERROR(VLOOKUP(B16,Сезонность!$A4 у.е.:$D1 у.е.5,4,FALSE),0)=0),"",G16/(H16*IFERROR(VLOOKUP(B16,Сезонность!$A4 у.е.:$D1 у.е.5,4,FALSE),1))) | L16: =IF(K16="","",IF(K16<Настройки!$B1 у.е.1,"ниже тренда",IF(K16>Настройки!$B1 у.е.2,"выше тренда","норма"))) | M16: =IF(L16="","",IF(L16="ниже тренда","возможное ослабление интереса",IF(L16="выше тренда","возможная фаза повышенного интереса","без выраженного отклонения"))) | N16: =IF(G16="","",COUNT($G5 у.е.:G16))
A17: =IF(Ввод_данных!A17="","",Ввод_данных!A17) | B17: =IF(A17="","",MONTH(A17)) | C17: =IF(A17="","",CHOOSE(MONTH(A17),"январь","февраль","март","апрель","май","июнь","июль","август","сентябрь","октябрь","ноябрь","декабрь")) | D17: =IF(Ввод_данных!C17="","",Ввод_данных!C17) | E17: =IF(Ввод_данных!D17="","",Ввод_данных!D17) | F17: =IF(E17="","",IF(MAX($E5 у.е.:$E6 у.е.4)=0,"",E17/MAX($E5 у.е.:$E6 у.е.4)*100)) | G17: =IF(COUNT(D17,F17)=0,"",IF(COUNT(D17,F17)=2,D17*Настройки!$B4 у.е.+F17*Настройки!$B5 у.е.,IF(D17<>"",D17,F17))) | H17: =IF(OR(G17="",COUNT($G5 у.е.:G17)<12),"",AVERAGE(G6:G17)) | I17: =IF(OR(G17="",H17="",H17=0),"",G17/H17) | J17: =IF(OR(G17="",IFERROR(VLOOKUP(B17,Сезонность!$A4 у.е.:$D1 у.е.5,4,FALSE),0)=0),"",G17/IFERROR(VLOOKUP(B17,Сезонность!$A4 у.е.:$D1 у.е.5,4,FALSE),1)) | K17: =IF(OR(G17="",H17="",H17=0,IFERROR(VLOOKUP(B17,Сезонность!$A4 у.е.:$D1 у.е.5,4,FALSE),0)=0),"",G17/(H17*IFERROR(VLOOKUP(B17,Сезонность!$A4 у.е.:$D1 у.е.5,4,FALSE),1))) | L17: =IF(K17="","",IF(K17<Настройки!$B1 у.е.1,"ниже тренда",IF(K17>Настройки!$B1 у.е.2,"выше тренда","норма"))) | M17: =IF(L17="","",IF(L17="ниже тренда","возможное ослабление интереса",IF(L17="выше тренда","возможная фаза повышенного интереса","без выраженного отклонения"))) | N17: =IF(G17="","",COUNT($G5 у.е.:G17))
A18: =IF(Ввод_данных!A18="","",Ввод_данных!A18) | B18: =IF(A18="","",MONTH(A18)) | C18: =IF(A18="","",CHOOSE(MONTH(A18),"январь","февраль","март","апрель","май","июнь","июль","август","сентябрь","октябрь","ноябрь","декабрь")) | D18: =IF(Ввод_данных!C18="","",Ввод_данных!C18) | E18: =IF(Ввод_данных!D18="","",Ввод_данных!D18) | F18: =IF(E18="","",IF(MAX($E5 у.е.:$E6 у.е.4)=0,"",E18/MAX($E5 у.е.:$E6 у.е.4)*100)) | G18: =IF(COUNT(D18,F18)=0,"",IF(COUNT(D18,F18)=2,D18*Настройки!$B4 у.е.+F18*Настройки!$B5 у.е.,IF(D18<>"",D18,F18))) | H18: =IF(OR(G18="",COUNT($G5 у.е.:G18)<12),"",AVERAGE(G7:G18)) | I18: =IF(OR(G18="",H18="",H18=0),"",G18/H18) | J18: =IF(OR(G18="",IFERROR(VLOOKUP(B18,Сезонность!$A4 у.е.:$D1 у.е.5,4,FALSE),0)=0),"",G18/IFERROR(VLOOKUP(B18,Сезонность!$A4 у.е.:$D1 у.е.5,4,FALSE),1)) | K18: =IF(OR(G18="",H18="",H18=0,IFERROR(VLOOKUP(B18,Сезонность!$A4 у.е.:$D1 у.е.5,4,FALSE),0)=0),"",G18/(H18*IFERROR(VLOOKUP(B18,Сезонность!$A4 у.е.:$D1 у.е.5,4,FALSE),1))) | L18: =IF(K18="","",IF(K18<Настройки!$B1 у.е.1,"ниже тренда",IF(K18>Настройки!$B1 у.е.2,"выше тренда","норма"))) | M18: =IF(L18="","",IF(L18="ниже тренда","возможное ослабление интереса",IF(L18="выше тренда","возможная фаза повышенного интереса","без выраженного отклонения"))) | N18: =IF(G18="","",COUNT($G5 у.е.:G18))
A19: =IF(Ввод_данных!A19="","",Ввод_данных!A19) | B19: =IF(A19="","",MONTH(A19)) | C19: =IF(A19="","",CHOOSE(MONTH(A19),"январь","февраль","март","апрель","май","июнь","июль","август","сентябрь","октябрь","ноябрь","декабрь")) | D19: =IF(Ввод_данных!C19="","",Ввод_данных!C19) | E19: =IF(Ввод_данных!D19="","",Ввод_данных!D19) | F19: =IF(E19="","",IF(MAX($E5 у.е.:$E6 у.е.4)=0,"",E19/MAX($E5 у.е.:$E6 у.е.4)*100)) | G19: =IF(COUNT(D19,F19)=0,"",IF(COUNT(D19,F19)=2,D19*Настройки!$B4 у.е.+F19*Настройки!$B5 у.е.,IF(D19<>"",D19,F19))) | H19: =IF(OR(G19="",COUNT($G5 у.е.:G19)<12),"",AVERAGE(G8:G19)) | I19: =IF(OR(G19="",H19="",H19=0),"",G19/H19) | J19: =IF(OR(G19="",IFERROR(VLOOKUP(B19,Сезонность!$A4 у.е.:$D1 у.е.5,4,FALSE),0)=0),"",G19/IFERROR(VLOOKUP(B19,Сезонность!$A4 у.е.:$D1 у.е.5,4,FALSE),1)) | K19: =IF(OR(G19="",H19="",H19=0,IFERROR(VLOOKUP(B19,Сезонность!$A4 у.е.:$D1 у.е.5,4,FALSE),0)=0),"",G19/(H19*IFERROR(VLOOKUP(B19,Сезонность!$A4 у.е.:$D1 у.е.5,4,FALSE),1))) | L19: =IF(K19="","",IF(K19<Настройки!$B1 у.е.1,"ниже тренда",IF(K19>Настройки!$B1 у.е.2,"выше тренда","норма"))) | M19: =IF(L19="","",IF(L19="ниже тренда","возможное ослабление интереса",IF(L19="выше тренда","возможная фаза повышенного интереса","без выраженного отклонения"))) | N19: =IF(G19="","",COUNT($G5 у.е.:G19))
A20: =IF(Ввод_данных!A20="","",Ввод_данных!A20) | B20: =IF(A20="","",MONTH(A20)) | C20: =IF(A20="","",CHOOSE(MONTH(A20),"январь","февраль","март","апрель","май","июнь","июль","август","сентябрь","октябрь","ноябрь","декабрь")) | D20: =IF(Ввод_данных!C20="","",Ввод_данных!C20) | E20: =IF(Ввод_данных!D20="","",Ввод_данных!D20) | F20: =IF(E20="","",IF(MAX($E5 у.е.:$E6 у.е.4)=0,"",E20/MAX($E5 у.е.:$E6 у.е.4)*100)) | G20: =IF(COUNT(D20,F20)=0,"",IF(COUNT(D20,F20)=2,D20*Настройки!$B4 у.е.+F20*Настройки!$B5 у.е.,IF(D20<>"",D20,F20))) | H20: =IF(OR(G20="",COUNT($G5 у.е.:G20)<12),"",AVERAGE(G9:G20)) | I20: =IF(OR(G20="",H20="",H20=0),"",G20/H20) | J20: =IF(OR(G20="",IFERROR(VLOOKUP(B20,Сезонность!$A4 у.е.:$D1 у.е.5,4,FALSE),0)=0),"",G20/IFERROR(VLOOKUP(B20,Сезонность!$A4 у.е.:$D1 у.е.5,4,FALSE),1)) | K20: =IF(OR(G20="",H20="",H20=0,IFERROR(VLOOKUP(B20,Сезонность!$A4 у.е.:$D1 у.е.5,4,FALSE),0)=0),"",G20/(H20*IFERROR(VLOOKUP(B20,Сезонность!$A4 у.е.:$D1 у.е.5,4,FALSE),1))) | L20: =IF(K20="","",IF(K20<Настройки!$B1 у.е.1,"ниже тренда",IF(K20>Настройки!$B1 у.е.2,"выше тренда","норма"))) | M20: =IF(L20="","",IF(L20="ниже тренда","возможное ослабление интереса",IF(L20="выше тренда","возможная фаза повышенного интереса","без выраженного отклонения"))) | N20: =IF(G20="","",COUNT($G5 у.е.:G20))
A21: =IF(Ввод_данных!A21="","",Ввод_данных!A21) | B21: =IF(A21="","",MONTH(A21)) | C21: =IF(A21="","",CHOOSE(MONTH(A21),"январь","февраль","март","апрель","май","июнь","июль","август","сентябрь","октябрь","ноябрь","декабрь")) | D21: =IF(Ввод_данных!C21="","",Ввод_данных!C21) | E21: =IF(Ввод_данных!D21="","",Ввод_данных!D21) | F21: =IF(E21="","",IF(MAX($E5 у.е.:$E6 у.е.4)=0,"",E21/MAX($E5 у.е.:$E6 у.е.4)*100)) | G21: =IF(COUNT(D21,F21)=0,"",IF(COUNT(D21,F21)=2,D21*Настройки!$B4 у.е.+F21*Настройки!$B5 у.е.,IF(D21<>"",D21,F21))) | H21: =IF(OR(G21="",COUNT($G5 у.е.:G21)<12),"",AVERAGE(G10:G21)) | I21: =IF(OR(G21="",H21="",H21=0),"",G21/H21) | J21: =IF(OR(G21="",IFERROR(VLOOKUP(B21,Сезонность!$A4 у.е.:$D1 у.е.5,4,FALSE),0)=0),"",G21/IFERROR(VLOOKUP(B21,Сезонность!$A4 у.е.:$D1 у.е.5,4,FALSE),1)) | K21: =IF(OR(G21="",H21="",H21=0,IFERROR(VLOOKUP(B21,Сезонность!$A4 у.е.:$D1 у.е.5,4,FALSE),0)=0),"",G21/(H21*IFERROR(VLOOKUP(B21,Сезонность!$A4 у.е.:$D1 у.е.5,4,FALSE),1))) | L21: =IF(K21="","",IF(K21<Настройки!$B1 у.е.1,"ниже тренда",IF(K21>Настройки!$B1 у.е.2,"выше тренда","норма"))) | M21: =IF(L21="","",IF(L21="ниже тренда","возможное ослабление интереса",IF(L21="выше тренда","возможная фаза повышенного интереса","без выраженного отклонения"))) | N21: =IF(G21="","",COUNT($G5 у.е.:G21))
A22: =IF(Ввод_данных!A22="","",Ввод_данных!A22) | B22: =IF(A22="","",MONTH(A22)) | C22: =IF(A22="","",CHOOSE(MONTH(A22),"январь","февраль","март","апрель","май","июнь","июль","август","сентябрь","октябрь","ноябрь","декабрь")) | D22: =IF(Ввод_данных!C22="","",Ввод_данных!C22) | E22: =IF(Ввод_данных!D22="","",Ввод_данных!D22) | F22: =IF(E22="","",IF(MAX($E5 у.е.:$E6 у.е.4)=0,"",E22/MAX($E5 у.е.:$E6 у.е.4)*100)) | G22: =IF(COUNT(D22,F22)=0,"",IF(COUNT(D22,F22)=2,D22*Настройки!$B4 у.е.+F22*Настройки!$B5 у.е.,IF(D22<>"",D22,F22))) | H22: =IF(OR(G22="",COUNT($G5 у.е.:G22)<12),"",AVERAGE(G11:G22)) | I22: =IF(OR(G22="",H22="",H22=0),"",G22/H22) | J22: =IF(OR(G22="",IFERROR(VLOOKUP(B22,Сезонность!$A4 у.е.:$D1 у.е.5,4,FALSE),0)=0),"",G22/IFERROR(VLOOKUP(B22,Сезонность!$A4 у.е.:$D1 у.е.5,4,FALSE),1)) | K22: =IF(OR(G22="",H22="",H22=0,IFERROR(VLOOKUP(B22,Сезонность!$A4 у.е.:$D1 у.е.5,4,FALSE),0)=0),"",G22/(H22*IFERROR(VLOOKUP(B22,Сезонность!$A4 у.е.:$D1 у.е.5,4,FALSE),1))) | L22: =IF(K22="","",IF(K22<Настройки!$B1 у.е.1,"ниже тренда",IF(K22>Настройки!$B1 у.е.2,"выше тренда","норма"))) | M22: =IF(L22="","",IF(L22="ниже тренда","возможное ослабление интереса",IF(L22="выше тренда","возможная фаза повышенного интереса","без выраженного отклонения"))) | N22: =IF(G22="","",COUNT($G5 у.е.:G22))
A23: =IF(Ввод_данных!A23="","",Ввод_данных!A23) | B23: =IF(A23="","",MONTH(A23)) | C23: =IF(A23="","",CHOOSE(MONTH(A23),"январь","февраль","март","апрель","май","июнь","июль","август","сентябрь","октябрь","ноябрь","декабрь")) | D23: =IF(Ввод_данных!C23="","",Ввод_данных!C23) | E23: =IF(Ввод_данных!D23="","",Ввод_данных!D23) | F23: =IF(E23="","",IF(MAX($E5 у.е.:$E6 у.е.4)=0,"",E23/MAX($E5 у.е.:$E6 у.е.4)*100)) | G23: =IF(COUNT(D23,F23)=0,"",IF(COUNT(D23,F23)=2,D23*Настройки!$B4 у.е.+F23*Настройки!$B5 у.е.,IF(D23<>"",D23,F23))) | H23: =IF(OR(G23="",COUNT($G5 у.е.:G23)<12),"",AVERAGE(G12:G23)) | I23: =IF(OR(G23="",H23="",H23=0),"",G23/H23) | J23: =IF(OR(G23="",IFERROR(VLOOKUP(B23,Сезонность!$A4 у.е.:$D1 у.е.5,4,FALSE),0)=0),"",G23/IFERROR(VLOOKUP(B23,Сезонность!$A4 у.е.:$D1 у.е.5,4,FALSE),1)) | K23: =IF(OR(G23="",H23="",H23=0,IFERROR(VLOOKUP(B23,Сезонность!$A4 у.е.:$D1 у.е.5,4,FALSE),0)=0),"",G23/(H23*IFERROR(VLOOKUP(B23,Сезонность!$A4 у.е.:$D1 у.е.5,4,FALSE),1))) | L23: =IF(K23="","",IF(K23<Настройки!$B1 у.е.1,"ниже тренда",IF(K23>Настройки!$B1 у.е.2,"выше тренда","норма"))) | M23: =IF(L23="","",IF(L23="ниже тренда","возможное ослабление интереса",IF(L23="выше тренда","возможная фаза повышенного интереса","без выраженного отклонения"))) | N23: =IF(G23="","",COUNT($G5 у.е.:G23))
A24: =IF(Ввод_данных!A24="","",Ввод_данных!A24) | B24: =IF(A24="","",MONTH(A24)) | C24: =IF(A24="","",CHOOSE(MONTH(A24),"январь","февраль","март","апрель","май","июнь","июль","август","сентябрь","октябрь","ноябрь","декабрь")) | D24: =IF(Ввод_данных!C24="","",Ввод_данных!C24) | E24: =IF(Ввод_данных!D24="","",Ввод_данных!D24) | F24: =IF(E24="","",IF(MAX($E5 у.е.:$E6 у.е.4)=0,"",E24/MAX($E5 у.е.:$E6 у.е.4)*100)) | G24: =IF(COUNT(D24,F24)=0,"",IF(COUNT(D24,F24)=2,D24*Настройки!$B4 у.е.+F24*Настройки!$B5 у.е.,IF(D24<>"",D24,F24))) | H24: =IF(OR(G24="",COUNT($G5 у.е.:G24)<12),"",AVERAGE(G13:G24)) | I24: =IF(OR(G24="",H24="",H24=0),"",G24/H24) | J24: =IF(OR(G24="",IFERROR(VLOOKUP(B24,Сезонность!$A4 у.е.:$D1 у.е.5,4,FALSE),0)=0),"",G24/IFERROR(VLOOKUP(B24,Сезонность!$A4 у.е.:$D1 у.е.5,4,FALSE),1)) | K24: =IF(OR(G24="",H24="",H24=0,IFERROR(VLOOKUP(B24,Сезонность!$A4 у.е.:$D1 у.е.5,4,FALSE),0)=0),"",G24/(H24*IFERROR(VLOOKUP(B24,Сезонность!$A4 у.е.:$D1 у.е.5,4,FALSE),1))) | L24: =IF(K24="","",IF(K24<Настройки!$B1 у.е.1,"ниже тренда",IF(K24>Настройки!$B1 у.е.2,"выше тренда","норма"))) | M24: =IF(L24="","",IF(L24="ниже тренда","возможное ослабление интереса",IF(L24="выше тренда","возможная фаза повышенного интереса","без выраженного отклонения"))) | N24: =IF(G24="","",COUNT($G5 у.е.:G24))
A25: =IF(Ввод_данных!A25="","",Ввод_данных!A25) | B25: =IF(A25="","",MONTH(A25)) | C25: =IF(A25="","",CHOOSE(MONTH(A25),"январь","февраль","март","апрель","май","июнь","июль","август","сентябрь","октябрь","ноябрь","декабрь")) | D25: =IF(Ввод_данных!C25="","",Ввод_данных!C25) | E25: =IF(Ввод_данных!D25="","",Ввод_данных!D25) | F25: =IF(E25="","",IF(MAX($E5 у.е.:$E6 у.е.4)=0,"",E25/MAX($E5 у.е.:$E6 у.е.4)*100)) | G25: =IF(COUNT(D25,F25)=0,"",IF(COUNT(D25,F25)=2,D25*Настройки!$B4 у.е.+F25*Настройки!$B5 у.е.,IF(D25<>"",D25,F25))) | H25: =IF(OR(G25="",COUNT($G5 у.е.:G25)<12),"",AVERAGE(G14:G25)) | I25: =IF(OR(G25="",H25="",H25=0),"",G25/H25) | J25: =IF(OR(G25="",IFERROR(VLOOKUP(B25,Сезонность!$A4 у.е.:$D1 у.е.5,4,FALSE),0)=0),"",G25/IFERROR(VLOOKUP(B25,Сезонность!$A4 у.е.:$D1 у.е.5,4,FALSE),1)) | K25: =IF(OR(G25="",H25="",H25=0,IFERROR(VLOOKUP(B25,Сезонность!$A4 у.е.:$D1 у.е.5,4,FALSE),0)=0),"",G25/(H25*IFERROR(VLOOKUP(B25,Сезонность!$A4 у.е.:$D1 у.е.5,4,FALSE),1))) | L25: =IF(K25="","",IF(K25<Настройки!$B1 у.е.1,"ниже тренда",IF(K25>Настройки!$B1 у.е.2,"выше тренда","норма"))) | M25: =IF(L25="","",IF(L25="ниже тренда","возможное ослабление интереса",IF(L25="выше тренда","возможная фаза повышенного интереса","без выраженного отклонения"))) | N25: =IF(G25="","",COUNT($G5 у.е.:G25))
A26: =IF(Ввод_данных!A26="","",Ввод_данных!A26) | B26: =IF(A26="","",MONTH(A26)) | C26: =IF(A26="","",CHOOSE(MONTH(A26),"январь","февраль","март","апрель","май","июнь","июль","август","сентябрь","октябрь","ноябрь","декабрь")) | D26: =IF(Ввод_данных!C26="","",Ввод_данных!C26) | E26: =IF(Ввод_данных!D26="","",Ввод_данных!D26) | F26: =IF(E26="","",IF(MAX($E5 у.е.:$E6 у.е.4)=0,"",E26/MAX($E5 у.е.:$E6 у.е.4)*100)) | G26: =IF(COUNT(D26,F26)=0,"",IF(COUNT(D26,F26)=2,D26*Настройки!$B4 у.е.+F26*Настройки!$B5 у.е.,IF(D26<>"",D26,F26))) | H26: =IF(OR(G26="",COUNT($G5 у.е.:G26)<12),"",AVERAGE(G15:G26)) | I26: =IF(OR(G26="",H26="",H26=0),"",G26/H26) | J26: =IF(OR(G26="",IFERROR(VLOOKUP(B26,Сезонность!$A4 у.е.:$D1 у.е.5,4,FALSE),0)=0),"",G26/IFERROR(VLOOKUP(B26,Сезонность!$A4 у.е.:$D1 у.е.5,4,FALSE),1)) | K26: =IF(OR(G26="",H26="",H26=0,IFERROR(VLOOKUP(B26,Сезонность!$A4 у.е.:$D1 у.е.5,4,FALSE),0)=0),"",G26/(H26*IFERROR(VLOOKUP(B26,Сезонность!$A4 у.е.:$D1 у.е.5,4,FALSE),1))) | L26: =IF(K26="","",IF(K26<Настройки!$B1 у.е.1,"ниже тренда",IF(K26>Настройки!$B1 у.е.2,"выше тренда","норма"))) | M26: =IF(L26="","",IF(L26="ниже тренда","возможное ослабление интереса",IF(L26="выше тренда","возможная фаза повышенного интереса","без выраженного отклонения"))) | N26: =IF(G26="","",COUNT($G5 у.е.:G26))
A27: =IF(Ввод_данных!A27="","",Ввод_данных!A27) | B27: =IF(A27="","",MONTH(A27)) | C27: =IF(A27="","",CHOOSE(MONTH(A27),"январь","февраль","март","апрель","май","июнь","июль","август","сентябрь","октябрь","ноябрь","декабрь")) | D27: =IF(Ввод_данных!C27="","",Ввод_данных!C27) | E27: =IF(Ввод_данных!D27="","",Ввод_данных!D27) | F27: =IF(E27="","",IF(MAX($E5 у.е.:$E6 у.е.4)=0,"",E27/MAX($E5 у.е.:$E6 у.е.4)*100)) | G27: =IF(COUNT(D27,F27)=0,"",IF(COUNT(D27,F27)=2,D27*Настройки!$B4 у.е.+F27*Настройки!$B5 у.е.,IF(D27<>"",D27,F27))) | H27: =IF(OR(G27="",COUNT($G5 у.е.:G27)<12),"",AVERAGE(G16:G27)) | I27: =IF(OR(G27="",H27="",H27=0),"",G27/H27) | J27: =IF(OR(G27="",IFERROR(VLOOKUP(B27,Сезонность!$A4 у.е.:$D1 у.е.5,4,FALSE),0)=0),"",G27/IFERROR(VLOOKUP(B27,Сезонность!$A4 у.е.:$D1 у.е.5,4,FALSE),1)) | K27: =IF(OR(G27="",H27="",H27=0,IFERROR(VLOOKUP(B27,Сезонность!$A4 у.е.:$D1 у.е.5,4,FALSE),0)=0),"",G27/(H27*IFERROR(VLOOKUP(B27,Сезонность!$A4 у.е.:$D1 у.е.5,4,FALSE),1))) | L27: =IF(K27="","",IF(K27<Настройки!$B1 у.е.1,"ниже тренда",IF(K27>Настройки!$B1 у.е.2,"выше тренда","норма"))) | M27: =IF(L27="","",IF(L27="ниже тренда","возможное ослабление интереса",IF(L27="выше тренда","возможная фаза повышенного интереса","без выраженного отклонения"))) | N27: =IF(G27="","",COUNT($G5 у.е.:G27))
A28: =IF(Ввод_данных!A28="","",Ввод_данных!A28) | B28: =IF(A28="","",MONTH(A28)) | C28: =IF(A28="","",CHOOSE(MONTH(A28),"январь","февраль","март","апрель","май","июнь","июль","август","сентябрь","октябрь","ноябрь","декабрь")) | D28: =IF(Ввод_данных!C28="","",Ввод_данных!C28) | E28: =IF(Ввод_данных!D28="","",Ввод_данных!D28) | F28: =IF(E28="","",IF(MAX($E5 у.е.:$E6 у.е.4)=0,"",E28/MAX($E5 у.е.:$E6 у.е.4)*100)) | G28: =IF(COUNT(D28,F28)=0,"",IF(COUNT(D28,F28)=2,D28*Настройки!$B4 у.е.+F28*Настройки!$B5 у.е.,IF(D28<>"",D28,F28))) | H28: =IF(OR(G28="",COUNT($G5 у.е.:G28)<12),"",AVERAGE(G17:G28)) | I28: =IF(OR(G28="",H28="",H28=0),"",G28/H28) | J28: =IF(OR(G28="",IFERROR(VLOOKUP(B28,Сезонность!$A4 у.е.:$D1 у.е.5,4,FALSE),0)=0),"",G28/IFERROR(VLOOKUP(B28,Сезонность!$A4 у.е.:$D1 у.е.5,4,FALSE),1)) | K28: =IF(OR(G28="",H28="",H28=0,IFERROR(VLOOKUP(B28,Сезонность!$A4 у.е.:$D1 у.е.5,4,FALSE),0)=0),"",G28/(H28*IFERROR(VLOOKUP(B28,Сезонность!$A4 у.е.:$D1 у.е.5,4,FALSE),1))) | L28: =IF(K28="","",IF(K28<Настройки!$B1 у.е.1,"ниже тренда",IF(K28>Настройки!$B1 у.е.2,"выше тренда","норма"))) | M28: =IF(L28="","",IF(L28="ниже тренда","возможное ослабление интереса",IF(L28="выше тренда","возможная фаза повышенного интереса","без выраженного отклонения"))) | N28: =IF(G28="","",COUNT($G5 у.е.:G28))
A29: =IF(Ввод_данных!A29="","",Ввод_данных!A29) | B29: =IF(A29="","",MONTH(A29)) | C29: =IF(A29="","",CHOOSE(MONTH(A29),"январь","февраль","март","апрель","май","июнь","июль","август","сентябрь","октябрь","ноябрь","декабрь")) | D29: =IF(Ввод_данных!C29="","",Ввод_данных!C29) | E29: =IF(Ввод_данных!D29="","",Ввод_данных!D29) | F29: =IF(E29="","",IF(MAX($E5 у.е.:$E6 у.е.4)=0,"",E29/MAX($E5 у.е.:$E6 у.е.4)*100)) | G29: =IF(COUNT(D29,F29)=0,"",IF(COUNT(D29,F29)=2,D29*Настройки!$B4 у.е.+F29*Настройки!$B5 у.е.,IF(D29<>"",D29,F29))) | H29: =IF(OR(G29="",COUNT($G5 у.е.:G29)<12),"",AVERAGE(G18:G29)) | I29: =IF(OR(G29="",H29="",H29=0),"",G29/H29) | J29: =IF(OR(G29="",IFERROR(VLOOKUP(B29,Сезонность!$A4 у.е.:$D1 у.е.5,4,FALSE),0)=0),"",G29/IFERROR(VLOOKUP(B29,Сезонность!$A4 у.е.:$D1 у.е.5,4,FALSE),1)) | K29: =IF(OR(G29="",H29="",H29=0,IFERROR(VLOOKUP(B29,Сезонность!$A4 у.е.:$D1 у.е.5,4,FALSE),0)=0),"",G29/(H29*IFERROR(VLOOKUP(B29,Сезонность!$A4 у.е.:$D1 у.е.5,4,FALSE),1))) | L29: =IF(K29="","",IF(K29<Настройки!$B1 у.е.1,"ниже тренда",IF(K29>Настройки!$B1 у.е.2,"выше тренда","норма"))) | M29: =IF(L29="","",IF(L29="ниже тренда","возможное ослабление интереса",IF(L29="выше тренда","возможная фаза повышенного интереса","без выраженного отклонения"))) | N29: =IF(G29="","",COUNT($G5 у.е.:G29))
A30: =IF(Ввод_данных!A30="","",Ввод_данных!A30) | B30: =IF(A30="","",MONTH(A30)) | C30: =IF(A30="","",CHOOSE(MONTH(A30),"январь","февраль","март","апрель","май","июнь","июль","август","сентябрь","октябрь","ноябрь","декабрь")) | D30: =IF(Ввод_данных!C30="","",Ввод_данных!C30) | E30: =IF(Ввод_данных!D30="","",Ввод_данных!D30) | F30: =IF(E30="","",IF(MAX($E5 у.е.:$E6 у.е.4)=0,"",E30/MAX($E5 у.е.:$E6 у.е.4)*100)) | G30: =IF(COUNT(D30,F30)=0,"",IF(COUNT(D30,F30)=2,D30*Настройки!$B4 у.е.+F30*Настройки!$B5 у.е.,IF(D30<>"",D30,F30))) | H30: =IF(OR(G30="",COUNT($G5 у.е.:G30)<12),"",AVERAGE(G19:G30)) | I30: =IF(OR(G30="",H30="",H30=0),"",G30/H30) | J30: =IF(OR(G30="",IFERROR(VLOOKUP(B30,Сезонность!$A4 у.е.:$D1 у.е.5,4,FALSE),0)=0),"",G30/IFERROR(VLOOKUP(B30,Сезонность!$A4 у.е.:$D1 у.е.5,4,FALSE),1)) | K30: =IF(OR(G30="",H30="",H30=0,IFERROR(VLOOKUP(B30,Сезонность!$A4 у.е.:$D1 у.е.5,4,FALSE),0)=0),"",G30/(H30*IFERROR(VLOOKUP(B30,Сезонность!$A4 у.е.:$D1 у.е.5,4,FALSE),1))) | L30: =IF(K30="","",IF(K30<Настройки!$B1 у.е.1,"ниже тренда",IF(K30>Настройки!$B1 у.е.2,"выше тренда","норма"))) | M30: =IF(L30="","",IF(L30="ниже тренда","возможное ослабление интереса",IF(L30="выше тренда","возможная фаза повышенного интереса","без выраженного отклонения"))) | N30: =IF(G30="","",COUNT($G5 у.е.:G30))
A31: =IF(Ввод_данных!A31="","",Ввод_данных!A31) | B31: =IF(A31="","",MONTH(A31)) | C31: =IF(A31="","",CHOOSE(MONTH(A31),"январь","февраль","март","апрель","май","июнь","июль","август","сентябрь","октябрь","ноябрь","декабрь")) | D31: =IF(Ввод_данных!C31="","",Ввод_данных!C31) | E31: =IF(Ввод_данных!D31="","",Ввод_данных!D31) | F31: =IF(E31="","",IF(MAX($E5 у.е.:$E6 у.е.4)=0,"",E31/MAX($E5 у.е.:$E6 у.е.4)*100)) | G31: =IF(COUNT(D31,F31)=0,"",IF(COUNT(D31,F31)=2,D31*Настройки!$B4 у.е.+F31*Настройки!$B5 у.е.,IF(D31<>"",D31,F31))) | H31: =IF(OR(G31="",COUNT($G5 у.е.:G31)<12),"",AVERAGE(G20:G31)) | I31: =IF(OR(G31="",H31="",H31=0),"",G31/H31) | J31: =IF(OR(G31="",IFERROR(VLOOKUP(B31,Сезонность!$A4 у.е.:$D1 у.е.5,4,FALSE),0)=0),"",G31/IFERROR(VLOOKUP(B31,Сезонность!$A4 у.е.:$D1 у.е.5,4,FALSE),1)) | K31: =IF(OR(G31="",H31="",H31=0,IFERROR(VLOOKUP(B31,Сезонность!$A4 у.е.:$D1 у.е.5,4,FALSE),0)=0),"",G31/(H31*IFERROR(VLOOKUP(B31,Сезонность!$A4 у.е.:$D1 у.е.5,4,FALSE),1))) | L31: =IF(K31="","",IF(K31<Настройки!$B1 у.е.1,"ниже тренда",IF(K31>Настройки!$B1 у.е.2,"выше тренда","норма"))) | M31: =IF(L31="","",IF(L31="ниже тренда","возможное ослабление интереса",IF(L31="выше тренда","возможная фаза повышенного интереса","без выраженного отклонения"))) | N31: =IF(G31="","",COUNT($G5 у.е.:G31))
A32: =IF(Ввод_данных!A32="","",Ввод_данных!A32) | B32: =IF(A32="","",MONTH(A32)) | C32: =IF(A32="","",CHOOSE(MONTH(A32),"январь","февраль","март","апрель","май","июнь","июль","август","сентябрь","октябрь","ноябрь","декабрь")) | D32: =IF(Ввод_данных!C32="","",Ввод_данных!C32) | E32: =IF(Ввод_данных!D32="","",Ввод_данных!D32) | F32: =IF(E32="","",IF(MAX($E5 у.е.:$E6 у.е.4)=0,"",E32/MAX($E5 у.е.:$E6 у.е.4)*100)) | G32: =IF(COUNT(D32,F32)=0,"",IF(COUNT(D32,F32)=2,D32*Настройки!$B4 у.е.+F32*Настройки!$B5 у.е.,IF(D32<>"",D32,F32))) | H32: =IF(OR(G32="",COUNT($G5 у.е.:G32)<12),"",AVERAGE(G21:G32)) | I32: =IF(OR(G32="",H32="",H32=0),"",G32/H32) | J32: =IF(OR(G32="",IFERROR(VLOOKUP(B32,Сезонность!$A4 у.е.:$D1 у.е.5,4,FALSE),0)=0),"",G32/IFERROR(VLOOKUP(B32,Сезонность!$A4 у.е.:$D1 у.е.5,4,FALSE),1)) | K32: =IF(OR(G32="",H32="",H32=0,IFERROR(VLOOKUP(B32,Сезонность!$A4 у.е.:$D1 у.е.5,4,FALSE),0)=0),"",G32/(H32*IFERROR(VLOOKUP(B32,Сезонность!$A4 у.е.:$D1 у.е.5,4,FALSE),1))) | L32: =IF(K32="","",IF(K32<Настройки!$B1 у.е.1,"ниже тренда",IF(K32>Настройки!$B1 у.е.2,"выше тренда","норма"))) | M32: =IF(L32="","",IF(L32="ниже тренда","возможное ослабление интереса",IF(L32="выше тренда","возможная фаза повышенного интереса","без выраженного отклонения"))) | N32: =IF(G32="","",COUNT($G5 у.е.:G32))
A33: =IF(Ввод_данных!A33="","",Ввод_данных!A33) | B33: =IF(A33="","",MONTH(A33)) | C33: =IF(A33="","",CHOOSE(MONTH(A33),"январь","февраль","март","апрель","май","июнь","июль","август","сентябрь","октябрь","ноябрь","декабрь")) | D33: =IF(Ввод_данных!C33="","",Ввод_данных!C33) | E33: =IF(Ввод_данных!D33="","",Ввод_данных!D33) | F33: =IF(E33="","",IF(MAX($E5 у.е.:$E6 у.е.4)=0,"",E33/MAX($E5 у.е.:$E6 у.е.4)*100)) | G33: =IF(COUNT(D33,F33)=0,"",IF(COUNT(D33,F33)=2,D33*Настройки!$B4 у.е.+F33*Настройки!$B5 у.е.,IF(D33<>"",D33,F33))) | H33: =IF(OR(G33="",COUNT($G5 у.е.:G33)<12),"",AVERAGE(G22:G33)) | I33: =IF(OR(G33="",H33="",H33=0),"",G33/H33) | J33: =IF(OR(G33="",IFERROR(VLOOKUP(B33,Сезонность!$A4 у.е.:$D1 у.е.5,4,FALSE),0)=0),"",G33/IFERROR(VLOOKUP(B33,Сезонность!$A4 у.е.:$D1 у.е.5,4,FALSE),1)) | K33: =IF(OR(G33="",H33="",H33=0,IFERROR(VLOOKUP(B33,Сезонность!$A4 у.е.:$D1 у.е.5,4,FALSE),0)=0),"",G33/(H33*IFERROR(VLOOKUP(B33,Сезонность!$A4 у.е.:$D1 у.е.5,4,FALSE),1))) | L33: =IF(K33="","",IF(K33<Настройки!$B1 у.е.1,"ниже тренда",IF(K33>Настройки!$B1 у.е.2,"выше тренда","норма"))) | M33: =IF(L33="","",IF(L33="ниже тренда","возможное ослабление интереса",IF(L33="выше тренда","возможная фаза повышенного интереса","без выраженного отклонения"))) | N33: =IF(G33="","",COUNT($G5 у.е.:G33))
A34: =IF(Ввод_данных!A34="","",Ввод_данных!A34) | B34: =IF(A34="","",MONTH(A34)) | C34: =IF(A34="","",CHOOSE(MONTH(A34),"январь","февраль","март","апрель","май","июнь","июль","август","сентябрь","октябрь","ноябрь","декабрь")) | D34: =IF(Ввод_данных!C34="","",Ввод_данных!C34) | E34: =IF(Ввод_данных!D34="","",Ввод_данных!D34) | F34: =IF(E34="","",IF(MAX($E5 у.е.:$E6 у.е.4)=0,"",E34/MAX($E5 у.е.:$E6 у.е.4)*100)) | G34: =IF(COUNT(D34,F34)=0,"",IF(COUNT(D34,F34)=2,D34*Настройки!$B4 у.е.+F34*Настройки!$B5 у.е.,IF(D34<>"",D34,F34))) | H34: =IF(OR(G34="",COUNT($G5 у.е.:G34)<12),"",AVERAGE(G23:G34)) | I34: =IF(OR(G34="",H34="",H34=0),"",G34/H34) | J34: =IF(OR(G34="",IFERROR(VLOOKUP(B34,Сезонность!$A4 у.е.:$D1 у.е.5,4,FALSE),0)=0),"",G34/IFERROR(VLOOKUP(B34,Сезонность!$A4 у.е.:$D1 у.е.5,4,FALSE),1)) | K34: =IF(OR(G34="",H34="",H34=0,IFERROR(VLOOKUP(B34,Сезонность!$A4 у.е.:$D1 у.е.5,4,FALSE),0)=0),"",G34/(H34*IFERROR(VLOOKUP(B34,Сезонность!$A4 у.е.:$D1 у.е.5,4,FALSE),1))) | L34: =IF(K34="","",IF(K34<Настройки!$B1 у.е.1,"ниже тренда",IF(K34>Настройки!$B1 у.е.2,"выше тренда","норма"))) | M34: =IF(L34="","",IF(L34="ниже тренда","возможное ослабление интереса",IF(L34="выше тренда","возможная фаза повышенного интереса","без выраженного отклонения"))) | N34: =IF(G34="","",COUNT($G5 у.е.:G34))
A35: =IF(Ввод_данных!A35="","",Ввод_данных!A35) | B35: =IF(A35="","",MONTH(A35)) | C35: =IF(A35="","",CHOOSE(MONTH(A35),"январь","февраль","март","апрель","май","июнь","июль","август","сентябрь","октябрь","ноябрь","декабрь")) | D35: =IF(Ввод_данных!C35="","",Ввод_данных!C35) | E35: =IF(Ввод_данных!D35="","",Ввод_данных!D35) | F35: =IF(E35="","",IF(MAX($E5 у.е.:$E6 у.е.4)=0,"",E35/MAX($E5 у.е.:$E6 у.е.4)*100)) | G35: =IF(COUNT(D35,F35)=0,"",IF(COUNT(D35,F35)=2,D35*Настройки!$B4 у.е.+F35*Настройки!$B5 у.е.,IF(D35<>"",D35,F35))) | H35: =IF(OR(G35="",COUNT($G5 у.е.:G35)<12),"",AVERAGE(G24:G35)) | I35: =IF(OR(G35="",H35="",H35=0),"",G35/H35) | J35: =IF(OR(G35="",IFERROR(VLOOKUP(B35,Сезонность!$A4 у.е.:$D1 у.е.5,4,FALSE),0)=0),"",G35/IFERROR(VLOOKUP(B35,Сезонность!$A4 у.е.:$D1 у.е.5,4,FALSE),1)) | K35: =IF(OR(G35="",H35="",H35=0,IFERROR(VLOOKUP(B35,Сезонность!$A4 у.е.:$D1 у.е.5,4,FALSE),0)=0),"",G35/(H35*IFERROR(VLOOKUP(B35,Сезонность!$A4 у.е.:$D1 у.е.5,4,FALSE),1))) | L35: =IF(K35="","",IF(K35<Настройки!$B1 у.е.1,"ниже тренда",IF(K35>Настройки!$B1 у.е.2,"выше тренда","норма"))) | M35: =IF(L35="","",IF(L35="ниже тренда","возможное ослабление интереса",IF(L35="выше тренда","возможная фаза повышенного интереса","без выраженного отклонения"))) | N35: =IF(G35="","",COUNT($G5 у.е.:G35))
A36: =IF(Ввод_данных!A36="","",Ввод_данных!A36) | B36: =IF(A36="","",MONTH(A36)) | C36: =IF(A36="","",CHOOSE(MONTH(A36),"январь","февраль","март","апрель","май","июнь","июль","август","сентябрь","октябрь","ноябрь","декабрь")) | D36: =IF(Ввод_данных!C36="","",Ввод_данных!C36) | E36: =IF(Ввод_данных!D36="","",Ввод_данных!D36) | F36: =IF(E36="","",IF(MAX($E5 у.е.:$E6 у.е.4)=0,"",E36/MAX($E5 у.е.:$E6 у.е.4)*100)) | G36: =IF(COUNT(D36,F36)=0,"",IF(COUNT(D36,F36)=2,D36*Настройки!$B4 у.е.+F36*Настройки!$B5 у.е.,IF(D36<>"",D36,F36))) | H36: =IF(OR(G36="",COUNT($G5 у.е.:G36)<12),"",AVERAGE(G25:G36)) | I36: =IF(OR(G36="",H36="",H36=0),"",G36/H36) | J36: =IF(OR(G36="",IFERROR(VLOOKUP(B36,Сезонность!$A4 у.е.:$D1 у.е.5,4,FALSE),0)=0),"",G36/IFERROR(VLOOKUP(B36,Сезонность!$A4 у.е.:$D1 у.е.5,4,FALSE),1)) | K36: =IF(OR(G36="",H36="",H36=0,IFERROR(VLOOKUP(B36,Сезонность!$A4 у.е.:$D1 у.е.5,4,FALSE),0)=0),"",G36/(H36*IFERROR(VLOOKUP(B36,Сезонность!$A4 у.е.:$D1 у.е.5,4,FALSE),1))) | L36: =IF(K36="","",IF(K36<Настройки!$B1 у.е.1,"ниже тренда",IF(K36>Настройки!$B1 у.е.2,"выше тренда","норма"))) | M36: =IF(L36="","",IF(L36="ниже тренда","возможное ослабление интереса",IF(L36="выше тренда","возможная фаза повышенного интереса","без выраженного отклонения"))) | N36: =IF(G36="","",COUNT($G5 у.е.:G36))
A37: =IF(Ввод_данных!A37="","",Ввод_данных!A37) | B37: =IF(A37="","",MONTH(A37)) | C37: =IF(A37="","",CHOOSE(MONTH(A37),"январь","февраль","март","апрель","май","июнь","июль","август","сентябрь","октябрь","ноябрь","декабрь")) | D37: =IF(Ввод_данных!C37="","",Ввод_данных!C37) | E37: =IF(Ввод_данных!D37="","",Ввод_данных!D37) | F37: =IF(E37="","",IF(MAX($E5 у.е.:$E6 у.е.4)=0,"",E37/MAX($E5 у.е.:$E6 у.е.4)*100)) | G37: =IF(COUNT(D37,F37)=0,"",IF(COUNT(D37,F37)=2,D37*Настройки!$B4 у.е.+F37*Настройки!$B5 у.е.,IF(D37<>"",D37,F37))) | H37: =IF(OR(G37="",COUNT($G5 у.е.:G37)<12),"",AVERAGE(G26:G37)) | I37: =IF(OR(G37="",H37="",H37=0),"",G37/H37) | J37: =IF(OR(G37="",IFERROR(VLOOKUP(B37,Сезонность!$A4 у.е.:$D1 у.е.5,4,FALSE),0)=0),"",G37/IFERROR(VLOOKUP(B37,Сезонность!$A4 у.е.:$D1 у.е.5,4,FALSE),1)) | K37: =IF(OR(G37="",H37="",H37=0,IFERROR(VLOOKUP(B37,Сезонность!$A4 у.е.:$D1 у.е.5,4,FALSE),0)=0),"",G37/(H37*IFERROR(VLOOKUP(B37,Сезонность!$A4 у.е.:$D1 у.е.5,4,FALSE),1))) | L37: =IF(K37="","",IF(K37<Настройки!$B1 у.е.1,"ниже тренда",IF(K37>Настройки!$B1 у.е.2,"выше тренда","норма"))) | M37: =IF(L37="","",IF(L37="ниже тренда","возможное ослабление интереса",IF(L37="выше тренда","возможная фаза повышенного интереса","без выраженного отклонения"))) | N37: =IF(G37="","",COUNT($G5 у.е.:G37))
A38: =IF(Ввод_данных!A38="","",Ввод_данных!A38) | B38: =IF(A38="","",MONTH(A38)) | C38: =IF(A38="","",CHOOSE(MONTH(A38),"январь","февраль","март","апрель","май","июнь","июль","август","сентябрь","октябрь","ноябрь","декабрь")) | D38: =IF(Ввод_данных!C38="","",Ввод_данных!C38) | E38: =IF(Ввод_данных!D38="","",Ввод_данных!D38) | F38: =IF(E38="","",IF(MAX($E5 у.е.:$E6 у.е.4)=0,"",E38/MAX($E5 у.е.:$E6 у.е.4)*100)) | G38: =IF(COUNT(D38,F38)=0,"",IF(COUNT(D38,F38)=2,D38*Настройки!$B4 у.е.+F38*Настройки!$B5 у.е.,IF(D38<>"",D38,F38))) | H38: =IF(OR(G38="",COUNT($G5 у.е.:G38)<12),"",AVERAGE(G27:G38)) | I38: =IF(OR(G38="",H38="",H38=0),"",G38/H38) | J38: =IF(OR(G38="",IFERROR(VLOOKUP(B38,Сезонность!$A4 у.е.:$D1 у.е.5,4,FALSE),0)=0),"",G38/IFERROR(VLOOKUP(B38,Сезонность!$A4 у.е.:$D1 у.е.5,4,FALSE),1)) | K38: =IF(OR(G38="",H38="",H38=0,IFERROR(VLOOKUP(B38,Сезонность!$A4 у.е.:$D1 у.е.5,4,FALSE),0)=0),"",G38/(H38*IFERROR(VLOOKUP(B38,Сезонность!$A4 у.е.:$D1 у.е.5,4,FALSE),1))) | L38: =IF(K38="","",IF(K38<Настройки!$B1 у.е.1,"ниже тренда",IF(K38>Настройки!$B1 у.е.2,"выше тренда","норма"))) | M38: =IF(L38="","",IF(L38="ниже тренда","возможное ослабление интереса",IF(L38="выше тренда","возможная фаза повышенного интереса","без выраженного отклонения"))) | N38: =IF(G38="","",COUNT($G5 у.е.:G38))
A39: =IF(Ввод_данных!A39="","",Ввод_данных!A39) | B39: =IF(A39="","",MONTH(A39)) | C39: =IF(A39="","",CHOOSE(MONTH(A39),"январь","февраль","март","апрель","май","июнь","июль","август","сентябрь","октябрь","ноябрь","декабрь")) | D39: =IF(Ввод_данных!C39="","",Ввод_данных!C39) | E39: =IF(Ввод_данных!D39="","",Ввод_данных!D39) | F39: =IF(E39="","",IF(MAX($E5 у.е.:$E6 у.е.4)=0,"",E39/MAX($E5 у.е.:$E6 у.е.4)*100)) | G39: =IF(COUNT(D39,F39)=0,"",IF(COUNT(D39,F39)=2,D39*Настройки!$B4 у.е.+F39*Настройки!$B5 у.е.,IF(D39<>"",D39,F39))) | H39: =IF(OR(G39="",COUNT($G5 у.е.:G39)<12),"",AVERAGE(G28:G39)) | I39: =IF(OR(G39="",H39="",H39=0),"",G39/H39) | J39: =IF(OR(G39="",IFERROR(VLOOKUP(B39,Сезонность!$A4 у.е.:$D1 у.е.5,4,FALSE),0)=0),"",G39/IFERROR(VLOOKUP(B39,Сезонность!$A4 у.е.:$D1 у.е.5,4,FALSE),1)) | K39: =IF(OR(G39="",H39="",H39=0,IFERROR(VLOOKUP(B39,Сезонность!$A4 у.е.:$D1 у.е.5,4,FALSE),0)=0),"",G39/(H39*IFERROR(VLOOKUP(B39,Сезонность!$A4 у.е.:$D1 у.е.5,4,FALSE),1))) | L39: =IF(K39="","",IF(K39<Настройки!$B1 у.е.1,"ниже тренда",IF(K39>Настройки!$B1 у.е.2,"выше тренда","норма"))) | M39: =IF(L39="","",IF(L39="ниже тренда","возможное ослабление интереса",IF(L39="выше тренда","возможная фаза повышенного интереса","без выраженного отклонения"))) | N39: =IF(G39="","",COUNT($G5 у.е.:G39))
A40: =IF(Ввод_данных!A40="","",Ввод_данных!A40) | B40: =IF(A40="","",MONTH(A40)) | C40: =IF(A40="","",CHOOSE(MONTH(A40),"январь","февраль","март","апрель","май","июнь","июль","август","сентябрь","октябрь","ноябрь","декабрь")) | D40: =IF(Ввод_данных!C40="","",Ввод_данных!C40) | E40: =IF(Ввод_данных!D40="","",Ввод_данных!D40) | F40: =IF(E40="","",IF(MAX($E5 у.е.:$E6 у.е.4)=0,"",E40/MAX($E5 у.е.:$E6 у.е.4)*100)) | G40: =IF(COUNT(D40,F40)=0,"",IF(COUNT(D40,F40)=2,D40*Настройки!$B4 у.е.+F40*Настройки!$B5 у.е.,IF(D40<>"",D40,F40))) | H40: =IF(OR(G40="",COUNT($G5 у.е.:G40)<12),"",AVERAGE(G29:G40)) | I40: =IF(OR(G40="",H40="",H40=0),"",G40/H40) | J40: =IF(OR(G40="",IFERROR(VLOOKUP(B40,Сезонность!$A4 у.е.:$D1 у.е.5,4,FALSE),0)=0),"",G40/IFERROR(VLOOKUP(B40,Сезонность!$A4 у.е.:$D1 у.е.5,4,FALSE),1)) | K40: =IF(OR(G40="",H40="",H40=0,IFERROR(VLOOKUP(B40,Сезонность!$A4 у.е.:$D1 у.е.5,4,FALSE),0)=0),"",G40/(H40*IFERROR(VLOOKUP(B40,Сезонность!$A4 у.е.:$D1 у.е.5,4,FALSE),1))) | L40: =IF(K40="","",IF(K40<Настройки!$B1 у.е.1,"ниже тренда",IF(K40>Настройки!$B1 у.е.2,"выше тренда","норма"))) | M40: =IF(L40="","",IF(L40="ниже тренда","возможное ослабление интереса",IF(L40="выше тренда","возможная фаза повышенного интереса","без выраженного отклонения"))) | N40: =IF(G40="","",COUNT($G5 у.е.:G40))
A41: =IF(Ввод_данных!A41="","",Ввод_данных!A41) | B41: =IF(A41="","",MONTH(A41)) | C41: =IF(A41="","",CHOOSE(MONTH(A41),"январь","февраль","март","апрель","май","июнь","июль","август","сентябрь","октябрь","ноябрь","декабрь")) | D41: =IF(Ввод_данных!C41="","",Ввод_данных!C41) | E41: =IF(Ввод_данных!D41="","",Ввод_данных!D41) | F41: =IF(E41="","",IF(MAX($E5 у.е.:$E6 у.е.4)=0,"",E41/MAX($E5 у.е.:$E6 у.е.4)*100)) | G41: =IF(COUNT(D41,F41)=0,"",IF(COUNT(D41,F41)=2,D41*Настройки!$B4 у.е.+F41*Настройки!$B5 у.е.,IF(D41<>"",D41,F41))) | H41: =IF(OR(G41="",COUNT($G5 у.е.:G41)<12),"",AVERAGE(G30:G41)) | I41: =IF(OR(G41="",H41="",H41=0),"",G41/H41) | J41: =IF(OR(G41="",IFERROR(VLOOKUP(B41,Сезонность!$A4 у.е.:$D1 у.е.5,4,FALSE),0)=0),"",G41/IFERROR(VLOOKUP(B41,Сезонность!$A4 у.е.:$D1 у.е.5,4,FALSE),1)) | K41: =IF(OR(G41="",H41="",H41=0,IFERROR(VLOOKUP(B41,Сезонность!$A4 у.е.:$D1 у.е.5,4,FALSE),0)=0),"",G41/(H41*IFERROR(VLOOKUP(B41,Сезонность!$A4 у.е.:$D1 у.е.5,4,FALSE),1))) | L41: =IF(K41="","",IF(K41<Настройки!$B1 у.е.1,"ниже тренда",IF(K41>Настройки!$B1 у.е.2,"выше тренда","норма"))) | M41: =IF(L41="","",IF(L41="ниже тренда","возможное ослабление интереса",IF(L41="выше тренда","возможная фаза повышенного интереса","без выраженного отклонения"))) | N41: =IF(G41="","",COUNT($G5 у.е.:G41))
...

Sheet Сезонность
A1: Расчет сезонных индексов по месяцам
A3: Месяц № | B3: Месяц | C3: Средний Y/T | D3: Сезонный индекс | E3: Отклонение от среднего | F3: Интерпретация
A4: 1 | B4: январь | C4: =IFERROR(SUMIFS(Расчет!$I5 у.е.:$I6 у.е.4,Расчет!$B5 у.е.:$B6 у.е.4,A4)/COUNTIFS(Расчет!$B5 у.е.:$B6 у.е.4,A4,Расчет!$I5 у.е.:$I6 у.е.4,">0"),"") | D4: =IF(C4="","",C4/AVERAGE($C4 у.е.:$C1 у.е.5)) | E4: =IF(D4="","",D4-1) | F4: =IF(D4="","",IF(D4>1.1,"сезонный максимум",IF(D4<0.9,"сезонный минимум","средний сезонный уровень")))
A5: 2 | B5: февраль | C5: =IFERROR(SUMIFS(Расчет!$I5 у.е.:$I6 у.е.4,Расчет!$B5 у.е.:$B6 у.е.4,A5)/COUNTIFS(Расчет!$B5 у.е.:$B6 у.е.4,A5,Расчет!$I5 у.е.:$I6 у.е.4,">0"),"") | D5: =IF(C5="","",C5/AVERAGE($C4 у.е.:$C1 у.е.5)) | E5: =IF(D5="","",D5-1) | F5: =IF(D5="","",IF(D5>1.1,"сезонный максимум",IF(D5<0.9,"сезонный минимум","средний сезонный уровень")))
A6: 3 | B6: март | C6: =IFERROR(SUMIFS(Расчет!$I5 у.е.:$I6 у.е.4,Расчет!$B5 у.е.:$B6 у.е.4,A6)/COUNTIFS(Расчет!$B5 у.е.:$B6 у.е.4,A6,Расчет!$I5 у.е.:$I6 у.е.4,">0"),"") | D6: =IF(C6="","",C6/AVERAGE($C4 у.е.:$C1 у.е.5)) | E6: =IF(D6="","",D6-1) | F6: =IF(D6="","",IF(D6>1.1,"сезонный максимум",IF(D6<0.9,"сезонный минимум","средний сезонный уровень")))
A7: 4 | B7: апрель | C7: =IFERROR(SUMIFS(Расчет!$I5 у.е.:$I6 у.е.4,Расчет!$B5 у.е.:$B6 у.е.4,A7)/COUNTIFS(Расчет!$B5 у.е.:$B6 у.е.4,A7,Расчет!$I5 у.е.:$I6 у.е.4,">0"),"") | D7: =IF(C7="","",C7/AVERAGE($C4 у.е.:$C1 у.е.5)) | E7: =IF(D7="","",D7-1) | F7: =IF(D7="","",IF(D7>1.1,"сезонный максимум",IF(D7<0.9,"сезонный минимум","средний сезонный уровень")))
A8: 5 | B8: май | C8: =IFERROR(SUMIFS(Расчет!$I5 у.е.:$I6 у.е.4,Расчет!$B5 у.е.:$B6 у.е.4,A8)/COUNTIFS(Расчет!$B5 у.е.:$B6 у.е.4,A8,Расчет!$I5 у.е.:$I6 у.е.4,">0"),"") | D8: =IF(C8="","",C8/AVERAGE($C4 у.е.:$C1 у.е.5)) | E8: =IF(D8="","",D8-1) | F8: =IF(D8="","",IF(D8>1.1,"сезонный максимум",IF(D8<0.9,"сезонный минимум","средний сезонный уровень")))
A9: 6 | B9: июнь | C9: =IFERROR(SUMIFS(Расчет!$I5 у.е.:$I6 у.е.4,Расчет!$B5 у.е.:$B6 у.е.4,A9)/COUNTIFS(Расчет!$B5 у.е.:$B6 у.е.4,A9,Расчет!$I5 у.е.:$I6 у.е.4,">0"),"") | D9: =IF(C9="","",C9/AVERAGE($C4 у.е.:$C1 у.е.5)) | E9: =IF(D9="","",D9-1) | F9: =IF(D9="","",IF(D9>1.1,"сезонный максимум",IF(D9<0.9,"сезонный минимум","средний сезонный уровень")))
A10: 7 | B10: июль | C10: =IFERROR(SUMIFS(Расчет!$I5 у.е.:$I6 у.е.4,Расчет!$B5 у.е.:$B6 у.е.4,A10)/COUNTIFS(Расчет!$B5 у.е.:$B6 у.е.4,A10,Расчет!$I5 у.е.:$I6 у.е.4,">0"),"") | D10: =IF(C10="","",C10/AVERAGE($C4 у.е.:$C1 у.е.5)) | E10: =IF(D10="","",D10-1) | F10: =IF(D10="","",IF(D10>1.1,"сезонный максимум",IF(D10<0.9,"сезонный минимум","средний сезонный уровень")))
A11: 8 | B11: август | C11: =IFERROR(SUMIFS(Расчет!$I5 у.е.:$I6 у.е.4,Расчет!$B5 у.е.:$B6 у.е.4,A11)/COUNTIFS(Расчет!$B5 у.е.:$B6 у.е.4,A11,Расчет!$I5 у.е.:$I6 у.е.4,">0"),"") | D11: =IF(C11="","",C11/AVERAGE($C4 у.е.:$C1 у.е.5)) | E11: =IF(D11="","",D11-1) | F11: =IF(D11="","",IF(D11>1.1,"сезонный максимум",IF(D11<0.9,"сезонный минимум","средний сезонный уровень")))
A12: 9 | B12: сентябрь | C12: =IFERROR(SUMIFS(Расчет!$I5 у.е.:$I6 у.е.4,Расчет!$B5 у.е.:$B6 у.е.4,A12)/COUNTIFS(Расчет!$B5 у.е.:$B6 у.е.4,A12,Расчет!$I5 у.е.:$I6 у.е.4,">0"),"") | D12: =IF(C12="","",C12/AVERAGE($C4 у.е.:$C1 у.е.5)) | E12: =IF(D12="","",D12-1) | F12: =IF(D12="","",IF(D12>1.1,"сезонный максимум",IF(D12<0.9,"сезонный минимум","средний сезонный уровень")))
A13: 10 | B13: октябрь | C13: =IFERROR(SUMIFS(Расчет!$I5 у.е.:$I6 у.е.4,Расчет!$B5 у.е.:$B6 у.е.4,A13)/COUNTIFS(Расчет!$B5 у.е.:$B6 у.е.4,A13,Расчет!$I5 у.е.:$I6 у.е.4,">0"),"") | D13: =IF(C13="","",C13/AVERAGE($C4 у.е.:$C1 у.е.5)) | E13: =IF(D13="","",D13-1) | F13: =IF(D13="","",IF(D13>1.1,"сезонный максимум",IF(D13<0.9,"сезонный минимум","средний сезонный уровень")))
A14: 11 | B14: ноябрь | C14: =IFERROR(SUMIFS(Расчет!$I5 у.е.:$I6 у.е.4,Расчет!$B5 у.е.:$B6 у.е.4,A14)/COUNTIFS(Расчет!$B5 у.е.:$B6 у.е.4,A14,Расчет!$I5 у.е.:$I6 у.е.4,">0"),"") | D14: =IF(C14="","",C14/AVERAGE($C4 у.е.:$C1 у.е.5)) | E14: =IF(D14="","",D14-1) | F14: =IF(D14="","",IF(D14>1.1,"сезонный максимум",IF(D14<0.9,"сезонный минимум","средний сезонный уровень")))
A15: 12 | B15: декабрь | C15: =IFERROR(SUMIFS(Расчет!$I5 у.е.:$I6 у.е.4,Расчет!$B5 у.е.:$B6 у.е.4,A15)/COUNTIFS(Расчет!$B5 у.е.:$B6 у.е.4,A15,Расчет!$I5 у.е.:$I6 у.е.4,">0"),"") | D15: =IF(C15="","",C15/AVERAGE($C4 у.е.:$C1 у.е.5)) | E15: =IF(D15="","",D15-1) | F15: =IF(D15="","",IF(D15>1.1,"сезонный максимум",IF(D15<0.9,"сезонный минимум","средний сезонный уровень")))
A18: Показатель | B18: Значение
A19: Максимальный сезонный индекс | B19: =MAX($D4 у.е.:$D1 у.е.5)
A20: Минимальный сезонный индекс | B20: =MIN($D4 у.е.:$D1 у.е.5)
A21: Амплитуда сезонности | B21: =B19-B20
A22: Оценка силы сезонности | B22: =IF(B21>=Настройки!$B7 у.е.,"выраженная сезонность",IF(B21>=Настройки!$B8 у.е.,"умеренная сезонность","слабая сезонность"))
A23: Месяц максимума | B23: =IFERROR(INDEX($B4 у.е.:$B1 у.е.5,MATCH(B19,$D4 у.е.:$D1 у.е.5,0)),"")
A24: Месяц минимума | B24: =IFERROR(INDEX($B4 у.е.:$B1 у.е.5,MATCH(B20,$D4 у.е.:$D1 у.е.5,0)),"")

Sheet Оценка_тренда
A1: Оценка устойчивой динамики интереса
A3: Показатель | B3: Формула / значение | C3: Интерпретация | D3: Комментарий
A4: Количество наблюдений | B4: =COUNT(Расчет!$G5 у.е.:$G6 у.е.4) | C4: минимально желательно не менее 24 месяцев | D4: чем длиннее ряд, тем надежнее оценка
A5: Средний индекс за первые 12 месяцев | B5: =IF(B4<12,"",SUMIFS(Расчет!$G5 у.е.:$G6 у.е.4,Расчет!$N5 у.е.:$N6 у.е.4,">=1",Расчет!$N5 у.е.:$N6 у.е.4,"<=12")/COUNTIFS(Расчет!$N5 у.е.:$N6 у.е.4,">=1",Расчет!$N5 у.е.:$N6 у.е.4,"<=12")) | C5: исходный уровень интереса | D5: используется для сравнения с последним годом
A6: Средний индекс за последние 12 месяцев | B6: =IF(B4<12,"",SUMIFS(Расчет!$G5 у.е.:$G6 у.е.4,Расчет!$N5 у.е.:$N6 у.е.4,">="&B4-11,Расчет!$N5 у.е.:$N6 у.е.4,"<="&B4)/COUNTIFS(Расчет!$N5 у.е.:$N6 у.е.4,">="&B4-11,Расчет!$N5 у.е.:$N6 у.е.4,"<="&B4)) | C6: текущий уровень интереса | D6: сравнивается с первым годом
A7: Абсолютное изменение | B7: =IF(OR(B5="",B6=""),"",B6-B5) | C7: последние 12 месяцев минус первые 12 месяцев | D7: положительное значение означает рост
A8: Относительное изменение | B8: =IF(OR(B5="",B6=""),"",B7/B5) | C8: темп изменения среднего уровня | D8: ключевой показатель тренда
A9: Наклон линейного тренда | B9: =IFERROR(SLOPE(Расчет!$G5 у.е.:$G6 у.е.4,Расчет!$N5 у.е.:$N6 у.е.4),"") | C9: среднее изменение за месяц | D9: дополнительная оценка направления
A10: Классификация тренда | B10: =IF(B8="","",IF(B8>=Настройки!$B1 у.е.0,"растущий тренд",IF(B8<=Настройки!$B9 у.е.,"снижающийся тренд","стабильный тренд"))) | C10: растущий / стабильный / снижающийся | D10: по порогам на листе «Настройки»
A11: Управленческий вывод | B11: =IF(B10="","Недостаточно данных",IF(B10="растущий тренд","Интерес аудитории растет; бизнес-идея может быть дополнительно проверена на платежеспособный спрос.",IF(B10="снижающийся тренд","Интерес аудитории снижается; требуется осторожная проверка ниши, сегмента и каналов продвижения.","Интерес аудитории относительно стабилен; целесообразно изучить структуру спроса, конкурентов и целевые сегменты."))) | C11: готовая формулировка для отчета | D11: используется в обосновании бизнес-идеи

Sheet Деловые_циклы
A1: Оценка циклических отклонений и фаз спроса
A2: Важно: данные Google Trends и Яндекс Вордстат не измеряют макроэкономический деловой цикл напрямую. В таблице оценивается поисковый цикл спроса: периоды, когда интерес находится выше или ниже трендово-сезонного уровня
A4: Показатель | B4: Значение
A5: Последний период | B5: =IFERROR(INDEX(Расчет!$A5 у.е.:$A6 у.е.4,Оценка_тренда!$B4 у.е.),"")
A6: Текущий циклический коэффициент | B6: =IFERROR(INDEX(Расчет!$K5 у.е.:$K6 у.е.4,Оценка_тренда!$B4 у.е.),"")
A7: Текущая фаза | B7: =IFERROR(INDEX(Расчет!$L5 у.е.:$L6 у.е.4,Оценка_тренда!$B4 у.е.),"")
A8: Минимальный коэффициент | B8: =MIN(Расчет!$K5 у.е.:$K6 у.е.4)
A9: Максимальный коэффициент | B9: =MAX(Расчет!$K5 у.е.:$K6 у.е.4)
A10: Амплитуда циклических колебаний | B10: =B9-B8
A13: Период | B13: Сводный индекс | C13: Тренд | D13: Сезонный индекс | E13: Сезонно очищенный индекс | F13: Циклический коэффициент | G13: Фаза | H13: Практическое значение
A14: =Расчет!A5 | B14: =Расчет!G5 | C14: =Расчет!H5 | D14: =IFERROR(VLOOKUP(Расчет!B5,Сезонность!$A4 у.е.:$D1 у.е.5,4,FALSE),"") | E14: =Расчет!J5 | F14: =Расчет!K5 | G14: =Расчет!L5 | H14: =IF(G14="","",IF(G14="ниже тренда","период осторожного планирования продаж и бюджета",IF(G14="выше тренда","период активизации продвижения и продаж","обычный режим анализа спроса")))
A15: =Расчет!A6 | B15: =Расчет!G6 | C15: =Расчет!H6 | D15: =IFERROR(VLOOKUP(Расчет!B6,Сезонность!$A4 у.е.:$D1 у.е.5,4,FALSE),"") | E15: =Расчет!J6 | F15: =Расчет!K6 | G15: =Расчет!L6 | H15: =IF(G15="","",IF(G15="ниже тренда","период осторожного планирования продаж и бюджета",IF(G15="выше тренда","период активизации продвижения и продаж","обычный режим анализа спроса")))
