Workbook

Sheet Инструкция
A1: Excel-шаблон к методике формулирования бизнес-логики и пользовательских сценариев
A3: Назначение файла
A4: Этот файл предназначен для последовательной сборки бизнес-логики цифрового товара и пользовательских сценариев на основе всех ранее выполненных видов анализа: проблем, отзывов, конкурентов, рыночного стандарта, ценностного предложения, цифрового товара и Канвас
A5: Ключевой принцип: каждый элемент бизнес-логики и каждый пользовательский сценарий должен иметь источник, доказательство, связь с ценностным предложением, цифровым товаром, монетизацией и блоком бизнес-модели
A6: Сначала заполняется «Банк анализа», затем «Бизнес-логика», «Роли и сегменты», «Пользовательские сценарии», «Функциональные требования», «Приоритизация» и «Связность». Лист «Дашборд» рассчитывается автоматически
A7: Желтые ячейки — зоны ручного ввода. Зеленые ячейки — расчетные поля. Выпадающие списки берутся из листа «Справочники»
A9: Этап | B9: Что сделать | C9: Основной лист | D9: Результат | E9: Проверка качества | F9: Связь с методикой | G9: Ответственный | H9: Статус
A10: 1 | B10: Перенести ключевые выводы из всех видов анализа | C10: Банк анализа | D10: Единая доказательная база | E10: Есть ссылка/факт/уровень доказательности | F10: Анализ проблем, отзывов, конкурентов, Канвас | G10: Хаджынова К.А | H10: Пройдено
A11: 2 | B11: Сформулировать элементы бизнес-логики | C11: Бизнес-логика | D11: Понятно, за счет чего создается, доставляется и монетизируется ценность | E11: Для элемента указаны ценность, товар, процесс и выручка | F11: Сборка бизнес-модели | G11: Хаджынова К.А | H11: Пройдено
A12: 3 | B12: Описать роли и сегменты пользователей | C12: Роли и сегменты | D12: Понятно, кто участвует в сценариях | E12: У каждой роли есть задача, проблема и основание | F12: Потребительские сегменты Канвас | G12: Хаджынова К.А | H12: Пройдено
A13: 4 | B13: Собрать пользовательские сценарии | C13: Пользовательские сценарии | D13: Описаны основные, монетизационные, сервисные и удерживающие сценарии | E13: У сценария есть проблема, цель, результат и монетизация | F13: Переход от ценности к поведению пользователя | G13: Хаджынова К.А | H13: Пройдено
A14: 5 | B14: Разложить сценарии по этапам взаимодействия | C14: Карта сценариев | D14: Видны точки входа, оплаты, поддержки и удержания | E14: Нет разрывов между этапами | F14: Клиентский путь | G14: Хаджынова К.А | H14: Пройдено
A15: 6 | B15: Перевести сценарии в требования | C15: Функциональные требования | D15: Получен перечень функций и требований | E15: Требование связано со сценарием и бизнес-целью | F15: Товар как носитель ценности | G15: Хаджынова К.А | H15: Пройдено
A16: 7 | B16: Приоритизировать инициативы | C16: Приоритизация | D16: Определена очередность разработки | E16: Приоритет зависит от ценности, эффекта, доказательности и сложности | F16: MVP и развитие продукта | G16: Хаджынова К.А | H16: Пройдено
A17: 8 | B17: Проверить связность всей конструкции | C17: Связность | D17: Выявлены слабые места модели | E17: Контрольные точки пройдены | F17: Цепочка «анализ → логика → сценарий → товар → монетизация» | G17: Хаджынова К.А | H17: Пройдено

Sheet Банк анализа
A1: Банк выводов из всех видов анализа
A3: ID вывода | B3: Направление анализа | C3: Объект анализа | D3: Краткий вывод | E3: Подтверждающий факт | F3: Источник / ссылка | G3: Сила доказательства (1-4) | H3: Значимость для модели (1-5) | I3: Риск ошибочной интерпретации (1-5) | J3: Индекс опоры | K3: Связанный блок Канвас | L3: Связанная проблема / роль / сценарий | M3: Решение использовать | N3: Комментарий
A4: A-001 | B4: Анализ проблем клиентов | C4: Проблема P-002 | D4: Нет единого инструмента для всех нотаций проекта | E4: IDEF0, DFD, сети Петри не найдены у 8 конкурентов; UML, BPMN, ERD вместе - только у Lucidchart | F4: 6.1: Excel/6_1_...; ЛР5 (Excel/analiz_konkurentov_Levitt_Kano_NotaCode.xlsx) | G4: 3 | H4: 5 | I4: 2 | J4: =IFERROR((G4*H4)*(6-I4)/20,"") | K4: Ценностные предложения | L4: Проблема P-002; сценарий S-005 | M4: =IF(J4="","",IF(J4>=3,"Использовать",IF(J4>=1.8,"Проверить дополнительно","Не использовать как основание"))) | N4: Наиболее значимый вывод по P-002; основание ЦП VP-001
A5: A-002 | B5: Анализ проблем клиентов | C5: Проблема P-001 | D5: Текстовые языки требуют изучения синтаксиса | E5: Сложность Mermaid в опросе 2,6 из 5 (27 студентов, данные сгенерированы) | F5: ЛР4, survey_students.csv | G5: 2 | H5: 4 | I5: 3 | J5: =IFERROR((G5*H5)*(6-I5)/20,"") | K5: Ценностные предложения | L5: Проблема P-001; сценарий S-004 | M5: =IF(J5="","",IF(J5>=3,"Использовать",IF(J5>=1.8,"Проверить дополнительно","Не использовать как основание")))
A6: A-003 | B6: Анализ конкурентов по сайтам | C6: Тарифы 5 конкурентов | D6: Платные редакторы тарифицируются за пользователя от 9 у.е. в месяц | E6: Mermaid Chart 10 и 20, Lucidchart 9 и 10, Eraser 15 и 45, Whimsical 10 и 20 у.е | F6: Страницы тарифов, 01.10.2026 | G6: 4 | H6: 5 | I6: 1 | J6: =IFERROR((G6*H6)*(6-I6)/20,"") | K6: Потоки доходов | L6: Сценарий S-008; требование F-010 | M6: =IF(J6="","",IF(J6>=3,"Использовать",IF(J6>=1.8,"Проверить дополнительно","Не использовать как основание")))
A7: A-004 | B7: Анализ бизнес-моделей конкурентов | C7: Рыночный стандарт бизнес-модели | D7: Условно-бесплатная модель у 5 из 8, бесплатный доступ у 8 из 8 | E7: Лист 10_Стандарт ЛР5 | F7: ЛР5 (Excel/analiz_biznes_modeli_konkurentov_NotaCode.xlsx) | G7: 4 | H7: 5 | I7: 1 | J7: =IFERROR((G7*H7)*(6-I7)/20,"") | K7: Потоки доходов | L7: Единица монетизации M-001 | M7: =IF(J7="","",IF(J7>=3,"Использовать",IF(J7>=1.8,"Проверить дополнительно","Не использовать как основание")))
A8: A-005 | B8: Анализ цифрового товара и рыночного стандарта | C8: Рыночный стандарт товара | D8: Экспорт у 8 из 8, документация у 6 из 8, совместная работа у 6 из 8, вход у 5 из 8 | E8: Лист 07_Стандарт_рынка ЛР5 | F8: ЛР5 (Excel/analiz_konkurentov_Levitt_Kano_NotaCode.xlsx) | G8: 4 | H8: 5 | I8: 1 | J8: =IFERROR((G8*H8)*(6-I8)/20,"") | K8: Ценностные предложения | L8: Требования F-005, F-006, F-012 | M8: =IF(J8="","",IF(J8>=3,"Использовать",IF(J8>=1.8,"Проверить дополнительно","Не использовать как основание")))
A9: A-006 | B9: Классификация компаний по уровням конкуренции | C9: 22 компании | D9: Один прямой конкурент (PlantUML) и четыре близких: ядро - текстовые инструменты | E9: Лист 06_Сводка ЛР5, средний балл 2,83 | F9: ЛР5 (klassifikaciya_urovni_konkurencii_NotaCode.xlsx) | G9: 3 | H9: 4 | I9: 2 | J9: =IFERROR((G9*H9)*(6-I9)/20,"") | K9: Потребительские сегменты | L9: Роли R-001, R-003 | M9: =IF(J9="","",IF(J9>=3,"Использовать",IF(J9>=1.8,"Проверить дополнительно","Не использовать как основание")))
A10: A-007 | B10: Анализ конкурентов по сайтам | C10: Каналы конкурентов | D10: Основной канал текстовых инструментов - органический поиск 47-59 % | E10: Similarweb Pro, июнь - август 2026 (PlantUML, Mermaid) | F10: ЛР4, Similarweb Pro | G10: 3 | H10: 4 | I10: 2 | J10: =IFERROR((G10*H10)*(6-I10)/20,"") | K10: Каналы | L10: Сценарии S-001, S-002 | M10: =IF(J10="","",IF(J10>=3,"Использовать",IF(J10>=1.8,"Проверить дополнительно","Не использовать как основание")))
A11: A-008 | B11: Анализ отзывов | C11: Опрос студентов | D11: Коллаборация важна 26 из 27, экспорт PNG 27 из 27, SVG 18 из 27 | E11: survey_students.csv, ЛР4 | F11: ЛР4 | G11: 2 | H11: 4 | I11: 3 | J11: =IFERROR((G11*H11)*(6-I11)/20,"") | K11: Ценностные предложения | L11: Требования F-005, F-013 | M11: =IF(J11="","",IF(J11>=3,"Использовать",IF(J11>=1.8,"Проверить дополнительно","Не использовать как основание")))
A12: A-009 | B12: Экономика монетизации | C12: Готовность платить | D12: 18 из 27 готовы платить; средняя максимальная цена 728 BYN | E12: survey_students.csv, ЛР4 (период не указан) | F12: ЛР4 | G12: 2 | H12: 4 | I12: 4 | J12: =IFERROR((G12*H12)*(6-I12)/20,"") | K12: Потоки доходов | L12: Роль R-004 | M12: =IF(J12="","",IF(J12>=3,"Использовать",IF(J12>=1.8,"Проверить дополнительно","Не использовать как основание")))
A13: A-010 | B13: Экономика монетизации | C13: Расчёт выручки Pro | D13: Около 1 634 платящих пользователей при 40 у.е. в год - около 65 360 у.е | E13: ЛР2-3, ЛР4 (SAM 197 988 BYN) | F13: ЛР2-3, ЛР4 | G13: 2 | H13: 4 | I13: 3 | J13: =IFERROR((G13*H13)*(6-I13)/20,"") | K13: Потоки доходов | L13: Единица монетизации M-001 | M13: =IF(J13="","",IF(J13>=3,"Использовать",IF(J13>=1.8,"Проверить дополнительно","Не использовать как основание")))
A14: A-011 | B14: Ценностное предложение и цифровой товар | C14: ЦП VP-001 | D14: Опорная проблема P-002, индекс проблемы 74; ИКЦП 3,83 | E14: Методика 6.1 | F14: Excel/6_1_cennostnoe_predlozhenie_NotaCode.xlsx | G14: 3 | H14: 5 | I14: 2 | J14: =IFERROR((G14*H14)*(6-I14)/20,"") | K14: Ценностные предложения | L14: BL-001 | M14: =IF(J14="","",IF(J14>=3,"Использовать",IF(J14>=1.8,"Проверить дополнительно","Не использовать как основание")))
A15: A-012 | B15: Канвас бизнес-модели | C15: Канвас | D15: Блоки 8-11 (ресурсы, деятельность, партнёры, затраты) - гипотезы; полнота 71 % | E15: Методика 6.2 | F15: Excel/6_2_biznes_model_kanvas_NotaCode.xlsx | G15: 3 | H15: 4 | I15: 3 | J15: =IFERROR((G15*H15)*(6-I15)/20,"") | K15: Ключевые ресурсы | L15: BL-006 | M15: =IF(J15="","",IF(J15>=3,"Использовать",IF(J15>=1.8,"Проверить дополнительно","Не использовать как основание")))
A16: A-013 | B16: Анализ конкурентов по сайтам | C16: Eraser, Mermaid Chart | D16: Лимиты ИИ используются как тарифный ограничитель | E16: Eraser: 3, 40, 250 ИИ-диаграмм; Mermaid Chart: 15, 300, 2000 кредитов | F16: Страницы тарифов, 01.10.2026 | G16: 3 | H16: 3 | I16: 2 | J16: =IFERROR((G16*H16)*(6-I16)/20,"") | K16: Структура затрат | L16: Функция F-011 | M16: =IF(J16="","",IF(J16>=3,"Использовать",IF(J16>=1.8,"Проверить дополнительно","Не использовать как основание")))

Sheet Бизнес-логика
A1: Формулирование бизнес-логики цифрового товара
A3: ID элемента | B3: Элемент бизнес-логики | C3: Тип бизнес-логики | D3: Какая ценность создается | E3: Для кого | F3: Цифровой товар / функция | G3: Процесс или механизм | H3: Источник выручки / единица монетизации | I3: Связанный вывод анализа | J3: Доказательность (1-4) | K3: Влияние на модель (1-5) | L3: Проверка связности | M3: Индекс надежности | N3: Статус | O3: Нужное уточнение
A4: BL-001 | B4: Снижение барьера первой диаграммы | C4: Клиентская | D4: Пользователь быстрее получает корректную диаграмму без изучения всего синтаксиса | E4: Новый пользователь | F4: Редактор с текстовым вводом, предпросмотром и примерами | G4: Текст превращается в диаграмму сразу; ИИ-ассистент помогает с описанием | H4: Free: конверсия в Pro | I4: A-002 | J4: 2 | K4: 5 | L4: =IF(A4="","",IF(COUNTA(D4:I4)>=5,1,0)) | M4: =IF(A4="","",IFERROR(J4*K4*L4/20,0)) | N4: Требует проверки | O4: Уточнить, какие шаги настройки критичны
A5: BL-002 | B5: Единый набор нотаций | C5: Конкурентная | D5: Одна среда вместо нескольких инструментов для UML, BPMN, ERD, IDEF0, DFD, сетей Петри | E5: Студент, аналитик ПО | F5: Движок нотаций | G5: Единый текстовый формат и общий редактор | H5: Pro: набор нотаций и экспорт | I5: A-001 | J5: 3 | K5: 5 | L5: =IF(A5="","",IF(COUNTA(D5:I5)>=5,1,0)) | M5: =IF(A5="","",IFERROR(J5*K5*L5/20,0)) | N5: Подтверждено
A6: BL-003 | B6: Бесплатный вход | C6: Канальная | D6: Студент начинает без оплаты, как у 8 из 8 конкурентов | E6: Посетитель, студент | F6: Уровень Free | G6: Free привлекает аудиторию и ведёт к Pro | H6: Free: вход в воронку | I6: A-004 | J6: 4 | K6: 4 | L6: =IF(A6="","",IF(COUNTA(D6:I6)>=5,1,0)) | M6: =IF(A6="","",IFERROR(J6*K6*L6/20,0)) | N6: Подтверждено
A7: BL-004 | B7: Монетизация подписки Pro | C7: Монетизационная | D7: Клиент платит за снятие ограничений и расширенные функции | E7: Платящий клиент | F7: Подписка Pro 40 у.е. в год | G7: Ограничения функций по тарифам | H7: Пользователь Pro, год | I7: A-003 | J7: 4 | K7: 5 | L7: =IF(A7="","",IF(COUNTA(D7:I7)>=5,1,0)) | M7: =IF(A7="","",IFERROR(J7*K7*L7/20,0)) | N7: Подтверждено
A8: BL-005 | B8: Доверие через открытую цену и документацию | C8: Клиентская | D8: Клиент видит цену и умеет пользоваться без поддержки | E8: Потенциальный клиент | F8: Страница тарифов, документация | G8: Прозрачные условия снижают риск выбора | H8: Pro: рост доверия | I8: A-005 | J8: 4 | K8: 4 | L8: =IF(A8="","",IF(COUNTA(D8:I8)>=5,1,0)) | M8: =IF(A8="","",IFERROR(J8*K8*L8/20,0)) | N8: Подтверждено
A9: BL-006 | B9: Операционная способность | C9: Операционная | D9: Качество разбора нотаций и работа сервиса | E9: Внутренняя команда | F9: Движок нотаций, инфраструктура PWA, ИИ-провайдер | G9: Разработка, поддержка, документация | H9: Затраты: ИИ-вызовы переменные | I9: A-012 | J9: 2 | K9: 4 | L9: =IF(A9="","",IF(COUNTA(D9:I9)>=5,1,0)) | M9: =IF(A9="","",IFERROR(J9*K9*L9/20,0)) | N9: Подтверждено
A10: BL-007 | B10: Метрики проверки | C10: Метрическая | D10: Показатели проверки модели: доля первой диаграммы, переход в Pro, удержание | E10: Руководитель проекта | F10: Аналитика продукта | G10: Сбор событий сценариев | H10: Конверсия Free в Pro | I10: A-009 | J10: 2 | K10: 3 | L10: =IF(A10="","",IF(COUNTA(D10:I10)>=5,1,0)) | M10: =IF(A10="","",IFERROR(J10*K10*L10/20,0)) | N10: Подтверждено

Sheet Роли и сегменты
A1: Роли пользователей и потребительские сегменты
A3: ID роли | B3: Роль / сегмент | C3: Потребительская задача | D3: Проблема | E3: Мотивация | F3: Ограничения | G3: Готовность платить (1-5) | H3: Частота потребности (1-5) | I3: Ценность сегмента | J3: Канал входа | K3: Связанный блок Канвас | L3: Основание из анализа | M3: Доказательность (1-4) | N3: Статус
A4: R-001 | B4: Посетитель | C4: Найти инструмент для диаграммы нотации | D4: Не знает, какой инструмент поддерживает нужную нотацию | E4: Быстро найти подходящий инструмент | F4: Нехватка времени, недоверие | G4: 2 | H4: 4 | I4: =IF(A4="","",IFERROR(G4*H4,"")) | J4: Поиск Google и Яндекс | K4: Каналы | L4: A-007 | M4: 3 | N4: Требует проверки
A5: R-002 | B5: Новый пользователь | C5: Получить первую диаграмму | D5: Сложность синтаксиса текстовых языков | E5: Сдать работу в срок | F5: Нет опыта с нотациями | G5: 2 | H5: 4 | I5: =IF(A5="","",IFERROR(G5*H5,"")) | J5: Сайт, документация | K5: Потребительские сегменты | L5: A-002 | M5: 4 | N5: Подтверждено
A6: R-003 | B6: Активный пользователь | C6: Регулярно строить диаграммы разных нотаций | D6: Нужны несколько инструментов | E6: Экономия времени | F6: Привычка к draw.io и PlantUML | G6: 3 | H6: 5 | I6: =IF(A6="","",IFERROR(G6*H6,"")) | J6: Личный кабинет | K6: Потребительские сегменты | L6: A-001 | M6: 3 | N6: Требует проверки
A7: R-004 | B7: Платящий клиент | C7: Снять ограничения Free и получить расширенные функции | D7: Ограничения бесплатного уровня | E7: Профессиональный результат | F7: Цена, оплата из Беларуси | G7: 4 | H7: 4 | I7: =IF(A7="","",IFERROR(G7*H7,"")) | J7: Прямой заход, кабинет | K7: Потоки доходов | L7: A-003 | M7: 3 | N7: Требует проверки
A8: R-005 | B8: Администратор клиента | C8: Выдать доступ команде | D8: Нет командного тарифа у Free | E8: Единая среда для команды | F8: Командный тариф отложен | G8: 3 | H8: 2 | I8: =IF(A8="","",IFERROR(G8*H8,"")) | J8: Кабинет | K8: Потоки доходов | L8: A-003 | M8: 3 | N8: Требует проверки
A9: R-006 | B9: Внутренний администратор | C9: Обрабатывать обращения и ошибки | D9: Обращения по нотациям и оплате | E9: Качество сервиса | F9: Объём поддержки | G9: 1 | H9: 3 | I9: =IF(A9="","",IFERROR(G9*H9,"")) | J9: Поддержка | K9: Ключевые виды деятельности | L9: A-012 | M9: 3 | N9: Требует проверки
A10: R-007 | B10: Партнер | C10: Подключить студентов вуза | D10: Вузы требуют инструмент для занятий | E10: Доступ студентов к инструменту | F10: Нет договорённостей | G10: 2 | H10: 2 | I10: =IF(A10="","",IFERROR(G10*H10,"")) | J10: Вуз | K10: Ключевые партнеры | L10: A-006 | M10: 3 | N10: Требует проверки

Sheet Пользовательские сценарии
A1: Пользовательские сценарии: от проблемы к действию и монетизации
A3: ID сценария | B3: Название сценария | C3: Роль | D3: Этап | E3: Тип сценария | F3: Исходная проблема | G3: Цель пользователя | H3: Триггер | I3: Основной путь | J3: Альтернативный путь / ошибка | K3: Результат для пользователя | L3: Результат для бизнес-модели | M3: Единица монетизации | N3: Частота потребности (1-5) | O3: Значимость проблемы (1-5) | P3: Влияние на выручку (1-5) | Q3: Доказательность (1-4) | R3: Индекс сценария | S3: Приоритет | T3: Статус | U3: Источник анализа
A4: S-001 | B4: Найти инструмент для диаграммы нотации | C4: Посетитель | D4: Привлечение | E4: Привлечение | F4: Не ясно, какой инструмент поддерживает нужную нотацию | G4: Найти подходящий инструмент | H4: Задание по проектированию, поиск в Google или Яндекс | I4: Поисковый запрос, переход на сайт, страница возможностей | J4: Выбор другого инструмента | K4: Понимание, что нотация поддерживается | L4: Рост трафика | M4: Free | N4: 4 | O4: 4 | P4: 3 | Q4: 3 | R4: =IF(A4="","",IFERROR(N4*O4*P4*Q4/20,0)) | S4: =IF(R4="","",IF(R4>=15,"Критический",IF(R4>=9,"Высокий",IF(R4>=5,"Средний",IF(R4>=2,"Низкий","Отложить"))))) | T4: Требует проверки | U4: A-001
A5: S-002 | B5: Сравнить NotaCode с другими инструментами и увидеть цену | C5: Потенциальный клиент | D5: Первичный интерес | E5: Сравнение и доверие | F5: Риск выбора неподходящего инструмента | G5: Убедиться в наборе нотаций и цене | H5: Сомнение в выборе | I5: Страница возможностей, тарифы, документация | J5: Уход к draw.io или PlantUML | K5: Решение зарегистрироваться | L5: Конверсия в регистрацию | M5: Free, Pro | N5: 4 | O5: 4 | P5: 4 | Q5: 3 | R5: =IF(A5="","",IFERROR(N5*O5*P5*Q5/20,0)) | S5: =IF(R5="","",IF(R5>=15,"Критический",IF(R5>=9,"Высокий",IF(R5>=5,"Средний",IF(R5>=2,"Низкий","Отложить"))))) | T5: Подтверждено | U5: A-003
A6: S-003 | B6: Зарегистрироваться в бесплатном уровне | C6: Новый пользователь | D6: Регистрация | E6: Вход и активация | F6: Барьер входа | G6: Получить доступ к редактору | H6: Решение попробовать | I6: Кнопка входа, регистрация, подтверждение | J6: Отказ от регистрации | K6: Доступ к редактору Free | L6: Активация пользователя | M6: Free | N6: 4 | O6: 4 | P6: 3 | Q6: 4 | R6: =IF(A6="","",IFERROR(N6*O6*P6*Q6/20,0)) | S6: =IF(R6="","",IF(R6>=15,"Критический",IF(R6>=9,"Высокий",IF(R6>=5,"Средний",IF(R6>=2,"Низкий","Отложить"))))) | T6: Подтверждено | U6: A-004
A7: S-004 | B7: Построить первую диаграмму из текста | C7: Новый пользователь | D7: Получение ценности | E7: Основной | F7: Сложность синтаксиса текстовых языков | G7: Получить корректную диаграмму | H7: Задание на диаграмму | I7: Выбор нотации, ввод текста, предпросмотр, правка | J7: Ошибка синтаксиса, подсказка и пример | K7: Диаграмма в выбранной нотации | L7: Первое значимое действие | M7: Free | N7: 5 | O7: 5 | P7: 3 | Q7: 3 | R7: =IF(A7="","",IFERROR(N7*O7*P7*Q7/20,0)) | S7: =IF(R7="","",IF(R7>=15,"Критический",IF(R7>=9,"Высокий",IF(R7>=5,"Средний",IF(R7>=2,"Низкий","Отложить"))))) | T7: Подтверждено | U7: A-001
A8: S-005 | B8: Построить диаграмму IDEF0 или DFD | C8: Активный пользователь | D8: Настройка | E8: Основной | F8: Нотации IDEF0 и DFD не поддерживаются конкурентами | G8: Получить диаграмму нужной нотации | H8: Задание по стандарту моделирования | I8: Выбор нотации, ввод текста, предпросмотр | J8: Достигнут лимит проектов Free | K8: Диаграмма IDEF0 или DFD | L8: Отличие от конкурентов | M8: Pro | N8: 3 | O8: 5 | P8: 4 | Q8: 3 | R8: =IF(A8="","",IFERROR(N8*O8*P8*Q8/20,0)) | S8: =IF(R8="","",IF(R8>=15,"Критический",IF(R8>=9,"Высокий",IF(R8>=5,"Средний",IF(R8>=2,"Низкий","Отложить"))))) | T8: Подтверждено | U8: A-001
A9: S-006 | B9: Экспортировать диаграмму в PNG или SVG | C9: Новый пользователь | D9: Получение ценности | E9: Основной | F9: Диаграмму нужно вставить в отчёт | G9: Получить файл диаграммы | H9: Оформление работы | I9: Кнопка экспорта, выбор формата, скачивание | J9: Формат недоступен | K9: Файл PNG или SVG | L9: Удовлетворённость | M9: Free, Pro | N9: 5 | O9: 5 | P9: 3 | Q9: 4 | R9: =IF(A9="","",IFERROR(N9*O9*P9*Q9/20,0)) | S9: =IF(R9="","",IF(R9>=15,"Критический",IF(R9>=9,"Высокий",IF(R9>=5,"Средний",IF(R9>=2,"Низкий","Отложить"))))) | T9: Подтверждено | U9: A-005
A10: S-007 | B10: Сохранить диаграмму и вернуться к ней | C10: Активный пользователь | D10: Повторное использование | E10: Удержание | F10: Потеря наработок | G10: Продолжить работу позже | H10: Возврат к заданию | I10: Вход, список диаграмм, открытие, правка | J10: Версия утеряна | K10: Продолжение работы | L10: Удержание пользователя | M10: Free, Pro | N10: 4 | O10: 4 | P10: 3 | Q10: 3 | R10: =IF(A10="","",IFERROR(N10*O10*P10*Q10/20,0)) | S10: =IF(R10="","",IF(R10>=15,"Критический",IF(R10>=9,"Высокий",IF(R10>=5,"Средний",IF(R10>=2,"Низкий","Отложить"))))) | T10: Требует проверки | U10: A-012
A11: S-008 | B11: Оформить подписку Pro | C11: Платящий клиент | D11: Оплата | E11: Монетизационный | F11: Достигнуто ограничение Free | G11: Снять ограничения | H11: Достигнут лимит или нужна нотация Pro | I11: Страница тарифов, выбор Pro, оплата 40 у.е. в год | J11: Ошибка оплаты, повтор, другая карта | K11: Доступ Pro | L11: Выручка Pro | M11: Pro, год | N11: 3 | O11: 5 | P11: 5 | Q11: 3 | R11: =IF(A11="","",IFERROR(N11*O11*P11*Q11/20,0)) | S11: =IF(R11="","",IF(R11>=15,"Критический",IF(R11>=9,"Высокий",IF(R11>=5,"Средний",IF(R11>=2,"Низкий","Отложить"))))) | T11: Подтверждено | U11: A-009
A12: S-009 | B12: Исправить ошибку в описании диаграммы | C12: Новый пользователь | D12: Поддержка | E12: Поддержка и восстановление | F12: Диаграмма не строится из-за ошибки | G12: Исправить и получить диаграмму | H12: Сообщение об ошибке | I12: Сообщение, подсказка, пример, правка | J12: Обращение в поддержку | K12: Исправленная диаграмма | L12: Снижение оттока | M12: Free | N12: 4 | O12: 4 | P12: 2 | Q12: 2 | R12: =IF(A12="","",IFERROR(N12*O12*P12*Q12/20,0)) | S12: =IF(R12="","",IF(R12>=15,"Критический",IF(R12>=9,"Высокий",IF(R12>=5,"Средний",IF(R12>=2,"Низкий","Отложить"))))) | T12: Требует проверки | U12: A-002
A13: S-010 | B13: Найти ответ в документации | C13: Активный пользователь | D13: Поддержка | E13: Поддержка и восстановление | F13: Нужен пример нотации | G13: Найти ответ без обращения | H13: Вопрос по нотации | I13: Поиск, раздел документации, пример | J13: Обращение в поддержку | K13: Ответ и пример | L13: Снижение нагрузки на поддержку | M13: Free, Pro | N13: 3 | O13: 3 | P13: 2 | Q13: 3 | R13: =IF(A13="","",IFERROR(N13*O13*P13*Q13/20,0)) | S13: =IF(R13="","",IF(R13>=15,"Критический",IF(R13>=9,"Высокий",IF(R13>=5,"Средний",IF(R13>=2,"Низкий","Отложить"))))) | T13: Требует проверки | U13: A-005
A14: S-011 | B14: Выдать доступ команде | C14: Администратор клиента | D14: Удержание | E14: Административный | F14: Команде нужна единая среда | G14: Подключить участников | H14: Рост команды | I14: Кабинет, приглашение, роли | J14: Отдельные подписки | K14: Командная работа | L14: Командный тариф | M14: Организация | N14: 2 | O14: 3 | P14: 4 | Q14: 2 | R14: =IF(A14="","",IFERROR(N14*O14*P14*Q14/20,0)) | S14: =IF(R14="","",IF(R14>=15,"Критический",IF(R14>=9,"Высокий",IF(R14>=5,"Средний",IF(R14>=2,"Низкий","Отложить"))))) | T14: Гипотеза | U14: A-006
A15: S-012 | B15: Подключить студентов вуза | C15: Партнер | D15: Привлечение | E15: Партнерский | F15: Вузы нуждаются в инструменте для занятий | G15: Организовать доступ студентов | H15: Начало семестра | I15: Договорённость, инструкция, регистрация | J15: Отказ вуза | K15: Доступ студентов | L15: Рост аудитории | M15: Free | N15: 2 | O15: 3 | P15: 3 | Q15: 1 | R15: =IF(A15="","",IFERROR(N15*O15*P15*Q15/20,0)) | S15: =IF(R15="","",IF(R15>=15,"Критический",IF(R15>=9,"Высокий",IF(R15>=5,"Средний",IF(R15>=2,"Низкий","Отложить"))))) | T15: Гипотеза | U15: A-006

Sheet Карта сценариев
A1: Карта прохождения пользовательских сценариев по этапам взаимодействия
A3: ID сценария | B3: Роль | C3: Сценарий | D3: Привлечение | E3: Первичный интерес | F3: Регистрация | G3: Настройка | H3: Получение ценности | I3: Оплата | J3: Повторное использование | K3: Поддержка | L3: Удержание | M3: Разрыв / риск | N3: Критическая точка | O3: Комментарий
A4: S-001 | B4: Посетитель | C4: Найти инструмент для диаграммы нотации | D4: Поисковый запрос, переход на сайт, страница возможностей | E4: страница продукта | F4: демо без регистрации | G4: автонастройка | H4: первый результат | I4: Просмотр галереи примеров | J4: Страница тарифов Free и Pro | K4: подсказка | L4: email-приглашение | M4: Выбор другого инструмента | N4: Да | O4: Метрика: Рост трафика
A5: S-002 | B5: Потенциальный клиент | C5: Сравнить NotaCode с другими инструментами и увидеть цену | D5: ретаргетинг | E5: Страница возможностей, тарифы, документация | F5: аккаунт создан | G5: Онбординг-тур, первая диаграмма | H5: доступ к ограничениям | I5: оплата тарифа | J5: активация доступа | K5: помощь при оплате | L5: уведомление о ценности | M5: Уход к draw.io или PlantUML | N5: Нет | O5: Метрика: Конверсия в регистрацию
A6: S-003 | B6: Новый пользователь | C6: Зарегистрироваться в бесплатном уровне | D6: Рекомендация однокурсника, поиск «онлайн редактор UML бесплатно» | E6: Сайт: страница нотаций и тарифа Free | F6: Кнопка входа, регистрация, подтверждение | G6: Настройка профиля, выбор нотации | H6: Первая диаграмма в редакторе Free | J6: Повторный вход в редактор | K6: Документация, онбординг-тур | L6: Email о новых функциях | M6: Отказ от регистрации | N6: Нет | O6: Метрика: Активация пользователя
A7: S-004 | B7: Новый пользователь | C7: Построить первую диаграмму из текста | D7: Переход из поисковой выдачи или с главной страницы | E7: Страница нотаций, демо-диаграмма | F7: Вход в редактор Free | G7: Выбор нотации UML или ERD | H7: Выбор нотации, ввод текста, предпросмотр, правка | J7: Сохранение проекта, повторный ввод | K7: Подсказки синтаксиса, валидация | L7: Уведомление о сохранённом проекте | M7: Ошибка синтаксиса, подсказка и пример | N7: Да | O7: Метрика: Первое значимое действие
A8: S-005 | B8: Активный пользователь | C8: Построить диаграмму IDEF0 или DFD | D8: Задание по IDEF0 или DFD; поиск инструмента | E8: Страница нотаций: IDEF0, DFD, сети Петри | F8: Вход в редактор Free | G8: Выбор нотации, ввод текста, предпросмотр | H8: Диаграмма IDEF0 или DFD построена | J8: Повторное использование при новом задании | K8: Примеры IDEF0 и DFD в документации | L8: Email с шаблонами IDEF0/DFD | M8: Достигнут лимит проектов Free | N8: Нет | O8: Метрика: Отличие от конкурентов
A9: S-006 | B9: Новый пользователь | C9: Экспортировать диаграмму в PNG или SVG | D9: Завершение диаграммы, необходимость вставить в отчёт | E9: Кнопка «Экспорт» в редакторе | F9: Выбор формата PNG или SVG | G9: Нажатие «Скачать» | H9: Кнопка экспорта, выбор формата, скачивание | J9: Повторный экспорт другой диаграммы | K9: Инструкция по разрешению изображения | L9: Напоминание об экспорте Pro: BPMN XML, DOT | M9: Формат недоступен | N9: Нет | O9: Метрика: Удовлетворённость
A10: S-007 | B10: Активный пользователь | C10: Сохранить диаграмму и вернуться к ней | D10: Опыт с PlantUML или Mermaid; поиск альтернативы | E10: Страница сравнения нотаций: IDEF0 в тексте vs визуальный редактор | F10: Вход без регистрации (демо) или в Free | G10: Попытка повторить знакомую диаграмму | H10: Результат совпадает с ожиданием | J10: Вход, список диаграмм, открытие, правка | K10: Сравнение синтаксиса PlantUML и NotaCode | L10: Письмо о поддержке PlantUML-экспорта в Pro | M10: Версия утеряна | N10: Нет | O10: Метрика: Удержание пользователя
A11: S-008 | B11: Платящий клиент | C11: Оформить подписку Pro | D11: Исчерпание лимита Free или потребность в расширенном экспорте | E11: Страница тарифов: сравнение Free и Pro | F11: Кнопка «Перейти на Pro» | G11: Форма оплаты, выбор годового тарифа | H11: Оплата 40 у.е. в год, активация Pro | I11: Страница тарифов, выбор Pro, оплата 40 у.е. в год | J11: Работа с расширенным экспортом | K11: Квитанция, FAQ по тарифам | L11: Уведомление за 14 дней до окончания подписки | M11: Ошибка оплаты, повтор, другая карта | N11: Да | O11: Метрика: Выручка Pro
A12: S-009 | B12: Новый пользователь | C12: Исправить ошибку в описании диаграммы | D12: Студент рассказывает однокурснику; упоминание на занятии | E12: Ссылка на проект или демо-диаграмму | F12: Регистрация приглашённого пользователя | G12: Совместный доступ к проекту | H12: Коллаборация в одном редакторе | J12: Совместное редактирование при следующем задании | K12: Сообщение, подсказка, пример, правка | L12: Приглашение в Pro для команды | M12: Обращение в поддержку | N12: Нет | O12: Метрика: Снижение оттока
A13: S-010 | B13: Активный пользователь | C13: Найти ответ в документации | D13: Задание с описанием процесса на русском | E13: Кнопка ИИ-ассистента в редакторе | F13: Ввод текстового описания процесса | G13: Запрос к ИИ-ассистенту | H13: ИИ-заглушка возвращает шаблон нотации | J13: Повторный запрос для другого блока | K13: Поиск, раздел документации, пример | L13: Уведомление о полной ИИ-генерации в Pro | M13: Обращение в поддержку | N13: Нет | O13: Метрика: Снижение нагрузки на поддержку
A14: S-011 | B14: Администратор клиента | C14: Выдать доступ команде | D14: Преподаватель ищет инструмент для учебных материалов | E14: Сайт: страница для преподавателей или документация | F14: Регистрация преподавателя в Free | G14: Создание учебного проекта с диаграммами | H14: Диаграмма IDEF0 или UML для лекции | J14: Использование в следующем курсе | K14: Примеры учебных диаграмм, FAQ | L14: Кабинет, приглашение, роли | M14: Отдельные подписки | N14: Нет | O14: Метрика: Командный тариф
A15: S-012 | B15: Партнер | C15: Подключить студентов вуза | D15: Договорённость, инструкция, регистрация | E15: Корпоративная страница или рекомендация коллеги | F15: Регистрация команды в Free | G15: Создание общего рабочего пространства | H15: Архитектурная диаграмма согласована командой | I15: Рассмотрение Pro для команды (40 у.е./чел./год) | J15: Регулярное использование в спринтах | K15: Onboarding для IT-команд, интеграции | L15: Предложение корпоративного тарифа | M15: Отказ вуза | N15: Нет | O15: Метрика: Рост аудитории

Sheet Функциональные требования
A1: Перевод пользовательских сценариев в функциональные требования
A3: ID требования | B3: Требование | C3: Связанный сценарий | D3: Роль | E3: Пользовательская задача | F3: Бизнес-цель | G3: Категория Кано | H3: Уровень товара по Левитту | I3: Влияние на ценность (1-5) | J3: Влияние на монетизацию (1-5) | K3: Сложность реализации (1-5) | L3: Доказательность (1-4) | M3: Индекс приоритета | N3: Приоритет | O3: MVP | P3: Статус | Q3: Источник
A4: F-001 | B4: Текстовый ввод диаграммы с предпросмотром | C4: S-004 | D4: Новый пользователь | E4: Получить первую диаграмму | F4: Рост активации | G4: Базовое требование | H4: Родовой товар | I4: 5 | J4: 4 | K4: 4 | L4: 4 | M4: =IF(A4="","",IFERROR((I4+J4)*L4/K4,0)) | N4: =IF(M4="","",IF(M4>=16,"Критический",IF(M4>=10,"Высокий",IF(M4>=6,"Средний",IF(M4>=3,"Низкий","Отложить"))))) | O4: =IF(M4="","",IF(OR(N4="Критический",N4="Высокий"),"Да",IF(N4="Средний","Кандидат","Нет"))) | P4: Требует проверки | Q4: A-001
A5: F-002 | B5: Нотация UML (классы, последовательности) | C5: S-004 | D5: Новый пользователь | E5: Построить UML-диаграмму | F5: Закрыть стандарт рынка | G5: Базовое требование | H5: Ожидаемый товар | I5: 5 | J5: 4 | K5: 3 | L5: 3 | M5: =IF(A5="","",IFERROR((I5+J5)*L5/K5,0)) | N5: =IF(M5="","",IF(M5>=16,"Критический",IF(M5>=10,"Высокий",IF(M5>=6,"Средний",IF(M5>=3,"Низкий","Отложить"))))) | O5: =IF(M5="","",IF(OR(N5="Критический",N5="Высокий"),"Да",IF(N5="Средний","Кандидат","Нет"))) | P5: Подтверждено | Q5: A-003
A6: F-003 | B6: Нотации ERD, IDEF1X и IDEF3 (волна 1) | C6: S-004 | D6: Активный пользователь | E6: Построить процесс и модель данных | F6: Закрыть ожидаемый состав | G6: Линейное требование | H6: Ожидаемый товар | I6: 4 | J6: 4 | K6: 3 | L6: 3 | M6: =IF(A6="","",IFERROR((I6+J6)*L6/K6,0)) | N6: =IF(M6="","",IF(M6>=16,"Критический",IF(M6>=10,"Высокий",IF(M6>=6,"Средний",IF(M6>=3,"Низкий","Отложить"))))) | O6: =IF(M6="","",IF(OR(N6="Критический",N6="Высокий"),"Да",IF(N6="Средний","Кандидат","Нет"))) | P6: Требует проверки
A7: F-004 | B7: Нотации IDEF0 и DFD (волна 1) | C7: S-005 | D7: Активный пользователь | E7: Построить диаграмму по стандарту | F7: Конкурентное отличие | G7: Привлекательное требование | H7: Расширенный товар | I7: 5 | J7: 4 | K7: 4 | L7: 3 | M7: =IF(A7="","",IFERROR((I7+J7)*L7/K7,0)) | N7: =IF(M7="","",IF(M7>=16,"Критический",IF(M7>=10,"Высокий",IF(M7>=6,"Средний",IF(M7>=3,"Низкий","Отложить"))))) | O7: =IF(M7="","",IF(OR(N7="Критический",N7="Высокий"),"Да",IF(N7="Средний","Кандидат","Нет"))) | P7: Требует проверки
A8: F-005 | B8: Экспорт в PNG и SVG | C8: S-006 | D8: Новый пользователь | E8: Вставить диаграмму в отчёт | F8: Удовлетворённость | G8: Базовое требование | H8: Ожидаемый товар | I8: 5 | J8: 3 | K8: 2 | L8: 4 | M8: =IF(A8="","",IFERROR((I8+J8)*L8/K8,0)) | N8: =IF(M8="","",IF(M8>=16,"Критический",IF(M8>=10,"Высокий",IF(M8>=6,"Средний",IF(M8>=3,"Низкий","Отложить"))))) | O8: =IF(M8="","",IF(OR(N8="Критический",N8="Высокий"),"Да",IF(N8="Средний","Кандидат","Нет"))) | P8: Требует проверки
A9: F-006 | B9: Регистрация и личный кабинет Free | C9: S-003 | D9: Новый пользователь | E9: Получить доступ | F9: Активация | G9: Базовое требование | H9: Ожидаемый товар | I9: 4 | J9: 4 | K9: 2 | L9: 3 | M9: =IF(A9="","",IFERROR((I9+J9)*L9/K9,0)) | N9: =IF(M9="","",IF(M9>=16,"Критический",IF(M9>=10,"Высокий",IF(M9>=6,"Средний",IF(M9>=3,"Низкий","Отложить"))))) | O9: =IF(M9="","",IF(OR(N9="Критический",N9="Высокий"),"Да",IF(N9="Средний","Кандидат","Нет"))) | P9: Требует проверки
A10: F-007 | B10: Сохранение диаграмм и история версий | C10: S-007 | D10: Активный пользователь | E10: Вернуться к работе | F10: Удержание | G10: Линейное требование | H10: Расширенный товар | I10: 4 | J10: 3 | K10: 3 | L10: 3 | M10: =IF(A10="","",IFERROR((I10+J10)*L10/K10,0)) | N10: =IF(M10="","",IF(M10>=16,"Критический",IF(M10>=10,"Высокий",IF(M10>=6,"Средний",IF(M10>=3,"Низкий","Отложить"))))) | O10: =IF(M10="","",IF(OR(N10="Критический",N10="Высокий"),"Да",IF(N10="Средний","Кандидат","Нет"))) | P10: Требует проверки
A11: F-008 | B11: Подсказки об ошибках синтаксиса | C11: S-009 | D11: Новый пользователь | E11: Исправить ошибку | F11: Снизить отказы | G11: Привлекательное требование | H11: Расширенный товар | I11: 4 | J11: 3 | K11: 4 | L11: 2 | M11: =IF(A11="","",IFERROR((I11+J11)*L11/K11,0)) | N11: =IF(M11="","",IF(M11>=16,"Критический",IF(M11>=10,"Высокий",IF(M11>=6,"Средний",IF(M11>=3,"Низкий","Отложить"))))) | O11: =IF(M11="","",IF(OR(N11="Критический",N11="Высокий"),"Да",IF(N11="Средний","Кандидат","Нет"))) | P11: Требует проверки
A12: F-009 | B12: Страница возможностей и тарифов Free и Pro | C12: S-002 | D12: Потенциальный клиент | E12: Сравнить и увидеть цену | F12: Конверсия в регистрацию | G12: Базовое требование | H12: Ожидаемый товар | I12: 4 | J12: 5 | K12: 2 | L12: 4 | M12: =IF(A12="","",IFERROR((I12+J12)*L12/K12,0)) | N12: =IF(M12="","",IF(M12>=16,"Критический",IF(M12>=10,"Высокий",IF(M12>=6,"Средний",IF(M12>=3,"Низкий","Отложить"))))) | O12: =IF(M12="","",IF(OR(N12="Критический",N12="Высокий"),"Да",IF(N12="Средний","Кандидат","Нет"))) | P12: Требует проверки
A13: F-010 | B13: Оплата подписки Pro | C13: S-008 | D13: Платящий клиент | E13: Оформить Pro | F13: Выручка | G13: Базовое требование | H13: Ожидаемый товар | I13: 3 | J13: 5 | K13: 3 | L13: 4 | M13: =IF(A13="","",IFERROR((I13+J13)*L13/K13,0)) | N13: =IF(M13="","",IF(M13>=16,"Критический",IF(M13>=10,"Высокий",IF(M13>=6,"Средний",IF(M13>=3,"Низкий","Отложить"))))) | O13: =IF(M13="","",IF(OR(N13="Критический",N13="Высокий"),"Да",IF(N13="Средний","Кандидат","Нет"))) | P13: Требует проверки
A14: F-011 | B14: ИИ-ассистент построения диаграммы | C14: S-004 | D14: Новый пользователь | E14: Описать диаграмму словами | F14: Снизить барьер входа | G14: Привлекательное требование | H14: Расширенный товар | I14: 4 | J14: 4 | K14: 4 | L14: 3 | M14: =IF(A14="","",IFERROR((I14+J14)*L14/K14,0)) | N14: =IF(M14="","",IF(M14>=16,"Критический",IF(M14>=10,"Высокий",IF(M14>=6,"Средний",IF(M14>=3,"Низкий","Отложить"))))) | O14: =IF(M14="","",IF(OR(N14="Критический",N14="Высокий"),"Да",IF(N14="Средний","Кандидат","Нет"))) | P14: Требует проверки
A15: F-012 | B15: Документация и примеры нотаций | C15: S-010 | D15: Активный пользователь | E15: Найти пример | F15: Снизить поддержку | G15: Базовое требование | H15: Ожидаемый товар | I15: 4 | J15: 2 | K15: 2 | L15: 4 | M15: =IF(A15="","",IFERROR((I15+J15)*L15/K15,0)) | N15: =IF(M15="","",IF(M15>=16,"Критический",IF(M15>=10,"Высокий",IF(M15>=6,"Средний",IF(M15>=3,"Низкий","Отложить"))))) | O15: =IF(M15="","",IF(OR(N15="Критический",N15="Высокий"),"Да",IF(N15="Средний","Кандидат","Нет"))) | P15: Требует проверки
A16: F-013 | B16: Совместное редактирование и доступ команде | C16: S-011 | D16: Администратор клиента | E16: Работать командой | F16: Командный тариф | G16: Линейное требование | H16: Расширенный товар | I16: 4 | J16: 4 | K16: 5 | L16: 3 | M16: =IF(A16="","",IFERROR((I16+J16)*L16/K16,0)) | N16: =IF(M16="","",IF(M16>=16,"Критический",IF(M16>=10,"Высокий",IF(M16>=6,"Средний",IF(M16>=3,"Низкий","Отложить"))))) | O16: =IF(M16="","",IF(OR(N16="Критический",N16="Высокий"),"Да",IF(N16="Средний","Кандидат","Нет"))) | P16: Требует проверки

Sheet Приоритизация
A1: Приоритизация сценариев, функций и продуктовых инициатив
A3: ID инициативы | B3: Инициатива | C3: Тип | D3: Связанный сценарий | E3: Связанное требование | F3: Пользовательская ценность (1-5) | G3: Бизнес-эффект (1-5) | H3: Доказательность (1-4) | I3: Сложность (1-5) | J3: Риск (1-5) | K3: Итоговый индекс | L3: Решение | M3: Период реализации | N3: Комментарий
A4: P-001 | B4: Построение диаграммы из текста с предпросмотром | C4: Сценарий + функция | D4: S-004 | E4: F-001 | F4: 5 | G4: 5 | H4: 4 | I4: 4 | J4: 2 | K4: =IF(A4="","",IFERROR((F4+G4+H4)*((6-J4)/5)/I4,0)) | L4: =IF(K4="","",IF(K4>=6,"Включить в первую версию",IF(K4>=4,"Включить после проверки",IF(K4>=2.5,"Проверить дополнительно",IF(K4>=1.5,"Отложить","Исключить"))))) | M4: Первая версия | N4: Ядро ценности
A5: P-002 | B5: Экспорт PNG и SVG | C5: Функция | D5: S-006 | E5: F-005 | F5: 5 | G5: 4 | H5: 4 | I5: 2 | J5: 1 | K5: =IF(A5="","",IFERROR((F5+G5+H5)*((6-J5)/5)/I5,0)) | L5: =IF(K5="","",IF(K5>=6,"Включить в первую версию",IF(K5>=4,"Включить после проверки",IF(K5>=2.5,"Проверить дополнительно",IF(K5>=1.5,"Отложить","Исключить"))))) | M5: Первая версия | N5: Ожидаемый минимум
A6: P-003 | B6: Нотации UML, ERD, IDEF0, IDEF1X, IDEF3, DFD | C6: Функция | D6: S-004 | E6: F-002 | F6: 5 | G6: 4 | H6: 3 | I6: 3 | J6: 2 | K6: =IF(A6="","",IFERROR((F6+G6+H6)*((6-J6)/5)/I6,0)) | L6: =IF(K6="","",IF(K6>=6,"Включить в первую версию",IF(K6>=4,"Включить после проверки",IF(K6>=2.5,"Проверить дополнительно",IF(K6>=1.5,"Отложить","Исключить"))))) | M6: Первая версия | N6: Стандарт рынка
A7: P-004 | B7: Регистрация и вход Free | C7: Функция | D7: S-003 | E7: F-006 | F7: 4 | G7: 4 | H7: 3 | I7: 2 | J7: 1 | K7: =IF(A7="","",IFERROR((F7+G7+H7)*((6-J7)/5)/I7,0)) | L7: =IF(K7="","",IF(K7>=6,"Включить в первую версию",IF(K7>=4,"Включить после проверки",IF(K7>=2.5,"Проверить дополнительно",IF(K7>=1.5,"Отложить","Исключить"))))) | M7: Первая версия | N7: Активация
A8: P-005 | B8: Страница возможностей и тарифов | C8: Монетизация | D8: S-002 | E8: F-009 | F8: 4 | G8: 5 | H8: 4 | I8: 2 | J8: 1 | K8: =IF(A8="","",IFERROR((F8+G8+H8)*((6-J8)/5)/I8,0)) | L8: =IF(K8="","",IF(K8>=6,"Включить в первую версию",IF(K8>=4,"Включить после проверки",IF(K8>=2.5,"Проверить дополнительно",IF(K8>=1.5,"Отложить","Исключить"))))) | M8: Первая версия | N8: Открытая цена
A9: P-006 | B9: Оплата Pro 40 у.е. в год | C9: Монетизация | D9: S-008 | E9: F-010 | F9: 3 | G9: 5 | H9: 4 | I9: 3 | J9: 3 | K9: =IF(A9="","",IFERROR((F9+G9+H9)*((6-J9)/5)/I9,0)) | L9: =IF(K9="","",IF(K9>=6,"Включить в первую версию",IF(K9>=4,"Включить после проверки",IF(K9>=2.5,"Проверить дополнительно",IF(K9>=1.5,"Отложить","Исключить"))))) | M9: Первая версия | N9: Платёжный провайдер не выбран
A10: P-007 | B10: Нотации IDEF0 и DFD (волна 1) | C10: Функция | D10: S-005 | E10: F-004 | F10: 5 | G10: 4 | H10: 3 | I10: 4 | J10: 3 | K10: =IF(A10="","",IFERROR((F10+G10+H10)*((6-J10)/5)/I10,0)) | L10: =IF(K10="","",IF(K10>=6,"Включить в первую версию",IF(K10>=4,"Включить после проверки",IF(K10>=2.5,"Проверить дополнительно",IF(K10>=1.5,"Отложить","Исключить"))))) | M10: Первая версия | N10: Конкурентное отличие
A11: P-008 | B11: ИИ-ассистент | C11: Функция | D11: S-004 | E11: F-011 | F11: 4 | G11: 4 | H11: 3 | I11: 4 | J11: 3 | K11: =IF(A11="","",IFERROR((F11+G11+H11)*((6-J11)/5)/I11,0)) | L11: =IF(K11="","",IF(K11>=6,"Включить в первую версию",IF(K11>=4,"Включить после проверки",IF(K11>=2.5,"Проверить дополнительно",IF(K11>=1.5,"Отложить","Исключить"))))) | M11: Первая версия (заглушка) | N11: В MVP заглушка с четырьмя режимами; квоты - позже
A12: P-009 | B12: Сохранение и история версий | C12: Функция | D12: S-007 | E12: F-007 | F12: 4 | G12: 3 | H12: 3 | I12: 3 | J12: 2 | K12: =IF(A12="","",IFERROR((F12+G12+H12)*((6-J12)/5)/I12,0)) | L12: =IF(K12="","",IF(K12>=6,"Включить в первую версию",IF(K12>=4,"Включить после проверки",IF(K12>=2.5,"Проверить дополнительно",IF(K12>=1.5,"Отложить","Исключить"))))) | M12: Вторая версия | N12: Удержание
A13: P-010 | B13: Совместное редактирование | C13: Функция | D13: S-011 | E13: F-013 | F13: 4 | G13: 4 | H13: 3 | I13: 5 | J13: 3 | K13: =IF(A13="","",IFERROR((F13+G13+H13)*((6-J13)/5)/I13,0)) | L13: =IF(K13="","",IF(K13>=6,"Включить в первую версию",IF(K13>=4,"Включить после проверки",IF(K13>=2.5,"Проверить дополнительно",IF(K13>=1.5,"Отложить","Исключить"))))) | M13: Позже | N13: Командный тариф

Sheet Связность
A1: Проверка связности: анализ → бизнес-логика → сценарии → требования → монетизация
A3: Контрольная точка | B3: Что проверяется | C3: Проверочный вопрос | D3: Источник листа | E3: Критерий прохождения | F3: Количество | G3: Порог | H3: Статус | I3: Комментарий
A4: Единая доказательная база | B4: Наличие выводов анализа | C4: Есть ли перенесенные выводы из предыдущих видов анализа? | D4: Банк анализа | E4: Не менее 5 выводов | F4: =COUNTA('Банк анализа'!A4:A203) | G4: 5 | H4: =IF(F4>=G4,"Пройдено","Недостаточно")
A5: Подтвержденные основания | B5: Качество доказательств | C5: Есть ли сильные основания для решений? | D5: Банк анализа | E5: Не менее 3 выводов с силой доказательства 3-4 | F5: =COUNTIF('Банк анализа'!G4:G203,">=3") | G5: 3 | H5: =IF(F5>=G5,"Пройдено","Недостаточно")
A6: Бизнес-логика | B6: Наличие элементов логики | C6: Сформулировано ли, за счет чего создается и монетизируется ценность? | D6: Бизнес-логика | E6: Не менее 3 элементов | F6: =COUNTA('Бизнес-логика'!A4:A203) | G6: 3 | H6: =IF(F6>=G6,"Пройдено","Недостаточно")
A7: Роли и сегменты | B7: Наличие ролей | C7: Понятно ли, для кого создаются сценарии? | D7: Роли и сегменты | E7: Не менее 2 ролей | F7: =COUNTA('Роли и сегменты'!A4:A203) | G7: 2 | H7: =IF(F7>=G7,"Пройдено","Недостаточно")
A8: Сценарии | B8: Наличие пользовательских сценариев | C8: Описаны ли действия пользователя от проблемы до результата? | D8: Пользовательские сценарии | E8: Не менее 5 сценариев | F8: =COUNTA('Пользовательские сценарии'!A4:A203) | G8: 5 | H8: =IF(F8>=G8,"Пройдено","Недостаточно")
A9: Монетизационные сценарии | B9: Связь сценариев с доходами | C9: Есть ли сценарии, напрямую связанные с оплатой или удержанием? | D9: Пользовательские сценарии | E9: Не менее 1 монетизационного сценария | F9: =COUNTIF('Пользовательские сценарии'!E4:E203,"Монетизационный") | G9: 1 | H9: =IF(F9>=G9,"Пройдено","Недостаточно")
A10: Требования | B10: Перевод сценариев в функции | C10: Есть ли функциональные требования, выведенные из сценариев? | D10: Функциональные требования | E10: Не менее 5 требований | F10: =COUNTA('Функциональные требования'!A4:A203) | G10: 5 | H10: =IF(F10>=G10,"Пройдено","Недостаточно")
A11: MVP | B11: Фокус первой версии | C11: Есть ли требования, рекомендованные в первую версию? | D11: Функциональные требования | E11: Не менее 3 требований MVP | F11: =COUNTIF('Функциональные требования'!O4:O203,"Да") | G11: 3 | H11: =IF(F11>=G11,"Пройдено","Недостаточно")
A12: Приоритизация | B12: Очередность реализации | C12: Определены ли инициативы и решения по ним? | D12: Приоритизация | E12: Не менее 5 инициатив | F12: =COUNTA(Приоритизация!A4:A203) | G12: 5 | H12: =IF(F12>=G12,"Пройдено","Недостаточно")
A13: Общая связность | B13: Прохождение контрольных точек | C13: Прошла ли модель ключевые проверки? | D13: Связность | E13: Не менее 7 пройденных точек | F13: =COUNTIF(H4:H12,"Пройдено") | G13: 7 | H13: =IF(F13>=G13,"Пройдено","Недостаточно")

Sheet Дашборд
A1: Дашборд готовности бизнес-логики и пользовательских сценариев
A3: Ключевые показатели | F3: Распределение сценариев и требований по приоритетам
A4: Показатель | B4: Значение | C4: Единица | D4: Интерпретация | F4: Приоритет | G4: Сценарии | H4: Требования | I4: Инициативы
A5: Выводов анализа | B5: =COUNTA('Банк анализа'!A4:A203) | C5: шт | D5: Объем доказательной базы | F5: Критический | G5: =COUNTIF('Пользовательские сценарии'!S4:S203,F5) | H5: =COUNTIF('Функциональные требования'!N4:N203,F5) | I5: =COUNTIF(Приоритизация!L4:L203,"*"&F5&"*")
A6: Сильных выводов | B6: =COUNTIF('Банк анализа'!G4:G203,">=3") | C6: шт | D6: Сила доказательной базы | F6: Высокий | G6: =COUNTIF('Пользовательские сценарии'!S4:S203,F6) | H6: =COUNTIF('Функциональные требования'!N4:N203,F6) | I6: =COUNTIF(Приоритизация!L4:L203,"*"&F6&"*")
A7: Элементов бизнес-логики | B7: =COUNTA('Бизнес-логика'!A4:A203) | C7: шт | D7: Сформированность логики | F7: Средний | G7: =COUNTIF('Пользовательские сценарии'!S4:S203,F7) | H7: =COUNTIF('Функциональные требования'!N4:N203,F7) | I7: =COUNTIF(Приоритизация!L4:L203,"*"&F7&"*")
A8: Средний индекс надежности логики | B8: =IFERROR(AVERAGEIF('Бизнес-логика'!M4:M203,">0",'Бизнес-логика'!M4:M203),0) | C8: 0-1 | D8: Качество связности элементов | F8: Низкий | G8: =COUNTIF('Пользовательские сценарии'!S4:S203,F8) | H8: =COUNTIF('Функциональные требования'!N4:N203,F8) | I8: =COUNTIF(Приоритизация!L4:L203,"*"&F8&"*")
A9: Ролей и сегментов | B9: =COUNTA('Роли и сегменты'!A4:A203) | C9: шт | D9: Покрытие пользователей | F9: Отложить | G9: =COUNTIF('Пользовательские сценарии'!S4:S203,F9) | H9: =COUNTIF('Функциональные требования'!N4:N203,F9) | I9: =COUNTIF(Приоритизация!L4:L203,"*"&F9&"*")
A10: Пользовательских сценариев | B10: =COUNTA('Пользовательские сценарии'!A4:A203) | C10: шт | D10: Полнота сценарной модели
A11: Критических и высоких сценариев | B11: =COUNTIF('Пользовательские сценарии'!S4:S203,"Критический")+COUNTIF('Пользовательские сценарии'!S4:S203,"Высокий") | C11: шт | D11: Фокус для проектирования
A12: Функциональных требований | B12: =COUNTA('Функциональные требования'!A4:A203) | C12: шт | D12: Перевод сценариев в продукт | F12: Контрольные точки связности
A13: Требований MVP | B13: =COUNTIF('Функциональные требования'!O4:O203,"Да") | C13: шт | D13: Состав первой версии | F13: Контрольная точка | G13: Количество | H13: Порог | I13: Статус
A14: Пройденных контрольных точек | B14: =COUNTIF(Связность!H4:H13,"Пройдено") | C14: из 10 | D14: Общая проверка | F14: =Связность!A4 | G14: =Связность!F4 | H14: =Связность!G4 | I14: =Связность!H4
A15: Индекс готовности | B15: =IFERROR(COUNTIF(Связность!H4:H13,"Пройдено")/10,0) | C15: % | D15: Итоговая готовность | F15: =Связность!A5 | G15: =Связность!F5 | H15: =Связность!G5 | I15: =Связность!H5
F16: =Связность!A6 | G16: =Связность!F6 | H16: =Связность!G6 | I16: =Связность!H6
F17: =Связность!A7 | G17: =Связность!F7 | H17: =Связность!G7 | I17: =Связность!H7
A18: Итоговая интерпретация | F18: =Связность!A8 | G18: =Связность!F8 | H18: =Связность!G8 | I18: =Связность!H8
A19: Индекс готовности менее 50% | B19: Модель неполная: сначала усилить доказательную базу, роли и сценарии | F19: =Связность!A9 | G19: =Связность!F9 | H19: =Связность!G9 | I19: =Связность!H9
A20: Индекс готовности 50–79% | B20: Модель рабочая, но требует проверки слабых связей и уточнения монетизационных сценариев | F20: =Связность!A10 | G20: =Связность!F10 | H20: =Связность!G10 | I20: =Связность!H10
A21: Индекс готовности 80–100% | B21: Модель готова к переводу в техническое задание, прототипирование и план первой версии | F21: =Связность!A11 | G21: =Связность!F11 | H21: =Связность!G11 | I21: =Связность!H11
A22: Главный риск | B22: Сценарии без связи с проблемой, товаром или единицей монетизации не должны попадать в первую версию | F22: =Связность!A12 | G22: =Связность!F12 | H22: =Связность!G12 | I22: =Связность!H12
A23: Главное правило | B23: Функция включается в продукт только если она поддерживает ценность, сценарий или монетизацию | F23: =Связность!A13 | G23: =Связность!F13 | H23: =Связность!G13 | I23: =Связность!H13

Sheet Справочники
A1: Справочники для выпадающих списков и шкал оценки
A3: Источник анализа | D3: Блок Канвас | G3: Уровень доказательности | J3: Роль пользователя
A4: Анализ проблем клиентов | D4: Потребительские сегменты | G4: 1 — слабый сигнал | J4: Посетитель
A5: Анализ отзывов | D5: Ценностные предложения | G5: 2 — частично подтверждено | J5: Потенциальный клиент
A6: Анализ конкурентов по сайтам | D6: Каналы | G6: 3 — подтверждено несколькими источниками | J6: Новый пользователь
A7: Анализ бизнес-моделей конкурентов | D7: Отношения с клиентами | G7: 4 — проверенное основание | J7: Активный пользователь
A8: Классификация компаний по уровням конкуренции | D8: Потоки доходов | J8: Платящий клиент
A9: Анализ цифрового товара и рыночного стандарта | D9: Ключевые ресурсы | J9: Администратор клиента
A10: Ценностное предложение и цифровой товар | D10: Ключевые виды деятельности | J10: Менеджер/оператор
A11: Канвас бизнес-модели | D11: Ключевые партнеры | J11: Партнер
A12: Экономика монетизации | D12: Структура затрат | J12: Внутренний администратор
A13: Проверка пользовательских сценариев
A17: Этап сценария | D17: Тип сценария | G17: Приоритет | J17: Статус
A18: Привлечение | D18: Основной | G18: Критический | J18: Черновик
A19: Первичный интерес | D19: Вспомогательный | G19: Высокий | J19: Требует проверки
A20: Регистрация | D20: Монетизационный | G20: Средний | J20: Подтверждено
A21: Первичная настройка | D21: Сервисный | G21: Низкий | J21: В разработку
A22: Получение ценности | D22: Административный | G22: Отложить | J22: Исключено
A23: Оплата | D23: Удерживающий
A24: Повторное использование | D24: Партнерский
A25: Поддержка
A26: Удержание
A27: Расширение потребления
A28: Отказ/возврат
A31: Тип бизнес-логики | D31: Категория Кано | G31: Уровень товара по Левитту | J31: Тип цифрового товара
A32: Клиентская | D32: Базовое требование | G32: Ядро выгоды | J32: Подписка
A33: Продуктовая | D33: Линейное требование | G33: Базовый товар | J33: Доступ к сервису
A34: Монетизационная | D34: Восхищающее требование | G34: Ожидаемый товар | J34: Цифровой контент
A35: Канальная | D35: Нейтральный признак | G35: Расширенный товар | J35: Транзакционная услуга
A36: Сервисная | D36: Обратное требование | G36: Потенциальный товар | J36: Маркетплейс-доступ
A37: Партнерская | D37: Не определено | J37: Программный модуль
A38: Операционная | J38: Данные/аналитика
A39: Инфраструктурная | J39: Образовательный продукт
A40: Правовая | J40: Гибридный товар
A41: Аналитическая
A45: Шкала | B45: 1 | C45: 2 | D45: 3 | E45: 4-5 | F45: Правило
A46: Значимость проблемы | B46: единичный дискомфорт | C46: частая неудобность | D46: существенный ущерб | E46: критичная боль | F46: Оценивать по частоте, тяжести, экономическим последствиям
A47: Влияние на выручку | B47: слабое | C47: косвенное | D47: заметное | E47: прямое | F47: Связывать с оплатой, удержанием, расширением потребления
A48: Сложность реализации | B48: низкая | C48: умеренная | D48: средняя | E48: высокая | F48: Чем выше сложность, тем ниже приоритет при равной ценности
A49: Доказательность | B49: слабый сигнал | C49: частично | D49: подтверждено | E49: проверено | F49: Оценивать по числу и качеству источников
...

Sheet Журнал_6_3
A1: Журнал рабочей копии: формулы, бизнес-логика в трёх версиях, ограничения
A3: Раздел | B3: Код | C3: Содержание
A4: Формула | B4: Ф-1 | C4: Индекс сценария рассчитан по шаблону: частота x значимость x влияние на выручку x доказательность / 20. По формуле docx (ценность 0,25; монетизация 0,20; частота 0,15; риск отказа 0,15; конкурентное значение 0,10; доказательность 0,15; минус сложность 0,10) расчёт не вёлся
A5: Бизнес-логика, полная версия | B5: Б-1 | C5: Мы работаем со студентами технических специальностей и аналитиками ПО, которые сталкиваются с отсутствием единого инструмента для всех нотаций проекта (UML, BPMN, ERD, IDEF0, DFD, сети Петри) и с высоким порогом освоения текстовых языков. Для решения предлагается NotaCode - веб-IDE «диаграммы как код», которая даёт корректную диаграмму в выбранной нотации из текста за счёт единого редактора, набора нотаций и ИИ-ассистента. Пользователь получает ценность через сценарии построения первой диаграммы, экспорта и построения диаграмм IDEF0 и DFD, а компания монетизирует её через подписку Pro 40 у.е. в год за пользователя при бесплатном уровне Free. Устойчивость обеспечивают собственный движок нотаций, документация, облачная инфраструктура и ИИ-провайдер (гипотезы), результат проверяется долей пользователей, построивших первую диаграмму, конверсией Free в Pro и удержанием
A6: Бизнес-логика, краткая версия | B6: Б-2 | C6: Студенты и аналитики ПО получают диаграмму любой нотации проекта из текста в одном бесплатном инструменте, а компания зарабатывает на подписке Pro за снятие ограничений
A7: Бизнес-логика, проверочная версия | B7: Б-3 | C7: Сегмент (студенты, аналитики ПО; A-006) -> проблема P-002 (A-001) -> цифровой товар NotaCode (6.1) -> механизм (единый редактор и набор нотаций; BL-002) -> сценарий S-004, S-005 -> монетизация Pro 40 у.е. в год (A-003, A-004) -> операционная способность (BL-006, гипотеза) -> метрики (BL-007)
A8: Правило | B8: П-1 | C8: Оценки 1-5 и 1-4 экспертные; источники - банк анализа (13 выводов из 6.1, 6.2 и ЛР1-ЛР5). Основные функции (нотации волны 1) по индексу шаблона получают статус «Кандидат» из-за сложности; решение об их включении принимается в методике 6.5
A9: Ограничения | B9: О-1 | C9: Опрос студентов сгенерирован (ЛР4)
